INFO:root:created Blog with title 'SeventhBlog'
INFO:root:Blog's listed for the user
INFO:root:Retrieved Blog 'bdc32290-ed89-48ef-b704-a6da67e30bc3'
INFO:root:Retrieved Blog 'bdc32290-ed89-48ef-b704-a6da67e30bc3'
INFO:root:Commented on Blog 'bdc32290-ed89-48ef-b704-a6da67e30bc3'
INFO:root:Liked Blog 'bdc32290-ed89-48ef-b704-a6da67e30bc3'
INFO:root:Disliked Blog 'bdc32290-ed89-48ef-b704-a6da67e30bc3'
INFO:root:Deleted Blog 'bdc32290-ed89-48ef-b704-a6da67e30bc3'
INFO:django.utils.autoreload:/media/utkarshrasal/4846FE1A46FE0908/WORK/PYTHON/Django/bloggingwebsite/blogs/viewsets.py changed, reloading.
INFO:root:Blog's listed for the user '1f3a52f8-3966-497d-a948-47b6cc2e41c1'
INFO:root:created Blog with title 'SeventhBlog'
INFO:root:created Blog with title 'SeventhBlog'
INFO:root:Commented on Blog 'f7b7ee76-2c6c-46d6-9f66-31246a2dea6f'
INFO:root:Liked Blog 'f7b7ee76-2c6c-46d6-9f66-31246a2dea6f'
INFO:root:Retrieved Blog 'f7b7ee76-2c6c-46d6-9f66-31246a2dea6f'
WARNING:django.request:Not Found: /favicon.ico
ERROR:django.request:Internal Server Error: /blogs/f7b7ee76-2c6c-46d6-9f66-31246a2dea6f/comment
Traceback (most recent call last):
  File "/home/utkarshrasal/.local/lib/python3.8/site-packages/django/core/handlers/exception.py", line 47, in inner
    response = get_response(request)
  File "/home/utkarshrasal/.local/lib/python3.8/site-packages/django/utils/deprecation.py", line 113, in __call__
    response = self.process_request(request)
  File "/home/utkarshrasal/.local/lib/python3.8/site-packages/django/middleware/common.py", line 54, in process_request
    path = self.get_full_path_with_slash(request)
  File "/home/utkarshrasal/.local/lib/python3.8/site-packages/django/middleware/common.py", line 87, in get_full_path_with_slash
    raise RuntimeError(
RuntimeError: You called this URL via PUT, but the URL doesn't end in a slash and you have APPEND_SLASH set. Django can't redirect to the slash URL while maintaining PUT data. Change your form to point to localhost:8000/blogs/f7b7ee76-2c6c-46d6-9f66-31246a2dea6f/comment/ (note the trailing slash), or set APPEND_SLASH=False in your Django settings.
INFO:root:Updated Blog 'f7b7ee76-2c6c-46d6-9f66-31246a2dea6f'
WARNING:django.request:Not Found: /favicon.ico
WARNING:django.request:Not Found: /blogs/f7b7ee76-2c6c-46d6-9f66-31246a2dea6f/likes
WARNING:django.request:Not Found: /blogs/f7b7ee76-2c6c-46d6-9f66-31246a2dea6f/likes
INFO:django.utils.autoreload:/media/utkarshrasal/4846FE1A46FE0908/WORK/PYTHON/Django/bloggingwebsite/blogs/mixins.py changed, reloading.
INFO:django.utils.autoreload:/media/utkarshrasal/4846FE1A46FE0908/WORK/PYTHON/Django/bloggingwebsite/blogs/mixins.py changed, reloading.
INFO:root:Commented on Blog 'f7b7ee76-2c6c-46d6-9f66-31246a2dea6f'
ERROR:django.request:Internal Server Error: /blogs/5ac724d8-5aba-4337-b150-59d8b52deea6/
Traceback (most recent call last):
  File "/home/utkarshrasal/.local/lib/python3.8/site-packages/django/core/handlers/exception.py", line 47, in inner
    response = get_response(request)
  File "/home/utkarshrasal/.local/lib/python3.8/site-packages/django/core/handlers/base.py", line 181, in _get_response
    response = wrapped_callback(request, *callback_args, **callback_kwargs)
  File "/home/utkarshrasal/.local/lib/python3.8/site-packages/django/views/decorators/csrf.py", line 54, in wrapped_view
    return view_func(*args, **kwargs)
  File "/home/utkarshrasal/.local/lib/python3.8/site-packages/rest_framework/viewsets.py", line 125, in view
    return self.dispatch(request, *args, **kwargs)
  File "/home/utkarshrasal/.local/lib/python3.8/site-packages/rest_framework/views.py", line 509, in dispatch
    response = self.handle_exception(exc)
  File "/home/utkarshrasal/.local/lib/python3.8/site-packages/rest_framework/views.py", line 469, in handle_exception
    self.raise_uncaught_exception(exc)
  File "/home/utkarshrasal/.local/lib/python3.8/site-packages/rest_framework/views.py", line 480, in raise_uncaught_exception
    raise exc
  File "/home/utkarshrasal/.local/lib/python3.8/site-packages/rest_framework/views.py", line 506, in dispatch
    response = handler(request, *args, **kwargs)
  File "/media/utkarshrasal/4846FE1A46FE0908/WORK/PYTHON/Django/bloggingwebsite/blogs/viewsets.py", line 80, in retrieve
    instance = self.model_class.objects.get(id=pk)
  File "/home/utkarshrasal/.local/lib/python3.8/site-packages/django/db/models/manager.py", line 85, in manager_method
    return getattr(self.get_queryset(), name)(*args, **kwargs)
  File "/home/utkarshrasal/.local/lib/python3.8/site-packages/django/db/models/query.py", line 429, in get
    raise self.model.DoesNotExist(
blogs.models.Blogs.DoesNotExist: Blogs matching query does not exist.
WARNING:django.request:Not Found: /blogs/f7b7ee76-2c6c-46d6-9f66-31246a2dea6f/5ac724d8-5aba-4337-b150-59d8b52deea6
WARNING:django.request:Method Not Allowed: /blogs/f7b7ee76-2c6c-46d6-9f66-31246a2dea6f/comment/
INFO:django.utils.autoreload:/media/utkarshrasal/4846FE1A46FE0908/WORK/PYTHON/Django/bloggingwebsite/blogs/mixins.py changed, reloading.
INFO:django.utils.autoreload:/media/utkarshrasal/4846FE1A46FE0908/WORK/PYTHON/Django/bloggingwebsite/blogs/serializers.py changed, reloading.
INFO:django.utils.autoreload:/media/utkarshrasal/4846FE1A46FE0908/WORK/PYTHON/Django/bloggingwebsite/blogs/views.py changed, reloading.
INFO:django.utils.autoreload:/media/utkarshrasal/4846FE1A46FE0908/WORK/PYTHON/Django/bloggingwebsite/blogs/mixins.py changed, reloading.
INFO:django.utils.autoreload:/media/utkarshrasal/4846FE1A46FE0908/WORK/PYTHON/Django/bloggingwebsite/blogs/mixins.py changed, reloading.
ERROR:django.request:Internal Server Error: /blogs/f7b7ee76-2c6c-46d6-9f66-31246a2dea6f/likes/
Traceback (most recent call last):
  File "/home/utkarshrasal/.local/lib/python3.8/site-packages/django/core/handlers/exception.py", line 47, in inner
    response = get_response(request)
  File "/home/utkarshrasal/.local/lib/python3.8/site-packages/django/core/handlers/base.py", line 181, in _get_response
    response = wrapped_callback(request, *callback_args, **callback_kwargs)
  File "/home/utkarshrasal/.local/lib/python3.8/site-packages/django/views/decorators/csrf.py", line 54, in wrapped_view
    return view_func(*args, **kwargs)
  File "/home/utkarshrasal/.local/lib/python3.8/site-packages/rest_framework/viewsets.py", line 125, in view
    return self.dispatch(request, *args, **kwargs)
  File "/home/utkarshrasal/.local/lib/python3.8/site-packages/rest_framework/views.py", line 509, in dispatch
    response = self.handle_exception(exc)
  File "/home/utkarshrasal/.local/lib/python3.8/site-packages/rest_framework/views.py", line 469, in handle_exception
    self.raise_uncaught_exception(exc)
  File "/home/utkarshrasal/.local/lib/python3.8/site-packages/rest_framework/views.py", line 480, in raise_uncaught_exception
    raise exc
  File "/home/utkarshrasal/.local/lib/python3.8/site-packages/rest_framework/views.py", line 506, in dispatch
    response = handler(request, *args, **kwargs)
  File "/media/utkarshrasal/4846FE1A46FE0908/WORK/PYTHON/Django/bloggingwebsite/blogs/mixins.py", line 135, in likes
    if not self.model_class.objects.filter(id=kwargs.get('pk')).exists():
NameError: name 'self' is not defined
INFO:django.utils.autoreload:/media/utkarshrasal/4846FE1A46FE0908/WORK/PYTHON/Django/bloggingwebsite/blogs/mixins.py changed, reloading.
INFO:django.utils.autoreload:/media/utkarshrasal/4846FE1A46FE0908/WORK/PYTHON/Django/bloggingwebsite/blogs/mixins.py changed, reloading.
ERROR:django.request:Internal Server Error: /blogs/f7b7ee76-2c6c-46d6-9f66-31246a2dea6f/likes/
Traceback (most recent call last):
  File "/home/utkarshrasal/.local/lib/python3.8/site-packages/django/core/handlers/exception.py", line 47, in inner
    response = get_response(request)
  File "/home/utkarshrasal/.local/lib/python3.8/site-packages/django/core/handlers/base.py", line 204, in _get_response
    response = response.render()
  File "/home/utkarshrasal/.local/lib/python3.8/site-packages/django/template/response.py", line 105, in render
    self.content = self.rendered_content
  File "/home/utkarshrasal/.local/lib/python3.8/site-packages/rest_framework/response.py", line 70, in rendered_content
    ret = renderer.render(self.data, accepted_media_type, context)
  File "/home/utkarshrasal/.local/lib/python3.8/site-packages/rest_framework/renderers.py", line 100, in render
    ret = json.dumps(
  File "/home/utkarshrasal/.local/lib/python3.8/site-packages/rest_framework/utils/json.py", line 25, in dumps
    return json.dumps(*args, **kwargs)
  File "/usr/lib/python3.8/json/__init__.py", line 234, in dumps
    return cls(
  File "/usr/lib/python3.8/json/encoder.py", line 199, in encode
    chunks = self.iterencode(o, _one_shot=True)
  File "/usr/lib/python3.8/json/encoder.py", line 257, in iterencode
    return _iterencode(o, 0)
  File "/home/utkarshrasal/.local/lib/python3.8/site-packages/rest_framework/utils/encoders.py", line 67, in default
    return super().default(obj)
  File "/usr/lib/python3.8/json/encoder.py", line 179, in default
    raise TypeError(f'Object of type {o.__class__.__name__} '
TypeError: Object of type User is not JSON serializable
INFO:django.utils.autoreload:/media/utkarshrasal/4846FE1A46FE0908/WORK/PYTHON/Django/bloggingwebsite/blogs/mixins.py changed, reloading.
INFO:django.utils.autoreload:/media/utkarshrasal/4846FE1A46FE0908/WORK/PYTHON/Django/bloggingwebsite/blogs/serializers.py changed, reloading.
INFO:django.utils.autoreload:/media/utkarshrasal/4846FE1A46FE0908/WORK/PYTHON/Django/bloggingwebsite/blogs/serializers.py changed, reloading.
INFO:django.utils.autoreload:/media/utkarshrasal/4846FE1A46FE0908/WORK/PYTHON/Django/bloggingwebsite/blogs/mixins.py changed, reloading.
ERROR:django.request:Internal Server Error: /blogs/f7b7ee76-2c6c-46d6-9f66-31246a2dea6f/likes/
Traceback (most recent call last):
  File "/home/utkarshrasal/.local/lib/python3.8/site-packages/rest_framework/fields.py", line 457, in get_attribute
    return get_attribute(instance, self.source_attrs)
  File "/home/utkarshrasal/.local/lib/python3.8/site-packages/rest_framework/fields.py", line 97, in get_attribute
    instance = getattr(instance, attr)
AttributeError: 'QuerySet' object has no attribute 'title'

During handling of the above exception, another exception occurred:

Traceback (most recent call last):
  File "/home/utkarshrasal/.local/lib/python3.8/site-packages/django/core/handlers/exception.py", line 47, in inner
    response = get_response(request)
  File "/home/utkarshrasal/.local/lib/python3.8/site-packages/django/core/handlers/base.py", line 181, in _get_response
    response = wrapped_callback(request, *callback_args, **callback_kwargs)
  File "/home/utkarshrasal/.local/lib/python3.8/site-packages/django/views/decorators/csrf.py", line 54, in wrapped_view
    return view_func(*args, **kwargs)
  File "/home/utkarshrasal/.local/lib/python3.8/site-packages/rest_framework/viewsets.py", line 125, in view
    return self.dispatch(request, *args, **kwargs)
  File "/home/utkarshrasal/.local/lib/python3.8/site-packages/rest_framework/views.py", line 509, in dispatch
    response = self.handle_exception(exc)
  File "/home/utkarshrasal/.local/lib/python3.8/site-packages/rest_framework/views.py", line 469, in handle_exception
    self.raise_uncaught_exception(exc)
  File "/home/utkarshrasal/.local/lib/python3.8/site-packages/rest_framework/views.py", line 480, in raise_uncaught_exception
    raise exc
  File "/home/utkarshrasal/.local/lib/python3.8/site-packages/rest_framework/views.py", line 506, in dispatch
    response = handler(request, *args, **kwargs)
  File "/media/utkarshrasal/4846FE1A46FE0908/WORK/PYTHON/Django/bloggingwebsite/blogs/mixins.py", line 146, in likes
    return Response(serializers.data)
  File "/home/utkarshrasal/.local/lib/python3.8/site-packages/rest_framework/serializers.py", line 548, in data
    ret = super().data
  File "/home/utkarshrasal/.local/lib/python3.8/site-packages/rest_framework/serializers.py", line 246, in data
    self._data = self.to_representation(self.instance)
  File "/home/utkarshrasal/.local/lib/python3.8/site-packages/rest_framework/serializers.py", line 502, in to_representation
    attribute = field.get_attribute(instance)
  File "/home/utkarshrasal/.local/lib/python3.8/site-packages/rest_framework/fields.py", line 490, in get_attribute
    raise type(exc)(msg)
AttributeError: Got AttributeError when attempting to get a value for field `title` on serializer `LikeSerializer`.
The serializer field might be named incorrectly and not match any attribute or key on the `QuerySet` instance.
Original exception text was: 'QuerySet' object has no attribute 'title'.
INFO:django.utils.autoreload:/media/utkarshrasal/4846FE1A46FE0908/WORK/PYTHON/Django/bloggingwebsite/blogs/viewsets.py changed, reloading.
INFO:django.utils.autoreload:/media/utkarshrasal/4846FE1A46FE0908/WORK/PYTHON/Django/bloggingwebsite/blogs/viewsets.py changed, reloading.
INFO:django.utils.autoreload:/media/utkarshrasal/4846FE1A46FE0908/WORK/PYTHON/Django/bloggingwebsite/blogs/mixins.py changed, reloading.
WARNING:django.request:Not Found: /favicon.ico
INFO:django.utils.autoreload:/media/utkarshrasal/4846FE1A46FE0908/WORK/PYTHON/Django/bloggingwebsite/blogs/mixins.py changed, reloading.
INFO:django.utils.autoreload:/media/utkarshrasal/4846FE1A46FE0908/WORK/PYTHON/Django/bloggingwebsite/blogs/mixins.py changed, reloading.
INFO:django.utils.autoreload:/media/utkarshrasal/4846FE1A46FE0908/WORK/PYTHON/Django/bloggingwebsite/blogs/mixins.py changed, reloading.
INFO:django.utils.autoreload:/media/utkarshrasal/4846FE1A46FE0908/WORK/PYTHON/Django/bloggingwebsite/blogs/mixins.py changed, reloading.
INFO:django.utils.autoreload:/media/utkarshrasal/4846FE1A46FE0908/WORK/PYTHON/Django/bloggingwebsite/blogs/mixins.py changed, reloading.
ERROR:django.request:Internal Server Error: /blogs/f7b7ee76-2c6c-46d6-9f66-31246a2dea6f/likes/
Traceback (most recent call last):
  File "/home/utkarshrasal/.local/lib/python3.8/site-packages/django/core/handlers/exception.py", line 47, in inner
    response = get_response(request)
  File "/home/utkarshrasal/.local/lib/python3.8/site-packages/django/core/handlers/base.py", line 181, in _get_response
    response = wrapped_callback(request, *callback_args, **callback_kwargs)
  File "/home/utkarshrasal/.local/lib/python3.8/site-packages/django/views/decorators/csrf.py", line 54, in wrapped_view
    return view_func(*args, **kwargs)
  File "/home/utkarshrasal/.local/lib/python3.8/site-packages/rest_framework/viewsets.py", line 125, in view
    return self.dispatch(request, *args, **kwargs)
  File "/home/utkarshrasal/.local/lib/python3.8/site-packages/rest_framework/views.py", line 509, in dispatch
    response = self.handle_exception(exc)
  File "/home/utkarshrasal/.local/lib/python3.8/site-packages/rest_framework/views.py", line 469, in handle_exception
    self.raise_uncaught_exception(exc)
  File "/home/utkarshrasal/.local/lib/python3.8/site-packages/rest_framework/views.py", line 480, in raise_uncaught_exception
    raise exc
  File "/home/utkarshrasal/.local/lib/python3.8/site-packages/rest_framework/views.py", line 506, in dispatch
    response = handler(request, *args, **kwargs)
  File "/media/utkarshrasal/4846FE1A46FE0908/WORK/PYTHON/Django/bloggingwebsite/blogs/mixins.py", line 151, in likes
    'message': f"Total Likes of user {pk}",
NameError: name 'pk' is not defined
INFO:django.utils.autoreload:/media/utkarshrasal/4846FE1A46FE0908/WORK/PYTHON/Django/bloggingwebsite/blogs/mixins.py changed, reloading.
INFO:django.utils.autoreload:/media/utkarshrasal/4846FE1A46FE0908/WORK/PYTHON/Django/bloggingwebsite/blogs/viewsets.py changed, reloading.
ERROR:django.request:Internal Server Error: /blogs/
Traceback (most recent call last):
  File "/home/utkarshrasal/.local/lib/python3.8/site-packages/django/utils/datastructures.py", line 76, in __getitem__
    list_ = super().__getitem__(key)
KeyError: 'file'

During handling of the above exception, another exception occurred:

Traceback (most recent call last):
  File "/home/utkarshrasal/.local/lib/python3.8/site-packages/django/core/handlers/exception.py", line 47, in inner
    response = get_response(request)
  File "/home/utkarshrasal/.local/lib/python3.8/site-packages/django/core/handlers/base.py", line 181, in _get_response
    response = wrapped_callback(request, *callback_args, **callback_kwargs)
  File "/home/utkarshrasal/.local/lib/python3.8/site-packages/django/views/decorators/csrf.py", line 54, in wrapped_view
    return view_func(*args, **kwargs)
  File "/home/utkarshrasal/.local/lib/python3.8/site-packages/rest_framework/viewsets.py", line 125, in view
    return self.dispatch(request, *args, **kwargs)
  File "/home/utkarshrasal/.local/lib/python3.8/site-packages/rest_framework/views.py", line 509, in dispatch
    response = self.handle_exception(exc)
  File "/home/utkarshrasal/.local/lib/python3.8/site-packages/rest_framework/views.py", line 469, in handle_exception
    self.raise_uncaught_exception(exc)
  File "/home/utkarshrasal/.local/lib/python3.8/site-packages/rest_framework/views.py", line 480, in raise_uncaught_exception
    raise exc
  File "/home/utkarshrasal/.local/lib/python3.8/site-packages/rest_framework/views.py", line 506, in dispatch
    response = handler(request, *args, **kwargs)
  File "/media/utkarshrasal/4846FE1A46FE0908/WORK/PYTHON/Django/bloggingwebsite/blogs/viewsets.py", line 50, in create
    path = 'http://' + current_site + '/' + file_path(request)
  File "/media/utkarshrasal/4846FE1A46FE0908/WORK/PYTHON/Django/bloggingwebsite/blogs/path.py", line 5, in file_path
    file = request.FILES['file']
  File "/home/utkarshrasal/.local/lib/python3.8/site-packages/django/utils/datastructures.py", line 78, in __getitem__
    raise MultiValueDictKeyError(key)
django.utils.datastructures.MultiValueDictKeyError: 'file'
INFO:root:created Blog with title 'SeventhBlog'
INFO:django.utils.autoreload:/media/utkarshrasal/4846FE1A46FE0908/WORK/PYTHON/Django/bloggingwebsite/blogs/viewsets.py changed, reloading.
INFO:root:created Blog with title 'SeventhBlog'
INFO:django.utils.autoreload:/media/utkarshrasal/4846FE1A46FE0908/WORK/PYTHON/Django/bloggingwebsite/blogs/viewsets.py changed, reloading.
ERROR:django.request:Internal Server Error: /blogs/
Traceback (most recent call last):
  File "/home/utkarshrasal/.local/lib/python3.8/site-packages/django/core/handlers/exception.py", line 47, in inner
    response = get_response(request)
  File "/home/utkarshrasal/.local/lib/python3.8/site-packages/django/core/handlers/base.py", line 181, in _get_response
    response = wrapped_callback(request, *callback_args, **callback_kwargs)
  File "/home/utkarshrasal/.local/lib/python3.8/site-packages/django/views/decorators/csrf.py", line 54, in wrapped_view
    return view_func(*args, **kwargs)
  File "/home/utkarshrasal/.local/lib/python3.8/site-packages/rest_framework/viewsets.py", line 125, in view
    return self.dispatch(request, *args, **kwargs)
  File "/home/utkarshrasal/.local/lib/python3.8/site-packages/rest_framework/views.py", line 509, in dispatch
    response = self.handle_exception(exc)
  File "/home/utkarshrasal/.local/lib/python3.8/site-packages/rest_framework/views.py", line 469, in handle_exception
    self.raise_uncaught_exception(exc)
  File "/home/utkarshrasal/.local/lib/python3.8/site-packages/rest_framework/views.py", line 480, in raise_uncaught_exception
    raise exc
  File "/home/utkarshrasal/.local/lib/python3.8/site-packages/rest_framework/views.py", line 506, in dispatch
    response = handler(request, *args, **kwargs)
  File "/media/utkarshrasal/4846FE1A46FE0908/WORK/PYTHON/Django/bloggingwebsite/blogs/viewsets.py", line 49, in create
    current_site = get_current_site(request).domain
  File "/usr/lib/python3.8/json/__init__.py", line 357, in loads
    return _default_decoder.decode(s)
  File "/usr/lib/python3.8/json/decoder.py", line 337, in decode
    obj, end = self.raw_decode(s, idx=_w(s, 0).end())
  File "/usr/lib/python3.8/json/decoder.py", line 355, in raw_decode
    raise JSONDecodeError("Expecting value", s, err.value) from None
json.decoder.JSONDecodeError: Expecting value: line 1 column 1 (char 0)
INFO:root:created Blog with title 'SeventhBlog'
INFO:django.utils.autoreload:/media/utkarshrasal/4846FE1A46FE0908/WORK/PYTHON/Django/bloggingwebsite/blogs/viewsets.py changed, reloading.
INFO:django.utils.autoreload:/media/utkarshrasal/4846FE1A46FE0908/WORK/PYTHON/Django/bloggingwebsite/blogs/viewsets.py changed, reloading.
INFO:django.utils.autoreload:/media/utkarshrasal/4846FE1A46FE0908/WORK/PYTHON/Django/bloggingwebsite/blogs/viewsets.py changed, reloading.
WARNING:django.request:Bad Request: /blogs/
INFO:django.utils.autoreload:/media/utkarshrasal/4846FE1A46FE0908/WORK/PYTHON/Django/bloggingwebsite/blogs/serializers.py changed, reloading.
WARNING:django.request:Bad Request: /blogs/
INFO:django.utils.autoreload:/media/utkarshrasal/4846FE1A46FE0908/WORK/PYTHON/Django/bloggingwebsite/blogs/viewsets.py changed, reloading.
ERROR:django.request:Internal Server Error: /blogs/
Traceback (most recent call last):
  File "/home/utkarshrasal/.local/lib/python3.8/site-packages/django/core/handlers/exception.py", line 47, in inner
    response = get_response(request)
  File "/home/utkarshrasal/.local/lib/python3.8/site-packages/django/core/handlers/base.py", line 181, in _get_response
    response = wrapped_callback(request, *callback_args, **callback_kwargs)
  File "/home/utkarshrasal/.local/lib/python3.8/site-packages/django/views/decorators/csrf.py", line 54, in wrapped_view
    return view_func(*args, **kwargs)
  File "/home/utkarshrasal/.local/lib/python3.8/site-packages/rest_framework/viewsets.py", line 125, in view
    return self.dispatch(request, *args, **kwargs)
  File "/home/utkarshrasal/.local/lib/python3.8/site-packages/rest_framework/views.py", line 509, in dispatch
    response = self.handle_exception(exc)
  File "/home/utkarshrasal/.local/lib/python3.8/site-packages/rest_framework/views.py", line 469, in handle_exception
    self.raise_uncaught_exception(exc)
  File "/home/utkarshrasal/.local/lib/python3.8/site-packages/rest_framework/views.py", line 480, in raise_uncaught_exception
    raise exc
  File "/home/utkarshrasal/.local/lib/python3.8/site-packages/rest_framework/views.py", line 506, in dispatch
    response = handler(request, *args, **kwargs)
  File "/media/utkarshrasal/4846FE1A46FE0908/WORK/PYTHON/Django/bloggingwebsite/blogs/viewsets.py", line 60, in create
    'tags':json.loads(tags),
  File "/usr/lib/python3.8/json/__init__.py", line 341, in loads
    raise TypeError(f'the JSON object must be str, bytes or bytearray, '
TypeError: the JSON object must be str, bytes or bytearray, not list
INFO:django.utils.autoreload:/media/utkarshrasal/4846FE1A46FE0908/WORK/PYTHON/Django/bloggingwebsite/blogs/viewsets.py changed, reloading.
ERROR:django.request:Internal Server Error: /blogs/
Traceback (most recent call last):
  File "/home/utkarshrasal/.local/lib/python3.8/site-packages/django/core/handlers/exception.py", line 47, in inner
    response = get_response(request)
  File "/home/utkarshrasal/.local/lib/python3.8/site-packages/django/core/handlers/base.py", line 181, in _get_response
    response = wrapped_callback(request, *callback_args, **callback_kwargs)
  File "/home/utkarshrasal/.local/lib/python3.8/site-packages/django/views/decorators/csrf.py", line 54, in wrapped_view
    return view_func(*args, **kwargs)
  File "/home/utkarshrasal/.local/lib/python3.8/site-packages/rest_framework/viewsets.py", line 125, in view
    return self.dispatch(request, *args, **kwargs)
  File "/home/utkarshrasal/.local/lib/python3.8/site-packages/rest_framework/views.py", line 509, in dispatch
    response = self.handle_exception(exc)
  File "/home/utkarshrasal/.local/lib/python3.8/site-packages/rest_framework/views.py", line 469, in handle_exception
    self.raise_uncaught_exception(exc)
  File "/home/utkarshrasal/.local/lib/python3.8/site-packages/rest_framework/views.py", line 480, in raise_uncaught_exception
    raise exc
  File "/home/utkarshrasal/.local/lib/python3.8/site-packages/rest_framework/views.py", line 506, in dispatch
    response = handler(request, *args, **kwargs)
  File "/media/utkarshrasal/4846FE1A46FE0908/WORK/PYTHON/Django/bloggingwebsite/blogs/viewsets.py", line 60, in create
    'tags':json.loads(''.join(tags)),
  File "/usr/lib/python3.8/json/__init__.py", line 357, in loads
    return _default_decoder.decode(s)
  File "/usr/lib/python3.8/json/decoder.py", line 337, in decode
    obj, end = self.raw_decode(s, idx=_w(s, 0).end())
  File "/usr/lib/python3.8/json/decoder.py", line 355, in raw_decode
    raise JSONDecodeError("Expecting value", s, err.value) from None
json.decoder.JSONDecodeError: Expecting value: line 1 column 1 (char 0)
INFO:django.utils.autoreload:/media/utkarshrasal/4846FE1A46FE0908/WORK/PYTHON/Django/bloggingwebsite/blogs/serializers.py changed, reloading.
INFO:django.utils.autoreload:/media/utkarshrasal/4846FE1A46FE0908/WORK/PYTHON/Django/bloggingwebsite/blogs/serializers.py changed, reloading.
INFO:django.utils.autoreload:/media/utkarshrasal/4846FE1A46FE0908/WORK/PYTHON/Django/bloggingwebsite/blogs/viewsets.py changed, reloading.
ERROR:django.request:Internal Server Error: /blogs/
Traceback (most recent call last):
  File "/home/utkarshrasal/.local/lib/python3.8/site-packages/django/core/handlers/exception.py", line 47, in inner
    response = get_response(request)
  File "/home/utkarshrasal/.local/lib/python3.8/site-packages/django/core/handlers/base.py", line 181, in _get_response
    response = wrapped_callback(request, *callback_args, **callback_kwargs)
  File "/home/utkarshrasal/.local/lib/python3.8/site-packages/django/views/decorators/csrf.py", line 54, in wrapped_view
    return view_func(*args, **kwargs)
  File "/home/utkarshrasal/.local/lib/python3.8/site-packages/rest_framework/viewsets.py", line 125, in view
    return self.dispatch(request, *args, **kwargs)
  File "/home/utkarshrasal/.local/lib/python3.8/site-packages/rest_framework/views.py", line 509, in dispatch
    response = self.handle_exception(exc)
  File "/home/utkarshrasal/.local/lib/python3.8/site-packages/rest_framework/views.py", line 469, in handle_exception
    self.raise_uncaught_exception(exc)
  File "/home/utkarshrasal/.local/lib/python3.8/site-packages/rest_framework/views.py", line 480, in raise_uncaught_exception
    raise exc
  File "/home/utkarshrasal/.local/lib/python3.8/site-packages/rest_framework/views.py", line 506, in dispatch
    response = handler(request, *args, **kwargs)
  File "/media/utkarshrasal/4846FE1A46FE0908/WORK/PYTHON/Django/bloggingwebsite/blogs/viewsets.py", line 49, in create
    current_site = get_current_site(request).domain
  File "/usr/lib/python3.8/json/__init__.py", line 357, in loads
    return _default_decoder.decode(s)
  File "/usr/lib/python3.8/json/decoder.py", line 337, in decode
    obj, end = self.raw_decode(s, idx=_w(s, 0).end())
  File "/usr/lib/python3.8/json/decoder.py", line 355, in raw_decode
    raise JSONDecodeError("Expecting value", s, err.value) from None
json.decoder.JSONDecodeError: Expecting value: line 1 column 1 (char 0)
ERROR:django.request:Internal Server Error: /blogs/
Traceback (most recent call last):
  File "/home/utkarshrasal/.local/lib/python3.8/site-packages/django/core/handlers/exception.py", line 47, in inner
    response = get_response(request)
  File "/home/utkarshrasal/.local/lib/python3.8/site-packages/django/core/handlers/base.py", line 181, in _get_response
    response = wrapped_callback(request, *callback_args, **callback_kwargs)
  File "/home/utkarshrasal/.local/lib/python3.8/site-packages/django/views/decorators/csrf.py", line 54, in wrapped_view
    return view_func(*args, **kwargs)
  File "/home/utkarshrasal/.local/lib/python3.8/site-packages/rest_framework/viewsets.py", line 125, in view
    return self.dispatch(request, *args, **kwargs)
  File "/home/utkarshrasal/.local/lib/python3.8/site-packages/rest_framework/views.py", line 509, in dispatch
    response = self.handle_exception(exc)
  File "/home/utkarshrasal/.local/lib/python3.8/site-packages/rest_framework/views.py", line 469, in handle_exception
    self.raise_uncaught_exception(exc)
  File "/home/utkarshrasal/.local/lib/python3.8/site-packages/rest_framework/views.py", line 480, in raise_uncaught_exception
    raise exc
  File "/home/utkarshrasal/.local/lib/python3.8/site-packages/rest_framework/views.py", line 506, in dispatch
    response = handler(request, *args, **kwargs)
  File "/media/utkarshrasal/4846FE1A46FE0908/WORK/PYTHON/Django/bloggingwebsite/blogs/viewsets.py", line 51, in create
    tags = json.loads(_tags) #convert string to dictionary
  File "/usr/lib/python3.8/json/__init__.py", line 357, in loads
    return _default_decoder.decode(s)
  File "/usr/lib/python3.8/json/decoder.py", line 337, in decode
    obj, end = self.raw_decode(s, idx=_w(s, 0).end())
  File "/usr/lib/python3.8/json/decoder.py", line 355, in raw_decode
    raise JSONDecodeError("Expecting value", s, err.value) from None
json.decoder.JSONDecodeError: Expecting value: line 1 column 1 (char 0)
INFO:django.utils.autoreload:/media/utkarshrasal/4846FE1A46FE0908/WORK/PYTHON/Django/bloggingwebsite/blogs/viewsets.py changed, reloading.
ERROR:django.request:Internal Server Error: /blogs/
Traceback (most recent call last):
  File "/home/utkarshrasal/.local/lib/python3.8/site-packages/django/core/handlers/exception.py", line 47, in inner
    response = get_response(request)
  File "/home/utkarshrasal/.local/lib/python3.8/site-packages/django/core/handlers/base.py", line 181, in _get_response
    response = wrapped_callback(request, *callback_args, **callback_kwargs)
  File "/home/utkarshrasal/.local/lib/python3.8/site-packages/django/views/decorators/csrf.py", line 54, in wrapped_view
    return view_func(*args, **kwargs)
  File "/home/utkarshrasal/.local/lib/python3.8/site-packages/rest_framework/viewsets.py", line 125, in view
    return self.dispatch(request, *args, **kwargs)
  File "/home/utkarshrasal/.local/lib/python3.8/site-packages/rest_framework/views.py", line 509, in dispatch
    response = self.handle_exception(exc)
  File "/home/utkarshrasal/.local/lib/python3.8/site-packages/rest_framework/views.py", line 469, in handle_exception
    self.raise_uncaught_exception(exc)
  File "/home/utkarshrasal/.local/lib/python3.8/site-packages/rest_framework/views.py", line 480, in raise_uncaught_exception
    raise exc
  File "/home/utkarshrasal/.local/lib/python3.8/site-packages/rest_framework/views.py", line 506, in dispatch
    response = handler(request, *args, **kwargs)
  File "/media/utkarshrasal/4846FE1A46FE0908/WORK/PYTHON/Django/bloggingwebsite/blogs/viewsets.py", line 51, in create
    tags = json.loads(_tags) #convert string to dictionary
  File "/usr/lib/python3.8/json/__init__.py", line 357, in loads
    return _default_decoder.decode(s)
  File "/usr/lib/python3.8/json/decoder.py", line 337, in decode
    obj, end = self.raw_decode(s, idx=_w(s, 0).end())
  File "/usr/lib/python3.8/json/decoder.py", line 355, in raw_decode
    raise JSONDecodeError("Expecting value", s, err.value) from None
json.decoder.JSONDecodeError: Expecting value: line 1 column 1 (char 0)
INFO:root:created Blog with title 'SeventhBlog'
WARNING:django.request:Method Not Allowed: /blogs/
WARNING:django.request:Not Found: /favicon.ico
INFO:root:Retrieved Blog 'f7b7ee76-2c6c-46d6-9f66-31246a2dea6f'
ERROR:django.request:Internal Server Error: /blogs/f7b7ee76-2c6c-46d6-9f66-31246a2dea6f
Traceback (most recent call last):
  File "/home/utkarshrasal/.local/lib/python3.8/site-packages/django/core/handlers/exception.py", line 47, in inner
    response = get_response(request)
  File "/home/utkarshrasal/.local/lib/python3.8/site-packages/django/utils/deprecation.py", line 113, in __call__
    response = self.process_request(request)
  File "/home/utkarshrasal/.local/lib/python3.8/site-packages/django/middleware/common.py", line 54, in process_request
    path = self.get_full_path_with_slash(request)
  File "/home/utkarshrasal/.local/lib/python3.8/site-packages/django/middleware/common.py", line 87, in get_full_path_with_slash
    raise RuntimeError(
RuntimeError: You called this URL via PATCH, but the URL doesn't end in a slash and you have APPEND_SLASH set. Django can't redirect to the slash URL while maintaining PATCH data. Change your form to point to localhost:8000/blogs/f7b7ee76-2c6c-46d6-9f66-31246a2dea6f/ (note the trailing slash), or set APPEND_SLASH=False in your Django settings.
INFO:root:Partially updated Blog 'f7b7ee76-2c6c-46d6-9f66-31246a2dea6f'
INFO:root:created Blog with title 'SeventhBlog'
INFO:django.utils.autoreload:/media/utkarshrasal/4846FE1A46FE0908/WORK/PYTHON/Django/bloggingwebsite/blogs/viewsets.py changed, reloading.
INFO:django.utils.autoreload:/media/utkarshrasal/4846FE1A46FE0908/WORK/PYTHON/Django/bloggingwebsite/blogs/viewsets.py changed, reloading.
INFO:django.utils.autoreload:/media/utkarshrasal/4846FE1A46FE0908/WORK/PYTHON/Django/bloggingwebsite/blogs/viewsets.py changed, reloading.
ERROR:django.request:Internal Server Error: /blogs/
Traceback (most recent call last):
  File "/home/utkarshrasal/.local/lib/python3.8/site-packages/django/core/handlers/exception.py", line 47, in inner
    response = get_response(request)
  File "/home/utkarshrasal/.local/lib/python3.8/site-packages/django/core/handlers/base.py", line 181, in _get_response
    response = wrapped_callback(request, *callback_args, **callback_kwargs)
  File "/home/utkarshrasal/.local/lib/python3.8/site-packages/django/views/decorators/csrf.py", line 54, in wrapped_view
    return view_func(*args, **kwargs)
  File "/home/utkarshrasal/.local/lib/python3.8/site-packages/rest_framework/viewsets.py", line 125, in view
    return self.dispatch(request, *args, **kwargs)
  File "/home/utkarshrasal/.local/lib/python3.8/site-packages/rest_framework/views.py", line 509, in dispatch
    response = self.handle_exception(exc)
  File "/home/utkarshrasal/.local/lib/python3.8/site-packages/rest_framework/views.py", line 469, in handle_exception
    self.raise_uncaught_exception(exc)
  File "/home/utkarshrasal/.local/lib/python3.8/site-packages/rest_framework/views.py", line 480, in raise_uncaught_exception
    raise exc
  File "/home/utkarshrasal/.local/lib/python3.8/site-packages/rest_framework/views.py", line 506, in dispatch
    response = handler(request, *args, **kwargs)
  File "/media/utkarshrasal/4846FE1A46FE0908/WORK/PYTHON/Django/bloggingwebsite/blogs/viewsets.py", line 55, in create
    tags.append({k: v.lower() for k, v in tags[i].items()})
IndexError: list index out of range
INFO:django.utils.autoreload:/media/utkarshrasal/4846FE1A46FE0908/WORK/PYTHON/Django/bloggingwebsite/blogs/viewsets.py changed, reloading.
INFO:django.utils.autoreload:/media/utkarshrasal/4846FE1A46FE0908/WORK/PYTHON/Django/bloggingwebsite/blogs/viewsets.py changed, reloading.
INFO:django.utils.autoreload:/media/utkarshrasal/4846FE1A46FE0908/WORK/PYTHON/Django/bloggingwebsite/blogs/viewsets.py changed, reloading.
INFO:django.utils.autoreload:/media/utkarshrasal/4846FE1A46FE0908/WORK/PYTHON/Django/bloggingwebsite/blogs/viewsets.py changed, reloading.
INFO:django.utils.autoreload:/media/utkarshrasal/4846FE1A46FE0908/WORK/PYTHON/Django/bloggingwebsite/blogs/viewsets.py changed, reloading.
INFO:django.utils.autoreload:/media/utkarshrasal/4846FE1A46FE0908/WORK/PYTHON/Django/bloggingwebsite/blogs/viewsets.py changed, reloading.
INFO:django.utils.autoreload:/media/utkarshrasal/4846FE1A46FE0908/WORK/PYTHON/Django/bloggingwebsite/blogs/viewsets.py changed, reloading.
INFO:django.utils.autoreload:/media/utkarshrasal/4846FE1A46FE0908/WORK/PYTHON/Django/bloggingwebsite/blogs/viewsets.py changed, reloading.
INFO:django.utils.autoreload:/media/utkarshrasal/4846FE1A46FE0908/WORK/PYTHON/Django/bloggingwebsite/blogs/viewsets.py changed, reloading.
INFO:django.utils.autoreload:/media/utkarshrasal/4846FE1A46FE0908/WORK/PYTHON/Django/bloggingwebsite/blogs/viewsets.py changed, reloading.
INFO:django.utils.autoreload:/media/utkarshrasal/4846FE1A46FE0908/WORK/PYTHON/Django/bloggingwebsite/blogs/viewsets.py changed, reloading.
INFO:root:created Blog with title 'SeventhBlog'
INFO:django.utils.autoreload:/media/utkarshrasal/4846FE1A46FE0908/WORK/PYTHON/Django/bloggingwebsite/blogs/viewsets.py changed, reloading.
INFO:root:created Blog with title 'SeventhBlog'
INFO:django.utils.autoreload:/media/utkarshrasal/4846FE1A46FE0908/WORK/PYTHON/Django/bloggingwebsite/blogs/viewsets.py changed, reloading.
INFO:django.utils.autoreload:/media/utkarshrasal/4846FE1A46FE0908/WORK/PYTHON/Django/bloggingwebsite/blogs/viewsets.py changed, reloading.
INFO:root:created Blog with title 'SeventhBlog'
INFO:django.utils.autoreload:/media/utkarshrasal/4846FE1A46FE0908/WORK/PYTHON/Django/bloggingwebsite/blogs/viewsets.py changed, reloading.
INFO:django.utils.autoreload:/media/utkarshrasal/4846FE1A46FE0908/WORK/PYTHON/Django/bloggingwebsite/blogs/viewsets.py changed, reloading.
INFO:django.utils.autoreload:/media/utkarshrasal/4846FE1A46FE0908/WORK/PYTHON/Django/bloggingwebsite/blogs/viewsets.py changed, reloading.
INFO:root:created Blog with title 'SeventhBlog'
INFO:root:created Blog with title 'SeventhBlog'
INFO:django.utils.autoreload:/media/utkarshrasal/4846FE1A46FE0908/WORK/PYTHON/Django/bloggingwebsite/blogs/mixins.py changed, reloading.
WARNING:django.request:Not Found: /favicon.ico
INFO:django.utils.autoreload:/media/utkarshrasal/4846FE1A46FE0908/WORK/PYTHON/Django/bloggingwebsite/blogs/mixins.py changed, reloading.
INFO:django.utils.autoreload:/media/utkarshrasal/4846FE1A46FE0908/WORK/PYTHON/Django/bloggingwebsite/blogs/serializers.py changed, reloading.
INFO:django.utils.autoreload:/media/utkarshrasal/4846FE1A46FE0908/WORK/PYTHON/Django/bloggingwebsite/accounts/serializers.py changed, reloading.
INFO:django.utils.autoreload:/media/utkarshrasal/4846FE1A46FE0908/WORK/PYTHON/Django/bloggingwebsite/blogs/serializers.py changed, reloading.
INFO:django.utils.autoreload:/media/utkarshrasal/4846FE1A46FE0908/WORK/PYTHON/Django/bloggingwebsite/blogs/mixins.py changed, reloading.
INFO:django.utils.autoreload:/media/utkarshrasal/4846FE1A46FE0908/WORK/PYTHON/Django/bloggingwebsite/blogs/serializers.py changed, reloading.
INFO:django.utils.autoreload:/media/utkarshrasal/4846FE1A46FE0908/WORK/PYTHON/Django/bloggingwebsite/blogs/serializers.py changed, reloading.
INFO:django.utils.autoreload:/media/utkarshrasal/4846FE1A46FE0908/WORK/PYTHON/Django/bloggingwebsite/blogs/mixins.py changed, reloading.
INFO:django.utils.autoreload:/media/utkarshrasal/4846FE1A46FE0908/WORK/PYTHON/Django/bloggingwebsite/blogs/mixins.py changed, reloading.
INFO:django.utils.autoreload:/media/utkarshrasal/4846FE1A46FE0908/WORK/PYTHON/Django/bloggingwebsite/accounts/serializers.py changed, reloading.
INFO:django.utils.autoreload:/media/utkarshrasal/4846FE1A46FE0908/WORK/PYTHON/Django/bloggingwebsite/accounts/serializers.py changed, reloading.
INFO:django.utils.autoreload:/media/utkarshrasal/4846FE1A46FE0908/WORK/PYTHON/Django/bloggingwebsite/blogs/serializers.py changed, reloading.
ERROR:django.request:Internal Server Error: /blogs/b7667fa1-9442-41b2-b715-a13b118e2147/likes/
Traceback (most recent call last):
  File "/home/utkarshrasal/.local/lib/python3.8/site-packages/django/core/handlers/exception.py", line 47, in inner
    response = get_response(request)
  File "/home/utkarshrasal/.local/lib/python3.8/site-packages/django/core/handlers/base.py", line 181, in _get_response
    response = wrapped_callback(request, *callback_args, **callback_kwargs)
  File "/home/utkarshrasal/.local/lib/python3.8/site-packages/django/views/decorators/csrf.py", line 54, in wrapped_view
    return view_func(*args, **kwargs)
  File "/home/utkarshrasal/.local/lib/python3.8/site-packages/rest_framework/viewsets.py", line 125, in view
    return self.dispatch(request, *args, **kwargs)
  File "/home/utkarshrasal/.local/lib/python3.8/site-packages/rest_framework/views.py", line 509, in dispatch
    response = self.handle_exception(exc)
  File "/home/utkarshrasal/.local/lib/python3.8/site-packages/rest_framework/views.py", line 469, in handle_exception
    self.raise_uncaught_exception(exc)
  File "/home/utkarshrasal/.local/lib/python3.8/site-packages/rest_framework/views.py", line 480, in raise_uncaught_exception
    raise exc
  File "/home/utkarshrasal/.local/lib/python3.8/site-packages/rest_framework/views.py", line 506, in dispatch
    response = handler(request, *args, **kwargs)
  File "/media/utkarshrasal/4846FE1A46FE0908/WORK/PYTHON/Django/bloggingwebsite/blogs/mixins.py", line 148, in likes
    'data':serializer.data
  File "/home/utkarshrasal/.local/lib/python3.8/site-packages/rest_framework/serializers.py", line 548, in data
    ret = super().data
  File "/home/utkarshrasal/.local/lib/python3.8/site-packages/rest_framework/serializers.py", line 246, in data
    self._data = self.to_representation(self.instance)
  File "/home/utkarshrasal/.local/lib/python3.8/site-packages/rest_framework/serializers.py", line 500, in to_representation
    for field in fields:
  File "/home/utkarshrasal/.local/lib/python3.8/site-packages/rest_framework/serializers.py", line 361, in _readable_fields
    for field in self.fields.values():
  File "/home/utkarshrasal/.local/lib/python3.8/site-packages/django/utils/functional.py", line 48, in __get__
    res = instance.__dict__[self.name] = self.func(instance)
  File "/home/utkarshrasal/.local/lib/python3.8/site-packages/rest_framework/serializers.py", line 349, in fields
    for key, value in self.get_fields().items():
  File "/home/utkarshrasal/.local/lib/python3.8/site-packages/rest_framework/serializers.py", line 1029, in get_fields
    field_names = self.get_field_names(declared_fields, info)
  File "/home/utkarshrasal/.local/lib/python3.8/site-packages/rest_framework/serializers.py", line 1125, in get_field_names
    assert field_name in fields, (
AssertionError: The field 'likes_count' was declared on serializer BlogLikesSerializer, but has not been included in the 'fields' option.
INFO:django.utils.autoreload:/media/utkarshrasal/4846FE1A46FE0908/WORK/PYTHON/Django/bloggingwebsite/blogs/serializers.py changed, reloading.
INFO:django.utils.autoreload:/media/utkarshrasal/4846FE1A46FE0908/WORK/PYTHON/Django/bloggingwebsite/blogs/serializers.py changed, reloading.
INFO:django.utils.autoreload:/media/utkarshrasal/4846FE1A46FE0908/WORK/PYTHON/Django/bloggingwebsite/blogs/views.py changed, reloading.
INFO:django.utils.autoreload:/media/utkarshrasal/4846FE1A46FE0908/WORK/PYTHON/Django/bloggingwebsite/blogs/viewsets.py changed, reloading.
INFO:django.utils.autoreload:/media/utkarshrasal/4846FE1A46FE0908/WORK/PYTHON/Django/bloggingwebsite/blogs/viewsets.py changed, reloading.
INFO:django.utils.autoreload:/media/utkarshrasal/4846FE1A46FE0908/WORK/PYTHON/Django/bloggingwebsite/blogs/urls.py changed, reloading.
ERROR:django.request:Internal Server Error: /tags/
Traceback (most recent call last):
  File "/home/utkarshrasal/.local/lib/python3.8/site-packages/rest_framework/fields.py", line 457, in get_attribute
    return get_attribute(instance, self.source_attrs)
  File "/home/utkarshrasal/.local/lib/python3.8/site-packages/rest_framework/fields.py", line 97, in get_attribute
    instance = getattr(instance, attr)
AttributeError: 'QuerySet' object has no attribute 'name'

During handling of the above exception, another exception occurred:

Traceback (most recent call last):
  File "/home/utkarshrasal/.local/lib/python3.8/site-packages/django/core/handlers/exception.py", line 47, in inner
    response = get_response(request)
  File "/home/utkarshrasal/.local/lib/python3.8/site-packages/django/core/handlers/base.py", line 181, in _get_response
    response = wrapped_callback(request, *callback_args, **callback_kwargs)
  File "/home/utkarshrasal/.local/lib/python3.8/site-packages/django/views/decorators/csrf.py", line 54, in wrapped_view
    return view_func(*args, **kwargs)
  File "/home/utkarshrasal/.local/lib/python3.8/site-packages/rest_framework/viewsets.py", line 125, in view
    return self.dispatch(request, *args, **kwargs)
  File "/home/utkarshrasal/.local/lib/python3.8/site-packages/rest_framework/views.py", line 509, in dispatch
    response = self.handle_exception(exc)
  File "/home/utkarshrasal/.local/lib/python3.8/site-packages/rest_framework/views.py", line 469, in handle_exception
    self.raise_uncaught_exception(exc)
  File "/home/utkarshrasal/.local/lib/python3.8/site-packages/rest_framework/views.py", line 480, in raise_uncaught_exception
    raise exc
  File "/home/utkarshrasal/.local/lib/python3.8/site-packages/rest_framework/views.py", line 506, in dispatch
    response = handler(request, *args, **kwargs)
  File "/media/utkarshrasal/4846FE1A46FE0908/WORK/PYTHON/Django/bloggingwebsite/blogs/viewsets.py", line 171, in list
    'data':serializers.data
  File "/home/utkarshrasal/.local/lib/python3.8/site-packages/rest_framework/serializers.py", line 548, in data
    ret = super().data
  File "/home/utkarshrasal/.local/lib/python3.8/site-packages/rest_framework/serializers.py", line 246, in data
    self._data = self.to_representation(self.instance)
  File "/home/utkarshrasal/.local/lib/python3.8/site-packages/rest_framework/serializers.py", line 502, in to_representation
    attribute = field.get_attribute(instance)
  File "/home/utkarshrasal/.local/lib/python3.8/site-packages/rest_framework/fields.py", line 490, in get_attribute
    raise type(exc)(msg)
AttributeError: Got AttributeError when attempting to get a value for field `name` on serializer `TagsSerializer`.
The serializer field might be named incorrectly and not match any attribute or key on the `QuerySet` instance.
Original exception text was: 'QuerySet' object has no attribute 'name'.
INFO:django.utils.autoreload:/media/utkarshrasal/4846FE1A46FE0908/WORK/PYTHON/Django/bloggingwebsite/blogs/viewsets.py changed, reloading.
INFO:django.utils.autoreload:/media/utkarshrasal/4846FE1A46FE0908/WORK/PYTHON/Django/bloggingwebsite/blogs/viewsets.py changed, reloading.
INFO:django.utils.autoreload:/media/utkarshrasal/4846FE1A46FE0908/WORK/PYTHON/Django/bloggingwebsite/blogs/serializers.py changed, reloading.
INFO:root:created Blog with title 'SeventhBlog'
INFO:django.utils.autoreload:/media/utkarshrasal/4846FE1A46FE0908/WORK/PYTHON/Django/bloggingwebsite/blogs/serializers.py changed, reloading.
INFO:django.utils.autoreload:/media/utkarshrasal/4846FE1A46FE0908/WORK/PYTHON/Django/bloggingwebsite/blogs/views.py changed, reloading.
INFO:root:created Blog with title 'SeventhBlog'
WARNING:django.request:Not Found: /tags/django/blogs
INFO:django.utils.autoreload:/media/utkarshrasal/4846FE1A46FE0908/WORK/PYTHON/Django/bloggingwebsite/blogs/urls.py changed, reloading.
INFO:django.utils.autoreload:/media/utkarshrasal/4846FE1A46FE0908/WORK/PYTHON/Django/bloggingwebsite/blogs/urls.py changed, reloading.
ERROR:django.request:Internal Server Error: /tags/django/
Traceback (most recent call last):
  File "/home/utkarshrasal/.local/lib/python3.8/site-packages/django/core/handlers/exception.py", line 47, in inner
    response = get_response(request)
  File "/home/utkarshrasal/.local/lib/python3.8/site-packages/django/core/handlers/base.py", line 181, in _get_response
    response = wrapped_callback(request, *callback_args, **callback_kwargs)
  File "/home/utkarshrasal/.local/lib/python3.8/site-packages/django/views/decorators/csrf.py", line 54, in wrapped_view
    return view_func(*args, **kwargs)
  File "/home/utkarshrasal/.local/lib/python3.8/site-packages/rest_framework/viewsets.py", line 125, in view
    return self.dispatch(request, *args, **kwargs)
  File "/home/utkarshrasal/.local/lib/python3.8/site-packages/rest_framework/views.py", line 509, in dispatch
    response = self.handle_exception(exc)
  File "/home/utkarshrasal/.local/lib/python3.8/site-packages/rest_framework/views.py", line 469, in handle_exception
    self.raise_uncaught_exception(exc)
  File "/home/utkarshrasal/.local/lib/python3.8/site-packages/rest_framework/views.py", line 480, in raise_uncaught_exception
    raise exc
  File "/home/utkarshrasal/.local/lib/python3.8/site-packages/rest_framework/views.py", line 506, in dispatch
    response = handler(request, *args, **kwargs)
  File "/home/utkarshrasal/.local/lib/python3.8/site-packages/rest_framework/mixins.py", line 54, in retrieve
    instance = self.get_object()
  File "/home/utkarshrasal/.local/lib/python3.8/site-packages/rest_framework/generics.py", line 83, in get_object
    queryset = self.filter_queryset(self.get_queryset())
  File "/home/utkarshrasal/.local/lib/python3.8/site-packages/rest_framework/generics.py", line 63, in get_queryset
    assert self.queryset is not None, (
AssertionError: 'TagsView' should either include a `queryset` attribute, or override the `get_queryset()` method.
INFO:django.utils.autoreload:/media/utkarshrasal/4846FE1A46FE0908/WORK/PYTHON/Django/bloggingwebsite/blogs/mixins.py changed, reloading.
WARNING:django.request:Not Found: /tags/django/blogs
WARNING:django.request:Not Found: /tags/django/blogs/
INFO:django.utils.autoreload:/media/utkarshrasal/4846FE1A46FE0908/WORK/PYTHON/Django/bloggingwebsite/blogs/mixins.py changed, reloading.
WARNING:django.request:Not Found: /tags/django/blogs/
WARNING:django.request:Not Found: /tags/django/blogs/
ERROR:django.request:Internal Server Error: /tags/django/
Traceback (most recent call last):
  File "/home/utkarshrasal/.local/lib/python3.8/site-packages/django/core/handlers/exception.py", line 47, in inner
    response = get_response(request)
  File "/home/utkarshrasal/.local/lib/python3.8/site-packages/django/core/handlers/base.py", line 181, in _get_response
    response = wrapped_callback(request, *callback_args, **callback_kwargs)
  File "/home/utkarshrasal/.local/lib/python3.8/site-packages/django/views/decorators/csrf.py", line 54, in wrapped_view
    return view_func(*args, **kwargs)
  File "/home/utkarshrasal/.local/lib/python3.8/site-packages/rest_framework/viewsets.py", line 125, in view
    return self.dispatch(request, *args, **kwargs)
  File "/home/utkarshrasal/.local/lib/python3.8/site-packages/rest_framework/views.py", line 509, in dispatch
    response = self.handle_exception(exc)
  File "/home/utkarshrasal/.local/lib/python3.8/site-packages/rest_framework/views.py", line 469, in handle_exception
    self.raise_uncaught_exception(exc)
  File "/home/utkarshrasal/.local/lib/python3.8/site-packages/rest_framework/views.py", line 480, in raise_uncaught_exception
    raise exc
  File "/home/utkarshrasal/.local/lib/python3.8/site-packages/rest_framework/views.py", line 506, in dispatch
    response = handler(request, *args, **kwargs)
  File "/home/utkarshrasal/.local/lib/python3.8/site-packages/rest_framework/mixins.py", line 54, in retrieve
    instance = self.get_object()
  File "/home/utkarshrasal/.local/lib/python3.8/site-packages/rest_framework/generics.py", line 83, in get_object
    queryset = self.filter_queryset(self.get_queryset())
  File "/home/utkarshrasal/.local/lib/python3.8/site-packages/rest_framework/generics.py", line 63, in get_queryset
    assert self.queryset is not None, (
AssertionError: 'TagsView' should either include a `queryset` attribute, or override the `get_queryset()` method.
INFO:django.utils.autoreload:/media/utkarshrasal/4846FE1A46FE0908/WORK/PYTHON/Django/bloggingwebsite/blogs/urls.py changed, reloading.
WARNING:django.request:Not Found: /tags/django/
WARNING:django.request:Not Found: /tags/django
WARNING:django.request:Not Found: /tags/django/
WARNING:django.request:Not Found: /tags/
INFO:django.utils.autoreload:/media/utkarshrasal/4846FE1A46FE0908/WORK/PYTHON/Django/bloggingwebsite/blogs/urls.py changed, reloading.
ERROR:django.request:Internal Server Error: /tags/utkarsh/
Traceback (most recent call last):
  File "/home/utkarshrasal/.local/lib/python3.8/site-packages/django/core/handlers/exception.py", line 47, in inner
    response = get_response(request)
  File "/home/utkarshrasal/.local/lib/python3.8/site-packages/django/core/handlers/base.py", line 181, in _get_response
    response = wrapped_callback(request, *callback_args, **callback_kwargs)
  File "/home/utkarshrasal/.local/lib/python3.8/site-packages/django/views/decorators/csrf.py", line 54, in wrapped_view
    return view_func(*args, **kwargs)
  File "/home/utkarshrasal/.local/lib/python3.8/site-packages/rest_framework/viewsets.py", line 125, in view
    return self.dispatch(request, *args, **kwargs)
  File "/home/utkarshrasal/.local/lib/python3.8/site-packages/rest_framework/views.py", line 509, in dispatch
    response = self.handle_exception(exc)
  File "/home/utkarshrasal/.local/lib/python3.8/site-packages/rest_framework/views.py", line 469, in handle_exception
    self.raise_uncaught_exception(exc)
  File "/home/utkarshrasal/.local/lib/python3.8/site-packages/rest_framework/views.py", line 480, in raise_uncaught_exception
    raise exc
  File "/home/utkarshrasal/.local/lib/python3.8/site-packages/rest_framework/views.py", line 506, in dispatch
    response = handler(request, *args, **kwargs)
  File "/home/utkarshrasal/.local/lib/python3.8/site-packages/rest_framework/mixins.py", line 54, in retrieve
    instance = self.get_object()
  File "/home/utkarshrasal/.local/lib/python3.8/site-packages/rest_framework/generics.py", line 83, in get_object
    queryset = self.filter_queryset(self.get_queryset())
  File "/home/utkarshrasal/.local/lib/python3.8/site-packages/rest_framework/generics.py", line 63, in get_queryset
    assert self.queryset is not None, (
AssertionError: 'TagsView' should either include a `queryset` attribute, or override the `get_queryset()` method.
INFO:django.utils.autoreload:/media/utkarshrasal/4846FE1A46FE0908/WORK/PYTHON/Django/bloggingwebsite/blogs/viewsets.py changed, reloading.
WARNING:django.request:Not Found: /tags/utkarsh/
WARNING:django.request:Not Found: /tags/django/
WARNING:django.request:Not Found: /tags/django/
INFO:django.utils.autoreload:/media/utkarshrasal/4846FE1A46FE0908/WORK/PYTHON/Django/bloggingwebsite/blogs/viewsets.py changed, reloading.
INFO:django.utils.autoreload:/media/utkarshrasal/4846FE1A46FE0908/WORK/PYTHON/Django/bloggingwebsite/blogs/mixins.py changed, reloading.
WARNING:django.request:Not Found: /tags/django/
INFO:django.utils.autoreload:/media/utkarshrasal/4846FE1A46FE0908/WORK/PYTHON/Django/bloggingwebsite/blogs/mixins.py changed, reloading.
WARNING:django.request:Not Found: /tags/django/blogs
INFO:django.utils.autoreload:/media/utkarshrasal/4846FE1A46FE0908/WORK/PYTHON/Django/bloggingwebsite/blogs/views.py changed, reloading.
ERROR:django.request:Internal Server Error: /tags/django/blogs/
Traceback (most recent call last):
  File "/home/utkarshrasal/.local/lib/python3.8/site-packages/django/core/handlers/exception.py", line 47, in inner
    response = get_response(request)
  File "/home/utkarshrasal/.local/lib/python3.8/site-packages/django/core/handlers/base.py", line 181, in _get_response
    response = wrapped_callback(request, *callback_args, **callback_kwargs)
  File "/home/utkarshrasal/.local/lib/python3.8/site-packages/django/views/decorators/csrf.py", line 54, in wrapped_view
    return view_func(*args, **kwargs)
  File "/home/utkarshrasal/.local/lib/python3.8/site-packages/rest_framework/viewsets.py", line 125, in view
    return self.dispatch(request, *args, **kwargs)
  File "/home/utkarshrasal/.local/lib/python3.8/site-packages/rest_framework/views.py", line 509, in dispatch
    response = self.handle_exception(exc)
  File "/home/utkarshrasal/.local/lib/python3.8/site-packages/rest_framework/views.py", line 469, in handle_exception
    self.raise_uncaught_exception(exc)
  File "/home/utkarshrasal/.local/lib/python3.8/site-packages/rest_framework/views.py", line 480, in raise_uncaught_exception
    raise exc
  File "/home/utkarshrasal/.local/lib/python3.8/site-packages/rest_framework/views.py", line 506, in dispatch
    response = handler(request, *args, **kwargs)
  File "/media/utkarshrasal/4846FE1A46FE0908/WORK/PYTHON/Django/bloggingwebsite/blogs/mixins.py", line 156, in blogs
    'message':f'this is the {name} of the tag',
NameError: name 'name' is not defined
INFO:django.utils.autoreload:/media/utkarshrasal/4846FE1A46FE0908/WORK/PYTHON/Django/bloggingwebsite/blogs/mixins.py changed, reloading.
ERROR:django.request:Internal Server Error: /tags/django/blogs/
Traceback (most recent call last):
  File "/home/utkarshrasal/.local/lib/python3.8/site-packages/django/core/handlers/exception.py", line 47, in inner
    response = get_response(request)
  File "/home/utkarshrasal/.local/lib/python3.8/site-packages/django/core/handlers/base.py", line 181, in _get_response
    response = wrapped_callback(request, *callback_args, **callback_kwargs)
  File "/home/utkarshrasal/.local/lib/python3.8/site-packages/django/views/decorators/csrf.py", line 54, in wrapped_view
    return view_func(*args, **kwargs)
  File "/home/utkarshrasal/.local/lib/python3.8/site-packages/rest_framework/viewsets.py", line 125, in view
    return self.dispatch(request, *args, **kwargs)
  File "/home/utkarshrasal/.local/lib/python3.8/site-packages/rest_framework/views.py", line 509, in dispatch
    response = self.handle_exception(exc)
  File "/home/utkarshrasal/.local/lib/python3.8/site-packages/rest_framework/views.py", line 469, in handle_exception
    self.raise_uncaught_exception(exc)
  File "/home/utkarshrasal/.local/lib/python3.8/site-packages/rest_framework/views.py", line 480, in raise_uncaught_exception
    raise exc
  File "/home/utkarshrasal/.local/lib/python3.8/site-packages/rest_framework/views.py", line 506, in dispatch
    response = handler(request, *args, **kwargs)
TypeError: blogs() missing 1 required positional argument: 'name'
INFO:django.utils.autoreload:/media/utkarshrasal/4846FE1A46FE0908/WORK/PYTHON/Django/bloggingwebsite/blogs/mixins.py changed, reloading.
INFO:django.utils.autoreload:/media/utkarshrasal/4846FE1A46FE0908/WORK/PYTHON/Django/bloggingwebsite/blogs/mixins.py changed, reloading.
ERROR:django.request:Internal Server Error: /tags/django/blogs/
Traceback (most recent call last):
  File "/home/utkarshrasal/.local/lib/python3.8/site-packages/django/core/handlers/exception.py", line 47, in inner
    response = get_response(request)
  File "/home/utkarshrasal/.local/lib/python3.8/site-packages/django/core/handlers/base.py", line 181, in _get_response
    response = wrapped_callback(request, *callback_args, **callback_kwargs)
  File "/home/utkarshrasal/.local/lib/python3.8/site-packages/django/views/decorators/csrf.py", line 54, in wrapped_view
    return view_func(*args, **kwargs)
  File "/home/utkarshrasal/.local/lib/python3.8/site-packages/rest_framework/viewsets.py", line 125, in view
    return self.dispatch(request, *args, **kwargs)
  File "/home/utkarshrasal/.local/lib/python3.8/site-packages/rest_framework/views.py", line 509, in dispatch
    response = self.handle_exception(exc)
  File "/home/utkarshrasal/.local/lib/python3.8/site-packages/rest_framework/views.py", line 469, in handle_exception
    self.raise_uncaught_exception(exc)
  File "/home/utkarshrasal/.local/lib/python3.8/site-packages/rest_framework/views.py", line 480, in raise_uncaught_exception
    raise exc
  File "/home/utkarshrasal/.local/lib/python3.8/site-packages/rest_framework/views.py", line 506, in dispatch
    response = handler(request, *args, **kwargs)
TypeError: blogs() missing 1 required positional argument: 'name'
INFO:django.utils.autoreload:/media/utkarshrasal/4846FE1A46FE0908/WORK/PYTHON/Django/bloggingwebsite/blogs/mixins.py changed, reloading.
INFO:django.utils.autoreload:/media/utkarshrasal/4846FE1A46FE0908/WORK/PYTHON/Django/bloggingwebsite/blogs/mixins.py changed, reloading.
INFO:django.utils.autoreload:/media/utkarshrasal/4846FE1A46FE0908/WORK/PYTHON/Django/bloggingwebsite/blogs/mixins.py changed, reloading.
INFO:django.utils.autoreload:/media/utkarshrasal/4846FE1A46FE0908/WORK/PYTHON/Django/bloggingwebsite/blogs/mixins.py changed, reloading.
INFO:root:created Blog with title 'Eigthth'
INFO:django.utils.autoreload:/media/utkarshrasal/4846FE1A46FE0908/WORK/PYTHON/Django/bloggingwebsite/blogs/serializers.py changed, reloading.
INFO:django.utils.autoreload:/media/utkarshrasal/4846FE1A46FE0908/WORK/PYTHON/Django/bloggingwebsite/blogs/mixins.py changed, reloading.
INFO:django.utils.autoreload:/media/utkarshrasal/4846FE1A46FE0908/WORK/PYTHON/Django/bloggingwebsite/blogs/mixins.py changed, reloading.
INFO:django.utils.autoreload:/media/utkarshrasal/4846FE1A46FE0908/WORK/PYTHON/Django/bloggingwebsite/blogs/serializers.py changed, reloading.
INFO:django.utils.autoreload:/media/utkarshrasal/4846FE1A46FE0908/WORK/PYTHON/Django/bloggingwebsite/blogs/mixins.py changed, reloading.
ERROR:django.request:Internal Server Error: /tags/django/blogs/
Traceback (most recent call last):
  File "/home/utkarshrasal/.local/lib/python3.8/site-packages/django/core/handlers/exception.py", line 47, in inner
    response = get_response(request)
  File "/home/utkarshrasal/.local/lib/python3.8/site-packages/django/core/handlers/base.py", line 181, in _get_response
    response = wrapped_callback(request, *callback_args, **callback_kwargs)
  File "/home/utkarshrasal/.local/lib/python3.8/site-packages/django/views/decorators/csrf.py", line 54, in wrapped_view
    return view_func(*args, **kwargs)
  File "/home/utkarshrasal/.local/lib/python3.8/site-packages/rest_framework/viewsets.py", line 125, in view
    return self.dispatch(request, *args, **kwargs)
  File "/home/utkarshrasal/.local/lib/python3.8/site-packages/rest_framework/views.py", line 509, in dispatch
    response = self.handle_exception(exc)
  File "/home/utkarshrasal/.local/lib/python3.8/site-packages/rest_framework/views.py", line 469, in handle_exception
    self.raise_uncaught_exception(exc)
  File "/home/utkarshrasal/.local/lib/python3.8/site-packages/rest_framework/views.py", line 480, in raise_uncaught_exception
    raise exc
  File "/home/utkarshrasal/.local/lib/python3.8/site-packages/rest_framework/views.py", line 506, in dispatch
    response = handler(request, *args, **kwargs)
  File "/media/utkarshrasal/4846FE1A46FE0908/WORK/PYTHON/Django/bloggingwebsite/blogs/mixins.py", line 155, in blogs
    tagname = kwargs.get('pk')
NameError: name 'a' is not defined
INFO:django.utils.autoreload:/media/utkarshrasal/4846FE1A46FE0908/WORK/PYTHON/Django/bloggingwebsite/blogs/mixins.py changed, reloading.
INFO:django.utils.autoreload:/media/utkarshrasal/4846FE1A46FE0908/WORK/PYTHON/Django/bloggingwebsite/blogs/mixins.py changed, reloading.
ERROR:django.request:Internal Server Error: /tags/first/blogs/
Traceback (most recent call last):
  File "/home/utkarshrasal/.local/lib/python3.8/site-packages/rest_framework/fields.py", line 457, in get_attribute
    return get_attribute(instance, self.source_attrs)
  File "/home/utkarshrasal/.local/lib/python3.8/site-packages/rest_framework/fields.py", line 97, in get_attribute
    instance = getattr(instance, attr)
AttributeError: 'Blogs' object has no attribute 'tag'

During handling of the above exception, another exception occurred:

Traceback (most recent call last):
  File "/home/utkarshrasal/.local/lib/python3.8/site-packages/django/core/handlers/exception.py", line 47, in inner
    response = get_response(request)
  File "/home/utkarshrasal/.local/lib/python3.8/site-packages/django/core/handlers/base.py", line 181, in _get_response
    response = wrapped_callback(request, *callback_args, **callback_kwargs)
  File "/home/utkarshrasal/.local/lib/python3.8/site-packages/django/views/decorators/csrf.py", line 54, in wrapped_view
    return view_func(*args, **kwargs)
  File "/home/utkarshrasal/.local/lib/python3.8/site-packages/rest_framework/viewsets.py", line 125, in view
    return self.dispatch(request, *args, **kwargs)
  File "/home/utkarshrasal/.local/lib/python3.8/site-packages/rest_framework/views.py", line 509, in dispatch
    response = self.handle_exception(exc)
  File "/home/utkarshrasal/.local/lib/python3.8/site-packages/rest_framework/views.py", line 469, in handle_exception
    self.raise_uncaught_exception(exc)
  File "/home/utkarshrasal/.local/lib/python3.8/site-packages/rest_framework/views.py", line 480, in raise_uncaught_exception
    raise exc
  File "/home/utkarshrasal/.local/lib/python3.8/site-packages/rest_framework/views.py", line 506, in dispatch
    response = handler(request, *args, **kwargs)
  File "/media/utkarshrasal/4846FE1A46FE0908/WORK/PYTHON/Django/bloggingwebsite/blogs/mixins.py", line 162, in blogs
    'data':serializer.data
  File "/home/utkarshrasal/.local/lib/python3.8/site-packages/rest_framework/serializers.py", line 745, in data
    ret = super().data
  File "/home/utkarshrasal/.local/lib/python3.8/site-packages/rest_framework/serializers.py", line 246, in data
    self._data = self.to_representation(self.instance)
  File "/home/utkarshrasal/.local/lib/python3.8/site-packages/rest_framework/serializers.py", line 663, in to_representation
    return [
  File "/home/utkarshrasal/.local/lib/python3.8/site-packages/rest_framework/serializers.py", line 664, in <listcomp>
    self.child.to_representation(item) for item in iterable
  File "/home/utkarshrasal/.local/lib/python3.8/site-packages/rest_framework/serializers.py", line 502, in to_representation
    attribute = field.get_attribute(instance)
  File "/home/utkarshrasal/.local/lib/python3.8/site-packages/rest_framework/fields.py", line 490, in get_attribute
    raise type(exc)(msg)
AttributeError: Got AttributeError when attempting to get a value for field `tag` on serializer `BlogTagsSerializer`.
The serializer field might be named incorrectly and not match any attribute or key on the `Blogs` instance.
Original exception text was: 'Blogs' object has no attribute 'tag'.
ERROR:django.request:Internal Server Error: /tags/first/blogs/
Traceback (most recent call last):
  File "/home/utkarshrasal/.local/lib/python3.8/site-packages/rest_framework/fields.py", line 457, in get_attribute
    return get_attribute(instance, self.source_attrs)
  File "/home/utkarshrasal/.local/lib/python3.8/site-packages/rest_framework/fields.py", line 97, in get_attribute
    instance = getattr(instance, attr)
AttributeError: 'Blogs' object has no attribute 'tag'

During handling of the above exception, another exception occurred:

Traceback (most recent call last):
  File "/home/utkarshrasal/.local/lib/python3.8/site-packages/django/core/handlers/exception.py", line 47, in inner
    response = get_response(request)
  File "/home/utkarshrasal/.local/lib/python3.8/site-packages/django/core/handlers/base.py", line 181, in _get_response
    response = wrapped_callback(request, *callback_args, **callback_kwargs)
  File "/home/utkarshrasal/.local/lib/python3.8/site-packages/django/views/decorators/csrf.py", line 54, in wrapped_view
    return view_func(*args, **kwargs)
  File "/home/utkarshrasal/.local/lib/python3.8/site-packages/rest_framework/viewsets.py", line 125, in view
    return self.dispatch(request, *args, **kwargs)
  File "/home/utkarshrasal/.local/lib/python3.8/site-packages/rest_framework/views.py", line 509, in dispatch
    response = self.handle_exception(exc)
  File "/home/utkarshrasal/.local/lib/python3.8/site-packages/rest_framework/views.py", line 469, in handle_exception
    self.raise_uncaught_exception(exc)
  File "/home/utkarshrasal/.local/lib/python3.8/site-packages/rest_framework/views.py", line 480, in raise_uncaught_exception
    raise exc
  File "/home/utkarshrasal/.local/lib/python3.8/site-packages/rest_framework/views.py", line 506, in dispatch
    response = handler(request, *args, **kwargs)
  File "/media/utkarshrasal/4846FE1A46FE0908/WORK/PYTHON/Django/bloggingwebsite/blogs/mixins.py", line 162, in blogs
    'data':serializer.data
  File "/home/utkarshrasal/.local/lib/python3.8/site-packages/rest_framework/serializers.py", line 745, in data
    ret = super().data
  File "/home/utkarshrasal/.local/lib/python3.8/site-packages/rest_framework/serializers.py", line 246, in data
    self._data = self.to_representation(self.instance)
  File "/home/utkarshrasal/.local/lib/python3.8/site-packages/rest_framework/serializers.py", line 663, in to_representation
    return [
  File "/home/utkarshrasal/.local/lib/python3.8/site-packages/rest_framework/serializers.py", line 664, in <listcomp>
    self.child.to_representation(item) for item in iterable
  File "/home/utkarshrasal/.local/lib/python3.8/site-packages/rest_framework/serializers.py", line 502, in to_representation
    attribute = field.get_attribute(instance)
  File "/home/utkarshrasal/.local/lib/python3.8/site-packages/rest_framework/fields.py", line 490, in get_attribute
    raise type(exc)(msg)
AttributeError: Got AttributeError when attempting to get a value for field `tag` on serializer `BlogTagsSerializer`.
The serializer field might be named incorrectly and not match any attribute or key on the `Blogs` instance.
Original exception text was: 'Blogs' object has no attribute 'tag'.
INFO:django.utils.autoreload:/media/utkarshrasal/4846FE1A46FE0908/WORK/PYTHON/Django/bloggingwebsite/blogs/mixins.py changed, reloading.
INFO:django.utils.autoreload:/media/utkarshrasal/4846FE1A46FE0908/WORK/PYTHON/Django/bloggingwebsite/blogs/serializers.py changed, reloading.
ERROR:django.request:Internal Server Error: /tags/first/blogs/
Traceback (most recent call last):
  File "/home/utkarshrasal/.local/lib/python3.8/site-packages/rest_framework/fields.py", line 457, in get_attribute
    return get_attribute(instance, self.source_attrs)
  File "/home/utkarshrasal/.local/lib/python3.8/site-packages/rest_framework/fields.py", line 97, in get_attribute
    instance = getattr(instance, attr)
AttributeError: 'Blogs' object has no attribute 'blogs'

During handling of the above exception, another exception occurred:

Traceback (most recent call last):
  File "/home/utkarshrasal/.local/lib/python3.8/site-packages/django/core/handlers/exception.py", line 47, in inner
    response = get_response(request)
  File "/home/utkarshrasal/.local/lib/python3.8/site-packages/django/core/handlers/base.py", line 181, in _get_response
    response = wrapped_callback(request, *callback_args, **callback_kwargs)
  File "/home/utkarshrasal/.local/lib/python3.8/site-packages/django/views/decorators/csrf.py", line 54, in wrapped_view
    return view_func(*args, **kwargs)
  File "/home/utkarshrasal/.local/lib/python3.8/site-packages/rest_framework/viewsets.py", line 125, in view
    return self.dispatch(request, *args, **kwargs)
  File "/home/utkarshrasal/.local/lib/python3.8/site-packages/rest_framework/views.py", line 509, in dispatch
    response = self.handle_exception(exc)
  File "/home/utkarshrasal/.local/lib/python3.8/site-packages/rest_framework/views.py", line 469, in handle_exception
    self.raise_uncaught_exception(exc)
  File "/home/utkarshrasal/.local/lib/python3.8/site-packages/rest_framework/views.py", line 480, in raise_uncaught_exception
    raise exc
  File "/home/utkarshrasal/.local/lib/python3.8/site-packages/rest_framework/views.py", line 506, in dispatch
    response = handler(request, *args, **kwargs)
  File "/media/utkarshrasal/4846FE1A46FE0908/WORK/PYTHON/Django/bloggingwebsite/blogs/mixins.py", line 155, in blogs
    tagname = kwargs.get('pk')
  File "/home/utkarshrasal/.local/lib/python3.8/site-packages/rest_framework/serializers.py", line 745, in data
    ret = super().data
  File "/home/utkarshrasal/.local/lib/python3.8/site-packages/rest_framework/serializers.py", line 246, in data
    self._data = self.to_representation(self.instance)
  File "/home/utkarshrasal/.local/lib/python3.8/site-packages/rest_framework/serializers.py", line 663, in to_representation
    return [
  File "/home/utkarshrasal/.local/lib/python3.8/site-packages/rest_framework/serializers.py", line 664, in <listcomp>
    self.child.to_representation(item) for item in iterable
  File "/home/utkarshrasal/.local/lib/python3.8/site-packages/rest_framework/serializers.py", line 502, in to_representation
    attribute = field.get_attribute(instance)
  File "/home/utkarshrasal/.local/lib/python3.8/site-packages/rest_framework/fields.py", line 490, in get_attribute
    raise type(exc)(msg)
AttributeError: Got AttributeError when attempting to get a value for field `blogs` on serializer `BlogTagsSerializer`.
The serializer field might be named incorrectly and not match any attribute or key on the `Blogs` instance.
Original exception text was: 'Blogs' object has no attribute 'blogs'.
INFO:django.utils.autoreload:/media/utkarshrasal/4846FE1A46FE0908/WORK/PYTHON/Django/bloggingwebsite/blogs/serializers.py changed, reloading.
INFO:django.utils.autoreload:/media/utkarshrasal/4846FE1A46FE0908/WORK/PYTHON/Django/bloggingwebsite/blogs/mixins.py changed, reloading.
WARNING:django.request:Not Found: /favicon.ico
WARNING:django.request:Not Found: /tags/<str:name>/
WARNING:django.request:Not Found: /tags/<str:name>/
WARNING:django.request:Not Found: /tags/<str:name>/
WARNING:django.request:Not Found: /favicon.ico
WARNING:django.request:Unauthorized: /blogs/b8aefe5b-4d71-42c7-9ee9-fa2fd50b8bed/likes/
ERROR:django.request:Internal Server Error: /tags/first/blogs/
Traceback (most recent call last):
  File "/home/utkarshrasal/.local/lib/python3.8/site-packages/rest_framework/fields.py", line 457, in get_attribute
    return get_attribute(instance, self.source_attrs)
  File "/home/utkarshrasal/.local/lib/python3.8/site-packages/rest_framework/fields.py", line 97, in get_attribute
    instance = getattr(instance, attr)
AttributeError: 'Blogs' object has no attribute 'blogs'

During handling of the above exception, another exception occurred:

Traceback (most recent call last):
  File "/home/utkarshrasal/.local/lib/python3.8/site-packages/django/core/handlers/exception.py", line 47, in inner
    response = get_response(request)
  File "/home/utkarshrasal/.local/lib/python3.8/site-packages/django/core/handlers/base.py", line 181, in _get_response
    response = wrapped_callback(request, *callback_args, **callback_kwargs)
  File "/home/utkarshrasal/.local/lib/python3.8/site-packages/django/views/decorators/csrf.py", line 54, in wrapped_view
    return view_func(*args, **kwargs)
  File "/home/utkarshrasal/.local/lib/python3.8/site-packages/rest_framework/viewsets.py", line 125, in view
    return self.dispatch(request, *args, **kwargs)
  File "/home/utkarshrasal/.local/lib/python3.8/site-packages/rest_framework/views.py", line 509, in dispatch
    response = self.handle_exception(exc)
  File "/home/utkarshrasal/.local/lib/python3.8/site-packages/rest_framework/views.py", line 469, in handle_exception
    self.raise_uncaught_exception(exc)
  File "/home/utkarshrasal/.local/lib/python3.8/site-packages/rest_framework/views.py", line 480, in raise_uncaught_exception
    raise exc
  File "/home/utkarshrasal/.local/lib/python3.8/site-packages/rest_framework/views.py", line 506, in dispatch
    response = handler(request, *args, **kwargs)
  File "/media/utkarshrasal/4846FE1A46FE0908/WORK/PYTHON/Django/bloggingwebsite/blogs/mixins.py", line 161, in blogs
    'status':True,
  File "/home/utkarshrasal/.local/lib/python3.8/site-packages/rest_framework/serializers.py", line 745, in data
    ret = super().data
  File "/home/utkarshrasal/.local/lib/python3.8/site-packages/rest_framework/serializers.py", line 246, in data
    self._data = self.to_representation(self.instance)
  File "/home/utkarshrasal/.local/lib/python3.8/site-packages/rest_framework/serializers.py", line 663, in to_representation
    return [
  File "/home/utkarshrasal/.local/lib/python3.8/site-packages/rest_framework/serializers.py", line 664, in <listcomp>
    self.child.to_representation(item) for item in iterable
  File "/home/utkarshrasal/.local/lib/python3.8/site-packages/rest_framework/serializers.py", line 502, in to_representation
    attribute = field.get_attribute(instance)
  File "/home/utkarshrasal/.local/lib/python3.8/site-packages/rest_framework/fields.py", line 490, in get_attribute
    raise type(exc)(msg)
AttributeError: Got AttributeError when attempting to get a value for field `blogs` on serializer `BlogTagsSerializer`.
The serializer field might be named incorrectly and not match any attribute or key on the `Blogs` instance.
Original exception text was: 'Blogs' object has no attribute 'blogs'.
INFO:django.utils.autoreload:/media/utkarshrasal/4846FE1A46FE0908/WORK/PYTHON/Django/bloggingwebsite/blogs/mixins.py changed, reloading.
INFO:django.utils.autoreload:/media/utkarshrasal/4846FE1A46FE0908/WORK/PYTHON/Django/bloggingwebsite/blogs/serializers.py changed, reloading.
INFO:django.utils.autoreload:/media/utkarshrasal/4846FE1A46FE0908/WORK/PYTHON/Django/bloggingwebsite/blogs/serializers.py changed, reloading.
INFO:django.utils.autoreload:/media/utkarshrasal/4846FE1A46FE0908/WORK/PYTHON/Django/bloggingwebsite/blogs/serializers.py changed, reloading.
INFO:django.utils.autoreload:/media/utkarshrasal/4846FE1A46FE0908/WORK/PYTHON/Django/bloggingwebsite/blogs/mixins.py changed, reloading.
INFO:django.utils.autoreload:/media/utkarshrasal/4846FE1A46FE0908/WORK/PYTHON/Django/bloggingwebsite/blogs/serializers.py changed, reloading.
INFO:django.utils.autoreload:/media/utkarshrasal/4846FE1A46FE0908/WORK/PYTHON/Django/bloggingwebsite/blogs/mixins.py changed, reloading.
INFO:django.utils.autoreload:/media/utkarshrasal/4846FE1A46FE0908/WORK/PYTHON/Django/bloggingwebsite/blogs/mixins.py changed, reloading.
INFO:django.utils.autoreload:/media/utkarshrasal/4846FE1A46FE0908/WORK/PYTHON/Django/bloggingwebsite/blogs/mixins.py changed, reloading.
INFO:django.utils.autoreload:/media/utkarshrasal/4846FE1A46FE0908/WORK/PYTHON/Django/bloggingwebsite/blogs/mixins.py changed, reloading.
INFO:django.utils.autoreload:/media/utkarshrasal/4846FE1A46FE0908/WORK/PYTHON/Django/bloggingwebsite/blogs/mixins.py changed, reloading.
ERROR:django.request:Internal Server Error: /tags/first/blogs/
Traceback (most recent call last):
  File "/home/utkarshrasal/.local/lib/python3.8/site-packages/django/core/handlers/exception.py", line 47, in inner
    response = get_response(request)
  File "/home/utkarshrasal/.local/lib/python3.8/site-packages/django/core/handlers/base.py", line 181, in _get_response
    response = wrapped_callback(request, *callback_args, **callback_kwargs)
  File "/home/utkarshrasal/.local/lib/python3.8/site-packages/django/views/decorators/csrf.py", line 54, in wrapped_view
    return view_func(*args, **kwargs)
  File "/home/utkarshrasal/.local/lib/python3.8/site-packages/rest_framework/viewsets.py", line 125, in view
    return self.dispatch(request, *args, **kwargs)
  File "/home/utkarshrasal/.local/lib/python3.8/site-packages/rest_framework/views.py", line 509, in dispatch
    response = self.handle_exception(exc)
  File "/home/utkarshrasal/.local/lib/python3.8/site-packages/rest_framework/views.py", line 469, in handle_exception
    self.raise_uncaught_exception(exc)
  File "/home/utkarshrasal/.local/lib/python3.8/site-packages/rest_framework/views.py", line 480, in raise_uncaught_exception
    raise exc
  File "/home/utkarshrasal/.local/lib/python3.8/site-packages/rest_framework/views.py", line 506, in dispatch
    response = handler(request, *args, **kwargs)
  File "/media/utkarshrasal/4846FE1A46FE0908/WORK/PYTHON/Django/bloggingwebsite/blogs/mixins.py", line 162, in blogs
    'data':serializer.data['json']
TypeError: list indices must be integers or slices, not str
INFO:django.utils.autoreload:/media/utkarshrasal/4846FE1A46FE0908/WORK/PYTHON/Django/bloggingwebsite/blogs/mixins.py changed, reloading.
INFO:django.utils.autoreload:/media/utkarshrasal/4846FE1A46FE0908/WORK/PYTHON/Django/bloggingwebsite/blogs/serializers.py changed, reloading.
INFO:django.utils.autoreload:/media/utkarshrasal/4846FE1A46FE0908/WORK/PYTHON/Django/bloggingwebsite/blogs/serializers.py changed, reloading.
WARNING:django.request:Not Found: /favicon.ico
INFO:django.utils.autoreload:/media/utkarshrasal/4846FE1A46FE0908/WORK/PYTHON/Django/bloggingwebsite/blogs/models.py changed, reloading.
WARNING:django.request:Not Found: /favicon.ico
INFO:django.utils.autoreload:/media/utkarshrasal/4846FE1A46FE0908/WORK/PYTHON/Django/bloggingwebsite/blogs/mixins.py changed, reloading.
INFO:django.utils.autoreload:/media/utkarshrasal/4846FE1A46FE0908/WORK/PYTHON/Django/bloggingwebsite/blogs/models.py changed, reloading.
INFO:django.utils.autoreload:/media/utkarshrasal/4846FE1A46FE0908/WORK/PYTHON/Django/bloggingwebsite/blogs/models.py changed, reloading.
INFO:django.utils.autoreload:/media/utkarshrasal/4846FE1A46FE0908/WORK/PYTHON/Django/bloggingwebsite/blogs/serializers.py changed, reloading.
INFO:django.utils.autoreload:/media/utkarshrasal/4846FE1A46FE0908/WORK/PYTHON/Django/bloggingwebsite/blogs/mixins.py changed, reloading.
INFO:django.utils.autoreload:/media/utkarshrasal/4846FE1A46FE0908/WORK/PYTHON/Django/bloggingwebsite/blogs/viewsets.py changed, reloading.
INFO:django.utils.autoreload:/media/utkarshrasal/4846FE1A46FE0908/WORK/PYTHON/Django/bloggingwebsite/blogs/path.py changed, reloading.
INFO:django.utils.autoreload:/media/utkarshrasal/4846FE1A46FE0908/WORK/PYTHON/Django/bloggingwebsite/blogs/path.py changed, reloading.
INFO:django.utils.autoreload:/media/utkarshrasal/4846FE1A46FE0908/WORK/PYTHON/Django/bloggingwebsite/blogs/path.py changed, reloading.
INFO:root:created Blog with title 'NinthBlog'
ERROR:django.request:Internal Server Error: /blogs/
Traceback (most recent call last):
  File "/home/utkarshrasal/.local/lib/python3.8/site-packages/django/core/handlers/exception.py", line 47, in inner
    response = get_response(request)
  File "/home/utkarshrasal/.local/lib/python3.8/site-packages/django/core/handlers/base.py", line 181, in _get_response
    response = wrapped_callback(request, *callback_args, **callback_kwargs)
  File "/home/utkarshrasal/.local/lib/python3.8/site-packages/django/views/decorators/csrf.py", line 54, in wrapped_view
    return view_func(*args, **kwargs)
  File "/home/utkarshrasal/.local/lib/python3.8/site-packages/rest_framework/viewsets.py", line 125, in view
    return self.dispatch(request, *args, **kwargs)
  File "/home/utkarshrasal/.local/lib/python3.8/site-packages/rest_framework/views.py", line 509, in dispatch
    response = self.handle_exception(exc)
  File "/home/utkarshrasal/.local/lib/python3.8/site-packages/rest_framework/views.py", line 469, in handle_exception
    self.raise_uncaught_exception(exc)
  File "/home/utkarshrasal/.local/lib/python3.8/site-packages/rest_framework/views.py", line 480, in raise_uncaught_exception
    raise exc
  File "/home/utkarshrasal/.local/lib/python3.8/site-packages/rest_framework/views.py", line 506, in dispatch
    response = handler(request, *args, **kwargs)
  File "/media/utkarshrasal/4846FE1A46FE0908/WORK/PYTHON/Django/bloggingwebsite/blogs/viewsets.py", line 68, in create
    Activity.objects.create(user=request.user.pk, blogs=data['id'], logs = 'Blogs created Successfully')
  File "/home/utkarshrasal/.local/lib/python3.8/site-packages/django/db/models/manager.py", line 85, in manager_method
    return getattr(self.get_queryset(), name)(*args, **kwargs)
  File "/home/utkarshrasal/.local/lib/python3.8/site-packages/django/db/models/query.py", line 445, in create
    obj = self.model(**kwargs)
  File "/home/utkarshrasal/.local/lib/python3.8/site-packages/django/db/models/base.py", line 483, in __init__
    _setattr(self, field.name, rel_obj)
  File "/home/utkarshrasal/.local/lib/python3.8/site-packages/django/db/models/fields/related_descriptors.py", line 215, in __set__
    raise ValueError(
ValueError: Cannot assign "UUID('1f3a52f8-3966-497d-a948-47b6cc2e41c1')": "Activity.user" must be a "User" instance.
INFO:django.utils.autoreload:/media/utkarshrasal/4846FE1A46FE0908/WORK/PYTHON/Django/bloggingwebsite/blogs/viewsets.py changed, reloading.
INFO:root:created Blog with title 'NinthBlog'
ERROR:django.request:Internal Server Error: /blogs/
Traceback (most recent call last):
  File "/home/utkarshrasal/.local/lib/python3.8/site-packages/django/core/handlers/exception.py", line 47, in inner
    response = get_response(request)
  File "/home/utkarshrasal/.local/lib/python3.8/site-packages/django/core/handlers/base.py", line 181, in _get_response
    response = wrapped_callback(request, *callback_args, **callback_kwargs)
  File "/home/utkarshrasal/.local/lib/python3.8/site-packages/django/views/decorators/csrf.py", line 54, in wrapped_view
    return view_func(*args, **kwargs)
  File "/home/utkarshrasal/.local/lib/python3.8/site-packages/rest_framework/viewsets.py", line 125, in view
    return self.dispatch(request, *args, **kwargs)
  File "/home/utkarshrasal/.local/lib/python3.8/site-packages/rest_framework/views.py", line 509, in dispatch
    response = self.handle_exception(exc)
  File "/home/utkarshrasal/.local/lib/python3.8/site-packages/rest_framework/views.py", line 469, in handle_exception
    self.raise_uncaught_exception(exc)
  File "/home/utkarshrasal/.local/lib/python3.8/site-packages/rest_framework/views.py", line 480, in raise_uncaught_exception
    raise exc
  File "/home/utkarshrasal/.local/lib/python3.8/site-packages/rest_framework/views.py", line 506, in dispatch
    response = handler(request, *args, **kwargs)
  File "/media/utkarshrasal/4846FE1A46FE0908/WORK/PYTHON/Django/bloggingwebsite/blogs/viewsets.py", line 68, in create
    Activity.objects.create(user=data['user'], blogs=data['id'], logs = 'Blogs created Successfully')
  File "/home/utkarshrasal/.local/lib/python3.8/site-packages/django/db/models/manager.py", line 85, in manager_method
    return getattr(self.get_queryset(), name)(*args, **kwargs)
  File "/home/utkarshrasal/.local/lib/python3.8/site-packages/django/db/models/query.py", line 445, in create
    obj = self.model(**kwargs)
  File "/home/utkarshrasal/.local/lib/python3.8/site-packages/django/db/models/base.py", line 483, in __init__
    _setattr(self, field.name, rel_obj)
  File "/home/utkarshrasal/.local/lib/python3.8/site-packages/django/db/models/fields/related_descriptors.py", line 215, in __set__
    raise ValueError(
ValueError: Cannot assign "UUID('1f3a52f8-3966-497d-a948-47b6cc2e41c1')": "Activity.user" must be a "User" instance.
INFO:django.utils.autoreload:/media/utkarshrasal/4846FE1A46FE0908/WORK/PYTHON/Django/bloggingwebsite/blogs/viewsets.py changed, reloading.
INFO:root:created Blog with title 'NinthBlog'
ERROR:django.request:Internal Server Error: /blogs/
Traceback (most recent call last):
  File "/home/utkarshrasal/.local/lib/python3.8/site-packages/django/core/handlers/exception.py", line 47, in inner
    response = get_response(request)
  File "/home/utkarshrasal/.local/lib/python3.8/site-packages/django/core/handlers/base.py", line 181, in _get_response
    response = wrapped_callback(request, *callback_args, **callback_kwargs)
  File "/home/utkarshrasal/.local/lib/python3.8/site-packages/django/views/decorators/csrf.py", line 54, in wrapped_view
    return view_func(*args, **kwargs)
  File "/home/utkarshrasal/.local/lib/python3.8/site-packages/rest_framework/viewsets.py", line 125, in view
    return self.dispatch(request, *args, **kwargs)
  File "/home/utkarshrasal/.local/lib/python3.8/site-packages/rest_framework/views.py", line 509, in dispatch
    response = self.handle_exception(exc)
  File "/home/utkarshrasal/.local/lib/python3.8/site-packages/rest_framework/views.py", line 469, in handle_exception
    self.raise_uncaught_exception(exc)
  File "/home/utkarshrasal/.local/lib/python3.8/site-packages/rest_framework/views.py", line 480, in raise_uncaught_exception
    raise exc
  File "/home/utkarshrasal/.local/lib/python3.8/site-packages/rest_framework/views.py", line 506, in dispatch
    response = handler(request, *args, **kwargs)
  File "/media/utkarshrasal/4846FE1A46FE0908/WORK/PYTHON/Django/bloggingwebsite/blogs/viewsets.py", line 68, in create
    Activity.objects.create(user={**{'user':request.user.pk}}, blogs=data['id'], logs = 'Blogs created Successfully')
  File "/home/utkarshrasal/.local/lib/python3.8/site-packages/django/db/models/manager.py", line 85, in manager_method
    return getattr(self.get_queryset(), name)(*args, **kwargs)
  File "/home/utkarshrasal/.local/lib/python3.8/site-packages/django/db/models/query.py", line 445, in create
    obj = self.model(**kwargs)
  File "/home/utkarshrasal/.local/lib/python3.8/site-packages/django/db/models/base.py", line 483, in __init__
    _setattr(self, field.name, rel_obj)
  File "/home/utkarshrasal/.local/lib/python3.8/site-packages/django/db/models/fields/related_descriptors.py", line 215, in __set__
    raise ValueError(
ValueError: Cannot assign "{'user': UUID('1f3a52f8-3966-497d-a948-47b6cc2e41c1')}": "Activity.user" must be a "User" instance.
INFO:django.utils.autoreload:/media/utkarshrasal/4846FE1A46FE0908/WORK/PYTHON/Django/bloggingwebsite/blogs/viewsets.py changed, reloading.
INFO:root:created Blog with title 'NinthBlog'
ERROR:django.request:Internal Server Error: /blogs/
Traceback (most recent call last):
  File "/home/utkarshrasal/.local/lib/python3.8/site-packages/django/core/handlers/exception.py", line 47, in inner
    response = get_response(request)
  File "/home/utkarshrasal/.local/lib/python3.8/site-packages/django/core/handlers/base.py", line 181, in _get_response
    response = wrapped_callback(request, *callback_args, **callback_kwargs)
  File "/home/utkarshrasal/.local/lib/python3.8/site-packages/django/views/decorators/csrf.py", line 54, in wrapped_view
    return view_func(*args, **kwargs)
  File "/home/utkarshrasal/.local/lib/python3.8/site-packages/rest_framework/viewsets.py", line 125, in view
    return self.dispatch(request, *args, **kwargs)
  File "/home/utkarshrasal/.local/lib/python3.8/site-packages/rest_framework/views.py", line 509, in dispatch
    response = self.handle_exception(exc)
  File "/home/utkarshrasal/.local/lib/python3.8/site-packages/rest_framework/views.py", line 469, in handle_exception
    self.raise_uncaught_exception(exc)
  File "/home/utkarshrasal/.local/lib/python3.8/site-packages/rest_framework/views.py", line 480, in raise_uncaught_exception
    raise exc
  File "/home/utkarshrasal/.local/lib/python3.8/site-packages/rest_framework/views.py", line 506, in dispatch
    response = handler(request, *args, **kwargs)
  File "/media/utkarshrasal/4846FE1A46FE0908/WORK/PYTHON/Django/bloggingwebsite/blogs/viewsets.py", line 68, in create
    Activity.objects.create(user=request.user, blogs=data['id'], logs = 'Blogs created Successfully')
  File "/home/utkarshrasal/.local/lib/python3.8/site-packages/django/db/models/manager.py", line 85, in manager_method
    return getattr(self.get_queryset(), name)(*args, **kwargs)
  File "/home/utkarshrasal/.local/lib/python3.8/site-packages/django/db/models/query.py", line 445, in create
    obj = self.model(**kwargs)
  File "/home/utkarshrasal/.local/lib/python3.8/site-packages/django/db/models/base.py", line 483, in __init__
    _setattr(self, field.name, rel_obj)
  File "/home/utkarshrasal/.local/lib/python3.8/site-packages/django/db/models/fields/related_descriptors.py", line 215, in __set__
    raise ValueError(
ValueError: Cannot assign "'8160b6a5-0503-44aa-8570-8f81dc09c847'": "Activity.blogs" must be a "Blogs" instance.
INFO:django.utils.autoreload:/media/utkarshrasal/4846FE1A46FE0908/WORK/PYTHON/Django/bloggingwebsite/blogs/viewsets.py changed, reloading.
INFO:root:created Blog with title 'NinthBlog'
ERROR:django.request:Internal Server Error: /blogs/
Traceback (most recent call last):
  File "/home/utkarshrasal/.local/lib/python3.8/site-packages/django/core/handlers/exception.py", line 47, in inner
    response = get_response(request)
  File "/home/utkarshrasal/.local/lib/python3.8/site-packages/django/core/handlers/base.py", line 181, in _get_response
    response = wrapped_callback(request, *callback_args, **callback_kwargs)
  File "/home/utkarshrasal/.local/lib/python3.8/site-packages/django/views/decorators/csrf.py", line 54, in wrapped_view
    return view_func(*args, **kwargs)
  File "/home/utkarshrasal/.local/lib/python3.8/site-packages/rest_framework/viewsets.py", line 125, in view
    return self.dispatch(request, *args, **kwargs)
  File "/home/utkarshrasal/.local/lib/python3.8/site-packages/rest_framework/views.py", line 509, in dispatch
    response = self.handle_exception(exc)
  File "/home/utkarshrasal/.local/lib/python3.8/site-packages/rest_framework/views.py", line 469, in handle_exception
    self.raise_uncaught_exception(exc)
  File "/home/utkarshrasal/.local/lib/python3.8/site-packages/rest_framework/views.py", line 480, in raise_uncaught_exception
    raise exc
  File "/home/utkarshrasal/.local/lib/python3.8/site-packages/rest_framework/views.py", line 506, in dispatch
    response = handler(request, *args, **kwargs)
  File "/media/utkarshrasal/4846FE1A46FE0908/WORK/PYTHON/Django/bloggingwebsite/blogs/viewsets.py", line 69, in create
    Activity.objects.create(user=request.user, blogs=blog, logs = 'Blogs created Successfully')
  File "/home/utkarshrasal/.local/lib/python3.8/site-packages/django/db/models/manager.py", line 85, in manager_method
    return getattr(self.get_queryset(), name)(*args, **kwargs)
  File "/home/utkarshrasal/.local/lib/python3.8/site-packages/django/db/models/query.py", line 445, in create
    obj = self.model(**kwargs)
  File "/home/utkarshrasal/.local/lib/python3.8/site-packages/django/db/models/base.py", line 483, in __init__
    _setattr(self, field.name, rel_obj)
  File "/home/utkarshrasal/.local/lib/python3.8/site-packages/django/db/models/fields/related_descriptors.py", line 215, in __set__
    raise ValueError(
ValueError: Cannot assign "'c27b293f-fa44-42a0-b275-96c0cef0b48d'": "Activity.blogs" must be a "Blogs" instance.
INFO:root:created Blog with title 'NinthBlog'
ERROR:django.request:Internal Server Error: /blogs/
Traceback (most recent call last):
  File "/home/utkarshrasal/.local/lib/python3.8/site-packages/django/core/handlers/exception.py", line 47, in inner
    response = get_response(request)
  File "/home/utkarshrasal/.local/lib/python3.8/site-packages/django/core/handlers/base.py", line 181, in _get_response
    response = wrapped_callback(request, *callback_args, **callback_kwargs)
  File "/home/utkarshrasal/.local/lib/python3.8/site-packages/django/views/decorators/csrf.py", line 54, in wrapped_view
    return view_func(*args, **kwargs)
  File "/home/utkarshrasal/.local/lib/python3.8/site-packages/rest_framework/viewsets.py", line 125, in view
    return self.dispatch(request, *args, **kwargs)
  File "/home/utkarshrasal/.local/lib/python3.8/site-packages/rest_framework/views.py", line 509, in dispatch
    response = self.handle_exception(exc)
  File "/home/utkarshrasal/.local/lib/python3.8/site-packages/rest_framework/views.py", line 469, in handle_exception
    self.raise_uncaught_exception(exc)
  File "/home/utkarshrasal/.local/lib/python3.8/site-packages/rest_framework/views.py", line 480, in raise_uncaught_exception
    raise exc
  File "/home/utkarshrasal/.local/lib/python3.8/site-packages/rest_framework/views.py", line 506, in dispatch
    response = handler(request, *args, **kwargs)
  File "/media/utkarshrasal/4846FE1A46FE0908/WORK/PYTHON/Django/bloggingwebsite/blogs/viewsets.py", line 69, in create
    Activity.objects.create(user=request.user, blogs=blog, logs = 'Blogs created Successfully')
  File "/home/utkarshrasal/.local/lib/python3.8/site-packages/django/db/models/manager.py", line 85, in manager_method
    return getattr(self.get_queryset(), name)(*args, **kwargs)
  File "/home/utkarshrasal/.local/lib/python3.8/site-packages/django/db/models/query.py", line 445, in create
    obj = self.model(**kwargs)
  File "/home/utkarshrasal/.local/lib/python3.8/site-packages/django/db/models/base.py", line 483, in __init__
    _setattr(self, field.name, rel_obj)
  File "/home/utkarshrasal/.local/lib/python3.8/site-packages/django/db/models/fields/related_descriptors.py", line 215, in __set__
    raise ValueError(
ValueError: Cannot assign "'4ade0d31-c5c7-4aad-896c-ae5d59a17803'": "Activity.blogs" must be a "Blogs" instance.
INFO:django.utils.autoreload:/media/utkarshrasal/4846FE1A46FE0908/WORK/PYTHON/Django/bloggingwebsite/blogs/viewsets.py changed, reloading.
INFO:root:created Blog with title 'NinthBlog'
ERROR:django.request:Internal Server Error: /blogs/
Traceback (most recent call last):
  File "/home/utkarshrasal/.local/lib/python3.8/site-packages/django/core/handlers/exception.py", line 47, in inner
    response = get_response(request)
  File "/home/utkarshrasal/.local/lib/python3.8/site-packages/django/core/handlers/base.py", line 181, in _get_response
    response = wrapped_callback(request, *callback_args, **callback_kwargs)
  File "/home/utkarshrasal/.local/lib/python3.8/site-packages/django/views/decorators/csrf.py", line 54, in wrapped_view
    return view_func(*args, **kwargs)
  File "/home/utkarshrasal/.local/lib/python3.8/site-packages/rest_framework/viewsets.py", line 125, in view
    return self.dispatch(request, *args, **kwargs)
  File "/home/utkarshrasal/.local/lib/python3.8/site-packages/rest_framework/views.py", line 509, in dispatch
    response = self.handle_exception(exc)
  File "/home/utkarshrasal/.local/lib/python3.8/site-packages/rest_framework/views.py", line 469, in handle_exception
    self.raise_uncaught_exception(exc)
  File "/home/utkarshrasal/.local/lib/python3.8/site-packages/rest_framework/views.py", line 480, in raise_uncaught_exception
    raise exc
  File "/home/utkarshrasal/.local/lib/python3.8/site-packages/rest_framework/views.py", line 506, in dispatch
    response = handler(request, *args, **kwargs)
  File "/media/utkarshrasal/4846FE1A46FE0908/WORK/PYTHON/Django/bloggingwebsite/blogs/viewsets.py", line 69, in create
    Activity.objects.create(user=request.user, blogs=blog, logs = 'Blogs created Successfully')
  File "/home/utkarshrasal/.local/lib/python3.8/site-packages/django/db/models/manager.py", line 85, in manager_method
    return getattr(self.get_queryset(), name)(*args, **kwargs)
  File "/home/utkarshrasal/.local/lib/python3.8/site-packages/django/db/models/query.py", line 445, in create
    obj = self.model(**kwargs)
  File "/home/utkarshrasal/.local/lib/python3.8/site-packages/django/db/models/base.py", line 483, in __init__
    _setattr(self, field.name, rel_obj)
  File "/home/utkarshrasal/.local/lib/python3.8/site-packages/django/db/models/fields/related_descriptors.py", line 215, in __set__
    raise ValueError(
ValueError: Cannot assign "<QuerySet [<Blogs: NinthBlog>]>": "Activity.blogs" must be a "Blogs" instance.
INFO:django.utils.autoreload:/media/utkarshrasal/4846FE1A46FE0908/WORK/PYTHON/Django/bloggingwebsite/blogs/viewsets.py changed, reloading.
INFO:root:created Blog with title 'NinthBlog'
ERROR:django.request:Internal Server Error: /blogs/
Traceback (most recent call last):
  File "/home/utkarshrasal/.local/lib/python3.8/site-packages/django/db/backends/utils.py", line 84, in _execute
    return self.cursor.execute(sql, params)
  File "/home/utkarshrasal/.local/lib/python3.8/site-packages/django/db/backends/sqlite3/base.py", line 413, in execute
    return Database.Cursor.execute(self, query, params)
sqlite3.OperationalError: no such table: blogs_activity

The above exception was the direct cause of the following exception:

Traceback (most recent call last):
  File "/home/utkarshrasal/.local/lib/python3.8/site-packages/django/core/handlers/exception.py", line 47, in inner
    response = get_response(request)
  File "/home/utkarshrasal/.local/lib/python3.8/site-packages/django/core/handlers/base.py", line 181, in _get_response
    response = wrapped_callback(request, *callback_args, **callback_kwargs)
  File "/home/utkarshrasal/.local/lib/python3.8/site-packages/django/views/decorators/csrf.py", line 54, in wrapped_view
    return view_func(*args, **kwargs)
  File "/home/utkarshrasal/.local/lib/python3.8/site-packages/rest_framework/viewsets.py", line 125, in view
    return self.dispatch(request, *args, **kwargs)
  File "/home/utkarshrasal/.local/lib/python3.8/site-packages/rest_framework/views.py", line 509, in dispatch
    response = self.handle_exception(exc)
  File "/home/utkarshrasal/.local/lib/python3.8/site-packages/rest_framework/views.py", line 469, in handle_exception
    self.raise_uncaught_exception(exc)
  File "/home/utkarshrasal/.local/lib/python3.8/site-packages/rest_framework/views.py", line 480, in raise_uncaught_exception
    raise exc
  File "/home/utkarshrasal/.local/lib/python3.8/site-packages/rest_framework/views.py", line 506, in dispatch
    response = handler(request, *args, **kwargs)
  File "/media/utkarshrasal/4846FE1A46FE0908/WORK/PYTHON/Django/bloggingwebsite/blogs/viewsets.py", line 69, in create
    Activity.objects.create(user=request.user, blogs=blog, logs = 'Blogs created Successfully')
  File "/home/utkarshrasal/.local/lib/python3.8/site-packages/django/db/models/manager.py", line 85, in manager_method
    return getattr(self.get_queryset(), name)(*args, **kwargs)
  File "/home/utkarshrasal/.local/lib/python3.8/site-packages/django/db/models/query.py", line 447, in create
    obj.save(force_insert=True, using=self.db)
  File "/home/utkarshrasal/.local/lib/python3.8/site-packages/django/db/models/base.py", line 753, in save
    self.save_base(using=using, force_insert=force_insert,
  File "/home/utkarshrasal/.local/lib/python3.8/site-packages/django/db/models/base.py", line 790, in save_base
    updated = self._save_table(
  File "/home/utkarshrasal/.local/lib/python3.8/site-packages/django/db/models/base.py", line 895, in _save_table
    results = self._do_insert(cls._base_manager, using, fields, returning_fields, raw)
  File "/home/utkarshrasal/.local/lib/python3.8/site-packages/django/db/models/base.py", line 933, in _do_insert
    return manager._insert(
  File "/home/utkarshrasal/.local/lib/python3.8/site-packages/django/db/models/manager.py", line 85, in manager_method
    return getattr(self.get_queryset(), name)(*args, **kwargs)
  File "/home/utkarshrasal/.local/lib/python3.8/site-packages/django/db/models/query.py", line 1254, in _insert
    return query.get_compiler(using=using).execute_sql(returning_fields)
  File "/home/utkarshrasal/.local/lib/python3.8/site-packages/django/db/models/sql/compiler.py", line 1397, in execute_sql
    cursor.execute(sql, params)
  File "/home/utkarshrasal/.local/lib/python3.8/site-packages/django/db/backends/utils.py", line 98, in execute
    return super().execute(sql, params)
  File "/home/utkarshrasal/.local/lib/python3.8/site-packages/django/db/backends/utils.py", line 66, in execute
    return self._execute_with_wrappers(sql, params, many=False, executor=self._execute)
  File "/home/utkarshrasal/.local/lib/python3.8/site-packages/django/db/backends/utils.py", line 75, in _execute_with_wrappers
    return executor(sql, params, many, context)
  File "/home/utkarshrasal/.local/lib/python3.8/site-packages/django/db/backends/utils.py", line 84, in _execute
    return self.cursor.execute(sql, params)
  File "/home/utkarshrasal/.local/lib/python3.8/site-packages/django/db/utils.py", line 90, in __exit__
    raise dj_exc_value.with_traceback(traceback) from exc_value
  File "/home/utkarshrasal/.local/lib/python3.8/site-packages/django/db/backends/utils.py", line 84, in _execute
    return self.cursor.execute(sql, params)
  File "/home/utkarshrasal/.local/lib/python3.8/site-packages/django/db/backends/sqlite3/base.py", line 413, in execute
    return Database.Cursor.execute(self, query, params)
django.db.utils.OperationalError: no such table: blogs_activity
INFO:root:created Blog with title 'NinthBlog'
INFO:django.utils.autoreload:/media/utkarshrasal/4846FE1A46FE0908/WORK/PYTHON/Django/bloggingwebsite/blogs/mixins.py changed, reloading.
INFO:django.utils.autoreload:/media/utkarshrasal/4846FE1A46FE0908/WORK/PYTHON/Django/bloggingwebsite/blogs/views.py changed, reloading.
ERROR:django.request:Internal Server Error: /blogs/575aefcf-26ac-4b06-b2c2-9cd2a810808c/activity/
Traceback (most recent call last):
  File "/home/utkarshrasal/.local/lib/python3.8/site-packages/django/core/handlers/exception.py", line 47, in inner
    response = get_response(request)
  File "/home/utkarshrasal/.local/lib/python3.8/site-packages/django/core/handlers/base.py", line 181, in _get_response
    response = wrapped_callback(request, *callback_args, **callback_kwargs)
  File "/home/utkarshrasal/.local/lib/python3.8/site-packages/django/views/decorators/csrf.py", line 54, in wrapped_view
    return view_func(*args, **kwargs)
  File "/home/utkarshrasal/.local/lib/python3.8/site-packages/rest_framework/viewsets.py", line 125, in view
    return self.dispatch(request, *args, **kwargs)
  File "/home/utkarshrasal/.local/lib/python3.8/site-packages/rest_framework/views.py", line 509, in dispatch
    response = self.handle_exception(exc)
  File "/home/utkarshrasal/.local/lib/python3.8/site-packages/rest_framework/views.py", line 469, in handle_exception
    self.raise_uncaught_exception(exc)
  File "/home/utkarshrasal/.local/lib/python3.8/site-packages/rest_framework/views.py", line 480, in raise_uncaught_exception
    raise exc
  File "/home/utkarshrasal/.local/lib/python3.8/site-packages/rest_framework/views.py", line 506, in dispatch
    response = handler(request, *args, **kwargs)
  File "/media/utkarshrasal/4846FE1A46FE0908/WORK/PYTHON/Django/bloggingwebsite/blogs/mixins.py", line 174, in activity
    serializers = self.get_serializer(intance= activity, many=True)
  File "/home/utkarshrasal/.local/lib/python3.8/site-packages/rest_framework/generics.py", line 110, in get_serializer
    return serializer_class(*args, **kwargs)
  File "/home/utkarshrasal/.local/lib/python3.8/site-packages/rest_framework/serializers.py", line 121, in __new__
    return cls.many_init(*args, **kwargs)
  File "/home/utkarshrasal/.local/lib/python3.8/site-packages/rest_framework/serializers.py", line 146, in many_init
    child_serializer = cls(*args, **kwargs)
  File "/home/utkarshrasal/.local/lib/python3.8/site-packages/rest_framework/serializers.py", line 115, in __init__
    super().__init__(**kwargs)
TypeError: __init__() got an unexpected keyword argument 'intance'
INFO:django.utils.autoreload:/media/utkarshrasal/4846FE1A46FE0908/WORK/PYTHON/Django/bloggingwebsite/blogs/mixins.py changed, reloading.
ERROR:django.request:Internal Server Error: /blogs/575aefcf-26ac-4b06-b2c2-9cd2a810808c/activity/
Traceback (most recent call last):
  File "/home/utkarshrasal/.local/lib/python3.8/site-packages/django/core/handlers/exception.py", line 47, in inner
    response = get_response(request)
  File "/home/utkarshrasal/.local/lib/python3.8/site-packages/django/core/handlers/base.py", line 181, in _get_response
    response = wrapped_callback(request, *callback_args, **callback_kwargs)
  File "/home/utkarshrasal/.local/lib/python3.8/site-packages/django/views/decorators/csrf.py", line 54, in wrapped_view
    return view_func(*args, **kwargs)
  File "/home/utkarshrasal/.local/lib/python3.8/site-packages/rest_framework/viewsets.py", line 125, in view
    return self.dispatch(request, *args, **kwargs)
  File "/home/utkarshrasal/.local/lib/python3.8/site-packages/rest_framework/views.py", line 509, in dispatch
    response = self.handle_exception(exc)
  File "/home/utkarshrasal/.local/lib/python3.8/site-packages/rest_framework/views.py", line 469, in handle_exception
    self.raise_uncaught_exception(exc)
  File "/home/utkarshrasal/.local/lib/python3.8/site-packages/rest_framework/views.py", line 480, in raise_uncaught_exception
    raise exc
  File "/home/utkarshrasal/.local/lib/python3.8/site-packages/rest_framework/views.py", line 506, in dispatch
    response = handler(request, *args, **kwargs)
  File "/media/utkarshrasal/4846FE1A46FE0908/WORK/PYTHON/Django/bloggingwebsite/blogs/mixins.py", line 178, in activity
    'message':f'this is the {tagname} of the tag',
NameError: name 'tagname' is not defined
INFO:django.utils.autoreload:/media/utkarshrasal/4846FE1A46FE0908/WORK/PYTHON/Django/bloggingwebsite/blogs/mixins.py changed, reloading.
ERROR:django.request:Internal Server Error: /blogs/575aefcf-26ac-4b06-b2c2-9cd2a810808c/activity/
Traceback (most recent call last):
  File "/home/utkarshrasal/.local/lib/python3.8/site-packages/rest_framework/fields.py", line 457, in get_attribute
    return get_attribute(instance, self.source_attrs)
  File "/home/utkarshrasal/.local/lib/python3.8/site-packages/rest_framework/fields.py", line 97, in get_attribute
    instance = getattr(instance, attr)
AttributeError: 'Blogs' object has no attribute 'logs'

During handling of the above exception, another exception occurred:

Traceback (most recent call last):
  File "/home/utkarshrasal/.local/lib/python3.8/site-packages/django/core/handlers/exception.py", line 47, in inner
    response = get_response(request)
  File "/home/utkarshrasal/.local/lib/python3.8/site-packages/django/core/handlers/base.py", line 181, in _get_response
    response = wrapped_callback(request, *callback_args, **callback_kwargs)
  File "/home/utkarshrasal/.local/lib/python3.8/site-packages/django/views/decorators/csrf.py", line 54, in wrapped_view
    return view_func(*args, **kwargs)
  File "/home/utkarshrasal/.local/lib/python3.8/site-packages/rest_framework/viewsets.py", line 125, in view
    return self.dispatch(request, *args, **kwargs)
  File "/home/utkarshrasal/.local/lib/python3.8/site-packages/rest_framework/views.py", line 509, in dispatch
    response = self.handle_exception(exc)
  File "/home/utkarshrasal/.local/lib/python3.8/site-packages/rest_framework/views.py", line 469, in handle_exception
    self.raise_uncaught_exception(exc)
  File "/home/utkarshrasal/.local/lib/python3.8/site-packages/rest_framework/views.py", line 480, in raise_uncaught_exception
    raise exc
  File "/home/utkarshrasal/.local/lib/python3.8/site-packages/rest_framework/views.py", line 506, in dispatch
    response = handler(request, *args, **kwargs)
  File "/media/utkarshrasal/4846FE1A46FE0908/WORK/PYTHON/Django/bloggingwebsite/blogs/mixins.py", line 179, in activity
    'data':serializers.data
  File "/home/utkarshrasal/.local/lib/python3.8/site-packages/rest_framework/serializers.py", line 745, in data
    ret = super().data
  File "/home/utkarshrasal/.local/lib/python3.8/site-packages/rest_framework/serializers.py", line 246, in data
    self._data = self.to_representation(self.instance)
  File "/home/utkarshrasal/.local/lib/python3.8/site-packages/rest_framework/serializers.py", line 663, in to_representation
    return [
  File "/home/utkarshrasal/.local/lib/python3.8/site-packages/rest_framework/serializers.py", line 664, in <listcomp>
    self.child.to_representation(item) for item in iterable
  File "/home/utkarshrasal/.local/lib/python3.8/site-packages/rest_framework/serializers.py", line 502, in to_representation
    attribute = field.get_attribute(instance)
  File "/home/utkarshrasal/.local/lib/python3.8/site-packages/rest_framework/fields.py", line 490, in get_attribute
    raise type(exc)(msg)
AttributeError: Got AttributeError when attempting to get a value for field `logs` on serializer `ActivitySerializer`.
The serializer field might be named incorrectly and not match any attribute or key on the `Blogs` instance.
Original exception text was: 'Blogs' object has no attribute 'logs'.
INFO:django.utils.autoreload:/media/utkarshrasal/4846FE1A46FE0908/WORK/PYTHON/Django/bloggingwebsite/blogs/mixins.py changed, reloading.
ERROR:django.request:Internal Server Error: /blogs/575aefcf-26ac-4b06-b2c2-9cd2a810808c/activity/
Traceback (most recent call last):
  File "/home/utkarshrasal/.local/lib/python3.8/site-packages/django/core/handlers/exception.py", line 47, in inner
    response = get_response(request)
  File "/home/utkarshrasal/.local/lib/python3.8/site-packages/django/core/handlers/base.py", line 181, in _get_response
    response = wrapped_callback(request, *callback_args, **callback_kwargs)
  File "/home/utkarshrasal/.local/lib/python3.8/site-packages/django/views/decorators/csrf.py", line 54, in wrapped_view
    return view_func(*args, **kwargs)
  File "/home/utkarshrasal/.local/lib/python3.8/site-packages/rest_framework/viewsets.py", line 125, in view
    return self.dispatch(request, *args, **kwargs)
  File "/home/utkarshrasal/.local/lib/python3.8/site-packages/rest_framework/views.py", line 509, in dispatch
    response = self.handle_exception(exc)
  File "/home/utkarshrasal/.local/lib/python3.8/site-packages/rest_framework/views.py", line 469, in handle_exception
    self.raise_uncaught_exception(exc)
  File "/home/utkarshrasal/.local/lib/python3.8/site-packages/rest_framework/views.py", line 480, in raise_uncaught_exception
    raise exc
  File "/home/utkarshrasal/.local/lib/python3.8/site-packages/rest_framework/views.py", line 506, in dispatch
    response = handler(request, *args, **kwargs)
  File "/media/utkarshrasal/4846FE1A46FE0908/WORK/PYTHON/Django/bloggingwebsite/blogs/mixins.py", line 179, in activity
    'data':serializers.data
  File "/home/utkarshrasal/.local/lib/python3.8/site-packages/rest_framework/serializers.py", line 745, in data
    ret = super().data
  File "/home/utkarshrasal/.local/lib/python3.8/site-packages/rest_framework/serializers.py", line 246, in data
    self._data = self.to_representation(self.instance)
  File "/home/utkarshrasal/.local/lib/python3.8/site-packages/rest_framework/serializers.py", line 663, in to_representation
    return [
TypeError: 'Blogs' object is not iterable
INFO:django.utils.autoreload:/media/utkarshrasal/4846FE1A46FE0908/WORK/PYTHON/Django/bloggingwebsite/blogs/mixins.py changed, reloading.
ERROR:django.request:Internal Server Error: /blogs/575aefcf-26ac-4b06-b2c2-9cd2a810808c/activity/
Traceback (most recent call last):
  File "/home/utkarshrasal/.local/lib/python3.8/site-packages/rest_framework/fields.py", line 457, in get_attribute
    return get_attribute(instance, self.source_attrs)
  File "/home/utkarshrasal/.local/lib/python3.8/site-packages/rest_framework/fields.py", line 97, in get_attribute
    instance = getattr(instance, attr)
AttributeError: 'Blogs' object has no attribute 'logs'

During handling of the above exception, another exception occurred:

Traceback (most recent call last):
  File "/home/utkarshrasal/.local/lib/python3.8/site-packages/django/core/handlers/exception.py", line 47, in inner
    response = get_response(request)
  File "/home/utkarshrasal/.local/lib/python3.8/site-packages/django/core/handlers/base.py", line 181, in _get_response
    response = wrapped_callback(request, *callback_args, **callback_kwargs)
  File "/home/utkarshrasal/.local/lib/python3.8/site-packages/django/views/decorators/csrf.py", line 54, in wrapped_view
    return view_func(*args, **kwargs)
  File "/home/utkarshrasal/.local/lib/python3.8/site-packages/rest_framework/viewsets.py", line 125, in view
    return self.dispatch(request, *args, **kwargs)
  File "/home/utkarshrasal/.local/lib/python3.8/site-packages/rest_framework/views.py", line 509, in dispatch
    response = self.handle_exception(exc)
  File "/home/utkarshrasal/.local/lib/python3.8/site-packages/rest_framework/views.py", line 469, in handle_exception
    self.raise_uncaught_exception(exc)
  File "/home/utkarshrasal/.local/lib/python3.8/site-packages/rest_framework/views.py", line 480, in raise_uncaught_exception
    raise exc
  File "/home/utkarshrasal/.local/lib/python3.8/site-packages/rest_framework/views.py", line 506, in dispatch
    response = handler(request, *args, **kwargs)
  File "/media/utkarshrasal/4846FE1A46FE0908/WORK/PYTHON/Django/bloggingwebsite/blogs/mixins.py", line 179, in activity
    'data':serializers.data
  File "/home/utkarshrasal/.local/lib/python3.8/site-packages/rest_framework/serializers.py", line 548, in data
    ret = super().data
  File "/home/utkarshrasal/.local/lib/python3.8/site-packages/rest_framework/serializers.py", line 246, in data
    self._data = self.to_representation(self.instance)
  File "/home/utkarshrasal/.local/lib/python3.8/site-packages/rest_framework/serializers.py", line 502, in to_representation
    attribute = field.get_attribute(instance)
  File "/home/utkarshrasal/.local/lib/python3.8/site-packages/rest_framework/fields.py", line 490, in get_attribute
    raise type(exc)(msg)
AttributeError: Got AttributeError when attempting to get a value for field `logs` on serializer `ActivitySerializer`.
The serializer field might be named incorrectly and not match any attribute or key on the `Blogs` instance.
Original exception text was: 'Blogs' object has no attribute 'logs'.
INFO:django.utils.autoreload:/media/utkarshrasal/4846FE1A46FE0908/WORK/PYTHON/Django/bloggingwebsite/blogs/mixins.py changed, reloading.
ERROR:django.request:Internal Server Error: /blogs/575aefcf-26ac-4b06-b2c2-9cd2a810808c/activity/
Traceback (most recent call last):
  File "/home/utkarshrasal/.local/lib/python3.8/site-packages/django/core/handlers/exception.py", line 47, in inner
    response = get_response(request)
  File "/home/utkarshrasal/.local/lib/python3.8/site-packages/django/core/handlers/base.py", line 181, in _get_response
    response = wrapped_callback(request, *callback_args, **callback_kwargs)
  File "/home/utkarshrasal/.local/lib/python3.8/site-packages/django/views/decorators/csrf.py", line 54, in wrapped_view
    return view_func(*args, **kwargs)
  File "/home/utkarshrasal/.local/lib/python3.8/site-packages/rest_framework/viewsets.py", line 125, in view
    return self.dispatch(request, *args, **kwargs)
  File "/home/utkarshrasal/.local/lib/python3.8/site-packages/rest_framework/views.py", line 509, in dispatch
    response = self.handle_exception(exc)
  File "/home/utkarshrasal/.local/lib/python3.8/site-packages/rest_framework/views.py", line 469, in handle_exception
    self.raise_uncaught_exception(exc)
  File "/home/utkarshrasal/.local/lib/python3.8/site-packages/rest_framework/views.py", line 480, in raise_uncaught_exception
    raise exc
  File "/home/utkarshrasal/.local/lib/python3.8/site-packages/rest_framework/views.py", line 506, in dispatch
    response = handler(request, *args, **kwargs)
  File "/media/utkarshrasal/4846FE1A46FE0908/WORK/PYTHON/Django/bloggingwebsite/blogs/mixins.py", line 179, in activity
    'data':serializers.data
  File "/home/utkarshrasal/.local/lib/python3.8/site-packages/rest_framework/serializers.py", line 745, in data
    ret = super().data
  File "/home/utkarshrasal/.local/lib/python3.8/site-packages/rest_framework/serializers.py", line 246, in data
    self._data = self.to_representation(self.instance)
  File "/home/utkarshrasal/.local/lib/python3.8/site-packages/rest_framework/serializers.py", line 663, in to_representation
    return [
TypeError: 'Blogs' object is not iterable
INFO:django.utils.autoreload:/media/utkarshrasal/4846FE1A46FE0908/WORK/PYTHON/Django/bloggingwebsite/blogs/serializers.py changed, reloading.
INFO:django.utils.autoreload:/media/utkarshrasal/4846FE1A46FE0908/WORK/PYTHON/Django/bloggingwebsite/blogs/serializers.py changed, reloading.
ERROR:django.request:Internal Server Error: /blogs/575aefcf-26ac-4b06-b2c2-9cd2a810808c/activity/
Traceback (most recent call last):
  File "/home/utkarshrasal/.local/lib/python3.8/site-packages/django/core/handlers/exception.py", line 47, in inner
    response = get_response(request)
  File "/home/utkarshrasal/.local/lib/python3.8/site-packages/django/core/handlers/base.py", line 181, in _get_response
    response = wrapped_callback(request, *callback_args, **callback_kwargs)
  File "/home/utkarshrasal/.local/lib/python3.8/site-packages/django/views/decorators/csrf.py", line 54, in wrapped_view
    return view_func(*args, **kwargs)
  File "/home/utkarshrasal/.local/lib/python3.8/site-packages/rest_framework/viewsets.py", line 125, in view
    return self.dispatch(request, *args, **kwargs)
  File "/home/utkarshrasal/.local/lib/python3.8/site-packages/rest_framework/views.py", line 509, in dispatch
    response = self.handle_exception(exc)
  File "/home/utkarshrasal/.local/lib/python3.8/site-packages/rest_framework/views.py", line 469, in handle_exception
    self.raise_uncaught_exception(exc)
  File "/home/utkarshrasal/.local/lib/python3.8/site-packages/rest_framework/views.py", line 480, in raise_uncaught_exception
    raise exc
  File "/home/utkarshrasal/.local/lib/python3.8/site-packages/rest_framework/views.py", line 506, in dispatch
    response = handler(request, *args, **kwargs)
  File "/media/utkarshrasal/4846FE1A46FE0908/WORK/PYTHON/Django/bloggingwebsite/blogs/mixins.py", line 179, in activity
    'data':serializers.data
  File "/home/utkarshrasal/.local/lib/python3.8/site-packages/rest_framework/serializers.py", line 745, in data
    ret = super().data
  File "/home/utkarshrasal/.local/lib/python3.8/site-packages/rest_framework/serializers.py", line 246, in data
    self._data = self.to_representation(self.instance)
  File "/home/utkarshrasal/.local/lib/python3.8/site-packages/rest_framework/serializers.py", line 663, in to_representation
    return [
TypeError: 'Blogs' object is not iterable
INFO:django.utils.autoreload:/media/utkarshrasal/4846FE1A46FE0908/WORK/PYTHON/Django/bloggingwebsite/blogs/viewsets.py changed, reloading.
INFO:django.utils.autoreload:/media/utkarshrasal/4846FE1A46FE0908/WORK/PYTHON/Django/bloggingwebsite/blogs/mixins.py changed, reloading.
ERROR:django.request:Internal Server Error: /blogs/575aefcf-26ac-4b06-b2c2-9cd2a810808c/activity/
Traceback (most recent call last):
  File "/home/utkarshrasal/.local/lib/python3.8/site-packages/rest_framework/fields.py", line 457, in get_attribute
    return get_attribute(instance, self.source_attrs)
  File "/home/utkarshrasal/.local/lib/python3.8/site-packages/rest_framework/fields.py", line 97, in get_attribute
    instance = getattr(instance, attr)
AttributeError: 'Blogs' object has no attribute 'logs'

During handling of the above exception, another exception occurred:

Traceback (most recent call last):
  File "/home/utkarshrasal/.local/lib/python3.8/site-packages/django/core/handlers/exception.py", line 47, in inner
    response = get_response(request)
  File "/home/utkarshrasal/.local/lib/python3.8/site-packages/django/core/handlers/base.py", line 181, in _get_response
    response = wrapped_callback(request, *callback_args, **callback_kwargs)
  File "/home/utkarshrasal/.local/lib/python3.8/site-packages/django/views/decorators/csrf.py", line 54, in wrapped_view
    return view_func(*args, **kwargs)
  File "/home/utkarshrasal/.local/lib/python3.8/site-packages/rest_framework/viewsets.py", line 125, in view
    return self.dispatch(request, *args, **kwargs)
  File "/home/utkarshrasal/.local/lib/python3.8/site-packages/rest_framework/views.py", line 509, in dispatch
    response = self.handle_exception(exc)
  File "/home/utkarshrasal/.local/lib/python3.8/site-packages/rest_framework/views.py", line 469, in handle_exception
    self.raise_uncaught_exception(exc)
  File "/home/utkarshrasal/.local/lib/python3.8/site-packages/rest_framework/views.py", line 480, in raise_uncaught_exception
    raise exc
  File "/home/utkarshrasal/.local/lib/python3.8/site-packages/rest_framework/views.py", line 506, in dispatch
    response = handler(request, *args, **kwargs)
  File "/media/utkarshrasal/4846FE1A46FE0908/WORK/PYTHON/Django/bloggingwebsite/blogs/mixins.py", line 179, in activity
    'data':serializers.data
  File "/home/utkarshrasal/.local/lib/python3.8/site-packages/rest_framework/serializers.py", line 745, in data
    ret = super().data
  File "/home/utkarshrasal/.local/lib/python3.8/site-packages/rest_framework/serializers.py", line 246, in data
    self._data = self.to_representation(self.instance)
  File "/home/utkarshrasal/.local/lib/python3.8/site-packages/rest_framework/serializers.py", line 663, in to_representation
    return [
  File "/home/utkarshrasal/.local/lib/python3.8/site-packages/rest_framework/serializers.py", line 664, in <listcomp>
    self.child.to_representation(item) for item in iterable
  File "/home/utkarshrasal/.local/lib/python3.8/site-packages/rest_framework/serializers.py", line 502, in to_representation
    attribute = field.get_attribute(instance)
  File "/home/utkarshrasal/.local/lib/python3.8/site-packages/rest_framework/fields.py", line 490, in get_attribute
    raise type(exc)(msg)
AttributeError: Got AttributeError when attempting to get a value for field `logs` on serializer `ActivitySerializer`.
The serializer field might be named incorrectly and not match any attribute or key on the `Blogs` instance.
Original exception text was: 'Blogs' object has no attribute 'logs'.
INFO:django.utils.autoreload:/media/utkarshrasal/4846FE1A46FE0908/WORK/PYTHON/Django/bloggingwebsite/blogs/mixins.py changed, reloading.
ERROR:django.request:Internal Server Error: /blogs/575aefcf-26ac-4b06-b2c2-9cd2a810808c/activity/
Traceback (most recent call last):
  File "/home/utkarshrasal/.local/lib/python3.8/site-packages/django/core/handlers/exception.py", line 47, in inner
    response = get_response(request)
  File "/home/utkarshrasal/.local/lib/python3.8/site-packages/django/core/handlers/base.py", line 181, in _get_response
    response = wrapped_callback(request, *callback_args, **callback_kwargs)
  File "/home/utkarshrasal/.local/lib/python3.8/site-packages/django/views/decorators/csrf.py", line 54, in wrapped_view
    return view_func(*args, **kwargs)
  File "/home/utkarshrasal/.local/lib/python3.8/site-packages/rest_framework/viewsets.py", line 125, in view
    return self.dispatch(request, *args, **kwargs)
  File "/home/utkarshrasal/.local/lib/python3.8/site-packages/rest_framework/views.py", line 509, in dispatch
    response = self.handle_exception(exc)
  File "/home/utkarshrasal/.local/lib/python3.8/site-packages/rest_framework/views.py", line 469, in handle_exception
    self.raise_uncaught_exception(exc)
  File "/home/utkarshrasal/.local/lib/python3.8/site-packages/rest_framework/views.py", line 480, in raise_uncaught_exception
    raise exc
  File "/home/utkarshrasal/.local/lib/python3.8/site-packages/rest_framework/views.py", line 506, in dispatch
    response = handler(request, *args, **kwargs)
  File "/media/utkarshrasal/4846FE1A46FE0908/WORK/PYTHON/Django/bloggingwebsite/blogs/mixins.py", line 176, in activity
    return Response(data={
  File "/home/utkarshrasal/.local/lib/python3.8/site-packages/rest_framework/serializers.py", line 745, in data
    ret = super().data
  File "/home/utkarshrasal/.local/lib/python3.8/site-packages/rest_framework/serializers.py", line 246, in data
    self._data = self.to_representation(self.instance)
  File "/home/utkarshrasal/.local/lib/python3.8/site-packages/rest_framework/serializers.py", line 663, in to_representation
    return [
TypeError: 'Blogs' object is not iterable
ERROR:django.request:Internal Server Error: /blogs/575aefcf-26ac-4b06-b2c2-9cd2a810808c/activity/
Traceback (most recent call last):
  File "/home/utkarshrasal/.local/lib/python3.8/site-packages/rest_framework/fields.py", line 457, in get_attribute
    return get_attribute(instance, self.source_attrs)
  File "/home/utkarshrasal/.local/lib/python3.8/site-packages/rest_framework/fields.py", line 97, in get_attribute
    instance = getattr(instance, attr)
AttributeError: 'Blogs' object has no attribute 'logs'

During handling of the above exception, another exception occurred:

Traceback (most recent call last):
  File "/home/utkarshrasal/.local/lib/python3.8/site-packages/django/core/handlers/exception.py", line 47, in inner
    response = get_response(request)
  File "/home/utkarshrasal/.local/lib/python3.8/site-packages/django/core/handlers/base.py", line 181, in _get_response
    response = wrapped_callback(request, *callback_args, **callback_kwargs)
  File "/home/utkarshrasal/.local/lib/python3.8/site-packages/django/views/decorators/csrf.py", line 54, in wrapped_view
    return view_func(*args, **kwargs)
  File "/home/utkarshrasal/.local/lib/python3.8/site-packages/rest_framework/viewsets.py", line 125, in view
    return self.dispatch(request, *args, **kwargs)
  File "/home/utkarshrasal/.local/lib/python3.8/site-packages/rest_framework/views.py", line 509, in dispatch
    response = self.handle_exception(exc)
  File "/home/utkarshrasal/.local/lib/python3.8/site-packages/rest_framework/views.py", line 469, in handle_exception
    self.raise_uncaught_exception(exc)
  File "/home/utkarshrasal/.local/lib/python3.8/site-packages/rest_framework/views.py", line 480, in raise_uncaught_exception
    raise exc
  File "/home/utkarshrasal/.local/lib/python3.8/site-packages/rest_framework/views.py", line 506, in dispatch
    response = handler(request, *args, **kwargs)
  File "/media/utkarshrasal/4846FE1A46FE0908/WORK/PYTHON/Django/bloggingwebsite/blogs/mixins.py", line 173, in activity
    activity = self.model_class.objects.filter(id=kwargs.get('pk'))
  File "/home/utkarshrasal/.local/lib/python3.8/site-packages/rest_framework/serializers.py", line 745, in data
    ret = super().data
  File "/home/utkarshrasal/.local/lib/python3.8/site-packages/rest_framework/serializers.py", line 246, in data
    self._data = self.to_representation(self.instance)
  File "/home/utkarshrasal/.local/lib/python3.8/site-packages/rest_framework/serializers.py", line 663, in to_representation
    return [
  File "/home/utkarshrasal/.local/lib/python3.8/site-packages/rest_framework/serializers.py", line 664, in <listcomp>
    self.child.to_representation(item) for item in iterable
  File "/home/utkarshrasal/.local/lib/python3.8/site-packages/rest_framework/serializers.py", line 502, in to_representation
    attribute = field.get_attribute(instance)
  File "/home/utkarshrasal/.local/lib/python3.8/site-packages/rest_framework/fields.py", line 490, in get_attribute
    raise type(exc)(msg)
AttributeError: Got AttributeError when attempting to get a value for field `logs` on serializer `ActivitySerializer`.
The serializer field might be named incorrectly and not match any attribute or key on the `Blogs` instance.
Original exception text was: 'Blogs' object has no attribute 'logs'.
INFO:django.utils.autoreload:/media/utkarshrasal/4846FE1A46FE0908/WORK/PYTHON/Django/bloggingwebsite/blogs/mixins.py changed, reloading.
INFO:django.utils.autoreload:/media/utkarshrasal/4846FE1A46FE0908/WORK/PYTHON/Django/bloggingwebsite/blogs/mixins.py changed, reloading.
ERROR:django.request:Internal Server Error: /blogs/575aefcf-26ac-4b06-b2c2-9cd2a810808c/activity/
Traceback (most recent call last):
  File "/home/utkarshrasal/.local/lib/python3.8/site-packages/django/core/handlers/exception.py", line 47, in inner
    response = get_response(request)
  File "/home/utkarshrasal/.local/lib/python3.8/site-packages/django/core/handlers/base.py", line 181, in _get_response
    response = wrapped_callback(request, *callback_args, **callback_kwargs)
  File "/home/utkarshrasal/.local/lib/python3.8/site-packages/django/views/decorators/csrf.py", line 54, in wrapped_view
    return view_func(*args, **kwargs)
  File "/home/utkarshrasal/.local/lib/python3.8/site-packages/rest_framework/viewsets.py", line 125, in view
    return self.dispatch(request, *args, **kwargs)
  File "/home/utkarshrasal/.local/lib/python3.8/site-packages/rest_framework/views.py", line 509, in dispatch
    response = self.handle_exception(exc)
  File "/home/utkarshrasal/.local/lib/python3.8/site-packages/rest_framework/views.py", line 469, in handle_exception
    self.raise_uncaught_exception(exc)
  File "/home/utkarshrasal/.local/lib/python3.8/site-packages/rest_framework/views.py", line 480, in raise_uncaught_exception
    raise exc
  File "/home/utkarshrasal/.local/lib/python3.8/site-packages/rest_framework/views.py", line 506, in dispatch
    response = handler(request, *args, **kwargs)
  File "/media/utkarshrasal/4846FE1A46FE0908/WORK/PYTHON/Django/bloggingwebsite/blogs/mixins.py", line 179, in activity
    'data':serializers.data
  File "/home/utkarshrasal/.local/lib/python3.8/site-packages/rest_framework/serializers.py", line 745, in data
    ret = super().data
  File "/home/utkarshrasal/.local/lib/python3.8/site-packages/rest_framework/serializers.py", line 246, in data
    self._data = self.to_representation(self.instance)
  File "/home/utkarshrasal/.local/lib/python3.8/site-packages/rest_framework/serializers.py", line 663, in to_representation
    return [
TypeError: 'Blogs' object is not iterable
INFO:django.utils.autoreload:/media/utkarshrasal/4846FE1A46FE0908/WORK/PYTHON/Django/bloggingwebsite/blogs/mixins.py changed, reloading.
ERROR:django.request:Internal Server Error: /blogs/575aefcf-26ac-4b06-b2c2-9cd2a810808c/activity/
Traceback (most recent call last):
  File "/home/utkarshrasal/.local/lib/python3.8/site-packages/django/core/handlers/exception.py", line 47, in inner
    response = get_response(request)
  File "/home/utkarshrasal/.local/lib/python3.8/site-packages/django/core/handlers/base.py", line 181, in _get_response
    response = wrapped_callback(request, *callback_args, **callback_kwargs)
  File "/home/utkarshrasal/.local/lib/python3.8/site-packages/django/views/decorators/csrf.py", line 54, in wrapped_view
    return view_func(*args, **kwargs)
  File "/home/utkarshrasal/.local/lib/python3.8/site-packages/rest_framework/viewsets.py", line 125, in view
    return self.dispatch(request, *args, **kwargs)
  File "/home/utkarshrasal/.local/lib/python3.8/site-packages/rest_framework/views.py", line 509, in dispatch
    response = self.handle_exception(exc)
  File "/home/utkarshrasal/.local/lib/python3.8/site-packages/rest_framework/views.py", line 469, in handle_exception
    self.raise_uncaught_exception(exc)
  File "/home/utkarshrasal/.local/lib/python3.8/site-packages/rest_framework/views.py", line 480, in raise_uncaught_exception
    raise exc
  File "/home/utkarshrasal/.local/lib/python3.8/site-packages/rest_framework/views.py", line 506, in dispatch
    response = handler(request, *args, **kwargs)
  File "/media/utkarshrasal/4846FE1A46FE0908/WORK/PYTHON/Django/bloggingwebsite/blogs/mixins.py", line 180, in activity
    'data':serializers.data
  File "/home/utkarshrasal/.local/lib/python3.8/site-packages/rest_framework/serializers.py", line 745, in data
    ret = super().data
  File "/home/utkarshrasal/.local/lib/python3.8/site-packages/rest_framework/serializers.py", line 246, in data
    self._data = self.to_representation(self.instance)
  File "/home/utkarshrasal/.local/lib/python3.8/site-packages/rest_framework/serializers.py", line 663, in to_representation
    return [
TypeError: 'Blogs' object is not iterable
INFO:django.utils.autoreload:/media/utkarshrasal/4846FE1A46FE0908/WORK/PYTHON/Django/bloggingwebsite/blogs/mixins.py changed, reloading.
ERROR:django.request:Internal Server Error: /blogs/575aefcf-26ac-4b06-b2c2-9cd2a810808c/activity/
Traceback (most recent call last):
  File "/home/utkarshrasal/.local/lib/python3.8/site-packages/rest_framework/fields.py", line 457, in get_attribute
    return get_attribute(instance, self.source_attrs)
  File "/home/utkarshrasal/.local/lib/python3.8/site-packages/rest_framework/fields.py", line 97, in get_attribute
    instance = getattr(instance, attr)
AttributeError: 'Blogs' object has no attribute 'logs'

During handling of the above exception, another exception occurred:

Traceback (most recent call last):
  File "/home/utkarshrasal/.local/lib/python3.8/site-packages/django/core/handlers/exception.py", line 47, in inner
    response = get_response(request)
  File "/home/utkarshrasal/.local/lib/python3.8/site-packages/django/core/handlers/base.py", line 181, in _get_response
    response = wrapped_callback(request, *callback_args, **callback_kwargs)
  File "/home/utkarshrasal/.local/lib/python3.8/site-packages/django/views/decorators/csrf.py", line 54, in wrapped_view
    return view_func(*args, **kwargs)
  File "/home/utkarshrasal/.local/lib/python3.8/site-packages/rest_framework/viewsets.py", line 125, in view
    return self.dispatch(request, *args, **kwargs)
  File "/home/utkarshrasal/.local/lib/python3.8/site-packages/rest_framework/views.py", line 509, in dispatch
    response = self.handle_exception(exc)
  File "/home/utkarshrasal/.local/lib/python3.8/site-packages/rest_framework/views.py", line 469, in handle_exception
    self.raise_uncaught_exception(exc)
  File "/home/utkarshrasal/.local/lib/python3.8/site-packages/rest_framework/views.py", line 480, in raise_uncaught_exception
    raise exc
  File "/home/utkarshrasal/.local/lib/python3.8/site-packages/rest_framework/views.py", line 506, in dispatch
    response = handler(request, *args, **kwargs)
  File "/media/utkarshrasal/4846FE1A46FE0908/WORK/PYTHON/Django/bloggingwebsite/blogs/mixins.py", line 180, in activity
    'data':serializers.data
  File "/home/utkarshrasal/.local/lib/python3.8/site-packages/rest_framework/serializers.py", line 745, in data
    ret = super().data
  File "/home/utkarshrasal/.local/lib/python3.8/site-packages/rest_framework/serializers.py", line 246, in data
    self._data = self.to_representation(self.instance)
  File "/home/utkarshrasal/.local/lib/python3.8/site-packages/rest_framework/serializers.py", line 663, in to_representation
    return [
  File "/home/utkarshrasal/.local/lib/python3.8/site-packages/rest_framework/serializers.py", line 664, in <listcomp>
    self.child.to_representation(item) for item in iterable
  File "/home/utkarshrasal/.local/lib/python3.8/site-packages/rest_framework/serializers.py", line 502, in to_representation
    attribute = field.get_attribute(instance)
  File "/home/utkarshrasal/.local/lib/python3.8/site-packages/rest_framework/fields.py", line 490, in get_attribute
    raise type(exc)(msg)
AttributeError: Got AttributeError when attempting to get a value for field `logs` on serializer `ActivitySerializer`.
The serializer field might be named incorrectly and not match any attribute or key on the `Blogs` instance.
Original exception text was: 'Blogs' object has no attribute 'logs'.
INFO:django.utils.autoreload:/media/utkarshrasal/4846FE1A46FE0908/WORK/PYTHON/Django/bloggingwebsite/blogs/models.py changed, reloading.
INFO:django.utils.autoreload:/media/utkarshrasal/4846FE1A46FE0908/WORK/PYTHON/Django/bloggingwebsite/blogs/mixins.py changed, reloading.
ERROR:django.request:Internal Server Error: /blogs/575aefcf-26ac-4b06-b2c2-9cd2a810808c/activity/
Traceback (most recent call last):
  File "/home/utkarshrasal/.local/lib/python3.8/site-packages/django/core/handlers/exception.py", line 47, in inner
    response = get_response(request)
  File "/home/utkarshrasal/.local/lib/python3.8/site-packages/django/core/handlers/base.py", line 181, in _get_response
    response = wrapped_callback(request, *callback_args, **callback_kwargs)
  File "/home/utkarshrasal/.local/lib/python3.8/site-packages/django/views/decorators/csrf.py", line 54, in wrapped_view
    return view_func(*args, **kwargs)
  File "/home/utkarshrasal/.local/lib/python3.8/site-packages/rest_framework/viewsets.py", line 125, in view
    return self.dispatch(request, *args, **kwargs)
  File "/home/utkarshrasal/.local/lib/python3.8/site-packages/rest_framework/views.py", line 509, in dispatch
    response = self.handle_exception(exc)
  File "/home/utkarshrasal/.local/lib/python3.8/site-packages/rest_framework/views.py", line 469, in handle_exception
    self.raise_uncaught_exception(exc)
  File "/home/utkarshrasal/.local/lib/python3.8/site-packages/rest_framework/views.py", line 480, in raise_uncaught_exception
    raise exc
  File "/home/utkarshrasal/.local/lib/python3.8/site-packages/rest_framework/views.py", line 506, in dispatch
    response = handler(request, *args, **kwargs)
  File "/media/utkarshrasal/4846FE1A46FE0908/WORK/PYTHON/Django/bloggingwebsite/blogs/mixins.py", line 180, in activity
    'data':serializers.data
  File "/home/utkarshrasal/.local/lib/python3.8/site-packages/rest_framework/serializers.py", line 745, in data
    ret = super().data
  File "/home/utkarshrasal/.local/lib/python3.8/site-packages/rest_framework/serializers.py", line 246, in data
    self._data = self.to_representation(self.instance)
  File "/home/utkarshrasal/.local/lib/python3.8/site-packages/rest_framework/serializers.py", line 663, in to_representation
    return [
  File "/home/utkarshrasal/.local/lib/python3.8/site-packages/rest_framework/serializers.py", line 664, in <listcomp>
    self.child.to_representation(item) for item in iterable
  File "/home/utkarshrasal/.local/lib/python3.8/site-packages/rest_framework/serializers.py", line 500, in to_representation
    for field in fields:
  File "/home/utkarshrasal/.local/lib/python3.8/site-packages/rest_framework/serializers.py", line 361, in _readable_fields
    for field in self.fields.values():
  File "/home/utkarshrasal/.local/lib/python3.8/site-packages/django/utils/functional.py", line 48, in __get__
    res = instance.__dict__[self.name] = self.func(instance)
  File "/home/utkarshrasal/.local/lib/python3.8/site-packages/rest_framework/serializers.py", line 349, in fields
    for key, value in self.get_fields().items():
  File "/home/utkarshrasal/.local/lib/python3.8/site-packages/rest_framework/serializers.py", line 1053, in get_fields
    field_class, field_kwargs = self.build_field(
  File "/home/utkarshrasal/.local/lib/python3.8/site-packages/rest_framework/serializers.py", line 1199, in build_field
    return self.build_unknown_field(field_name, model_class)
  File "/home/utkarshrasal/.local/lib/python3.8/site-packages/rest_framework/serializers.py", line 1317, in build_unknown_field
    raise ImproperlyConfigured(
django.core.exceptions.ImproperlyConfigured: Field name `blogs` is not valid for model `Activity`.
INFO:django.utils.autoreload:/media/utkarshrasal/4846FE1A46FE0908/WORK/PYTHON/Django/bloggingwebsite/blogs/serializers.py changed, reloading.
INFO:django.utils.autoreload:/media/utkarshrasal/4846FE1A46FE0908/WORK/PYTHON/Django/bloggingwebsite/blogs/viewsets.py changed, reloading.
INFO:root:Blog's listed for the user '1f3a52f8-3966-497d-a948-47b6cc2e41c1'
ERROR:django.request:Internal Server Error: /blogs/
Traceback (most recent call last):
  File "/home/utkarshrasal/.local/lib/python3.8/site-packages/django/core/handlers/exception.py", line 47, in inner
    response = get_response(request)
  File "/home/utkarshrasal/.local/lib/python3.8/site-packages/django/core/handlers/base.py", line 181, in _get_response
    response = wrapped_callback(request, *callback_args, **callback_kwargs)
  File "/home/utkarshrasal/.local/lib/python3.8/site-packages/django/views/decorators/csrf.py", line 54, in wrapped_view
    return view_func(*args, **kwargs)
  File "/home/utkarshrasal/.local/lib/python3.8/site-packages/rest_framework/viewsets.py", line 125, in view
    return self.dispatch(request, *args, **kwargs)
  File "/home/utkarshrasal/.local/lib/python3.8/site-packages/rest_framework/views.py", line 509, in dispatch
    response = self.handle_exception(exc)
  File "/home/utkarshrasal/.local/lib/python3.8/site-packages/rest_framework/views.py", line 469, in handle_exception
    self.raise_uncaught_exception(exc)
  File "/home/utkarshrasal/.local/lib/python3.8/site-packages/rest_framework/views.py", line 480, in raise_uncaught_exception
    raise exc
  File "/home/utkarshrasal/.local/lib/python3.8/site-packages/rest_framework/views.py", line 506, in dispatch
    response = handler(request, *args, **kwargs)
  File "/media/utkarshrasal/4846FE1A46FE0908/WORK/PYTHON/Django/bloggingwebsite/blogs/viewsets.py", line 38, in list
    blog = self.model_class.objects.get(id=data['id'])
NameError: name 'data' is not defined
INFO:django.utils.autoreload:/media/utkarshrasal/4846FE1A46FE0908/WORK/PYTHON/Django/bloggingwebsite/blogs/viewsets.py changed, reloading.
INFO:root:Blog's listed for the user '1f3a52f8-3966-497d-a948-47b6cc2e41c1'
ERROR:django.request:Internal Server Error: /blogs/
Traceback (most recent call last):
  File "/home/utkarshrasal/.local/lib/python3.8/site-packages/django/core/handlers/exception.py", line 47, in inner
    response = get_response(request)
  File "/home/utkarshrasal/.local/lib/python3.8/site-packages/django/core/handlers/base.py", line 181, in _get_response
    response = wrapped_callback(request, *callback_args, **callback_kwargs)
  File "/home/utkarshrasal/.local/lib/python3.8/site-packages/django/views/decorators/csrf.py", line 54, in wrapped_view
    return view_func(*args, **kwargs)
  File "/home/utkarshrasal/.local/lib/python3.8/site-packages/rest_framework/viewsets.py", line 125, in view
    return self.dispatch(request, *args, **kwargs)
  File "/home/utkarshrasal/.local/lib/python3.8/site-packages/rest_framework/views.py", line 509, in dispatch
    response = self.handle_exception(exc)
  File "/home/utkarshrasal/.local/lib/python3.8/site-packages/rest_framework/views.py", line 469, in handle_exception
    self.raise_uncaught_exception(exc)
  File "/home/utkarshrasal/.local/lib/python3.8/site-packages/rest_framework/views.py", line 480, in raise_uncaught_exception
    raise exc
  File "/home/utkarshrasal/.local/lib/python3.8/site-packages/rest_framework/views.py", line 506, in dispatch
    response = handler(request, *args, **kwargs)
  File "/media/utkarshrasal/4846FE1A46FE0908/WORK/PYTHON/Django/bloggingwebsite/blogs/viewsets.py", line 38, in list
    blog = self.model_class.objects.get(id=serializers.data['id'])
KeyError: 'id'
INFO:django.utils.autoreload:/media/utkarshrasal/4846FE1A46FE0908/WORK/PYTHON/Django/bloggingwebsite/blogs/viewsets.py changed, reloading.
INFO:django.utils.autoreload:/media/utkarshrasal/4846FE1A46FE0908/WORK/PYTHON/Django/bloggingwebsite/blogs/viewsets.py changed, reloading.
INFO:django.utils.autoreload:/media/utkarshrasal/4846FE1A46FE0908/WORK/PYTHON/Django/bloggingwebsite/blogs/viewsets.py changed, reloading.
INFO:django.utils.autoreload:/media/utkarshrasal/4846FE1A46FE0908/WORK/PYTHON/Django/bloggingwebsite/blogs/viewsets.py changed, reloading.
INFO:django.utils.autoreload:/media/utkarshrasal/4846FE1A46FE0908/WORK/PYTHON/Django/bloggingwebsite/blogs/viewsets.py changed, reloading.
INFO:django.utils.autoreload:/media/utkarshrasal/4846FE1A46FE0908/WORK/PYTHON/Django/bloggingwebsite/blogs/mixins.py changed, reloading.
INFO:root:Blog's listed for the user '1f3a52f8-3966-497d-a948-47b6cc2e41c1'
INFO:root:Commented on Blog '575aefcf-26ac-4b06-b2c2-9cd2a810808c'
ERROR:django.request:Internal Server Error: /blogs/575aefcf-26ac-4b06-b2c2-9cd2a810808c/post_comment/
Traceback (most recent call last):
  File "/home/utkarshrasal/.local/lib/python3.8/site-packages/django/core/handlers/exception.py", line 47, in inner
    response = get_response(request)
  File "/home/utkarshrasal/.local/lib/python3.8/site-packages/django/core/handlers/base.py", line 181, in _get_response
    response = wrapped_callback(request, *callback_args, **callback_kwargs)
  File "/home/utkarshrasal/.local/lib/python3.8/site-packages/django/views/decorators/csrf.py", line 54, in wrapped_view
    return view_func(*args, **kwargs)
  File "/home/utkarshrasal/.local/lib/python3.8/site-packages/rest_framework/viewsets.py", line 125, in view
    return self.dispatch(request, *args, **kwargs)
  File "/home/utkarshrasal/.local/lib/python3.8/site-packages/rest_framework/views.py", line 509, in dispatch
    response = self.handle_exception(exc)
  File "/home/utkarshrasal/.local/lib/python3.8/site-packages/rest_framework/views.py", line 469, in handle_exception
    self.raise_uncaught_exception(exc)
  File "/home/utkarshrasal/.local/lib/python3.8/site-packages/rest_framework/views.py", line 480, in raise_uncaught_exception
    raise exc
  File "/home/utkarshrasal/.local/lib/python3.8/site-packages/rest_framework/views.py", line 506, in dispatch
    response = handler(request, *args, **kwargs)
  File "/media/utkarshrasal/4846FE1A46FE0908/WORK/PYTHON/Django/bloggingwebsite/blogs/mixins.py", line 60, in post_comment
    Activity.objects.create(user=request.user, blogs=instance, logs = f"Commented on blog '{pk}'")
NameError: name 'instance' is not defined
INFO:django.utils.autoreload:/media/utkarshrasal/4846FE1A46FE0908/WORK/PYTHON/Django/bloggingwebsite/blogs/mixins.py changed, reloading.
INFO:root:Commented on Blog '575aefcf-26ac-4b06-b2c2-9cd2a810808c'
ERROR:django.request:Internal Server Error: /blogs/575aefcf-26ac-4b06-b2c2-9cd2a810808c/post_comment/
Traceback (most recent call last):
  File "/home/utkarshrasal/.local/lib/python3.8/site-packages/django/core/handlers/exception.py", line 47, in inner
    response = get_response(request)
  File "/home/utkarshrasal/.local/lib/python3.8/site-packages/django/core/handlers/base.py", line 181, in _get_response
    response = wrapped_callback(request, *callback_args, **callback_kwargs)
  File "/home/utkarshrasal/.local/lib/python3.8/site-packages/django/views/decorators/csrf.py", line 54, in wrapped_view
    return view_func(*args, **kwargs)
  File "/home/utkarshrasal/.local/lib/python3.8/site-packages/rest_framework/viewsets.py", line 125, in view
    return self.dispatch(request, *args, **kwargs)
  File "/home/utkarshrasal/.local/lib/python3.8/site-packages/rest_framework/views.py", line 509, in dispatch
    response = self.handle_exception(exc)
  File "/home/utkarshrasal/.local/lib/python3.8/site-packages/rest_framework/views.py", line 469, in handle_exception
    self.raise_uncaught_exception(exc)
  File "/home/utkarshrasal/.local/lib/python3.8/site-packages/rest_framework/views.py", line 480, in raise_uncaught_exception
    raise exc
  File "/home/utkarshrasal/.local/lib/python3.8/site-packages/rest_framework/views.py", line 506, in dispatch
    response = handler(request, *args, **kwargs)
  File "/media/utkarshrasal/4846FE1A46FE0908/WORK/PYTHON/Django/bloggingwebsite/blogs/mixins.py", line 60, in post_comment
    Activity.objects.create(user=request.user, blogs=blog, logs = f"Commented on blog '{pk}'")
  File "/home/utkarshrasal/.local/lib/python3.8/site-packages/django/db/models/manager.py", line 85, in manager_method
    return getattr(self.get_queryset(), name)(*args, **kwargs)
  File "/home/utkarshrasal/.local/lib/python3.8/site-packages/django/db/models/query.py", line 445, in create
    obj = self.model(**kwargs)
  File "/home/utkarshrasal/.local/lib/python3.8/site-packages/django/db/models/base.py", line 501, in __init__
    raise TypeError("%s() got an unexpected keyword argument '%s'" % (cls.__name__, kwarg))
TypeError: Activity() got an unexpected keyword argument 'blogs'
INFO:django.utils.autoreload:/media/utkarshrasal/4846FE1A46FE0908/WORK/PYTHON/Django/bloggingwebsite/blogs/mixins.py changed, reloading.
INFO:django.utils.autoreload:/media/utkarshrasal/4846FE1A46FE0908/WORK/PYTHON/Django/bloggingwebsite/blogs/mixins.py changed, reloading.
INFO:django.utils.autoreload:/media/utkarshrasal/4846FE1A46FE0908/WORK/PYTHON/Django/bloggingwebsite/blogs/viewsets.py changed, reloading.
INFO:root:Commented on Blog '575aefcf-26ac-4b06-b2c2-9cd2a810808c'
INFO:django.utils.autoreload:/media/utkarshrasal/4846FE1A46FE0908/WORK/PYTHON/Django/bloggingwebsite/blogs/mixins.py changed, reloading.
INFO:django.utils.autoreload:/media/utkarshrasal/4846FE1A46FE0908/WORK/PYTHON/Django/bloggingwebsite/blogs/mixins.py changed, reloading.
INFO:root:Commented on Blog '575aefcf-26ac-4b06-b2c2-9cd2a810808c'
INFO:root:Commented retrieved for Blog '575aefcf-26ac-4b06-b2c2-9cd2a810808c'
INFO:django.utils.autoreload:/media/utkarshrasal/4846FE1A46FE0908/WORK/PYTHON/Django/bloggingwebsite/blogs/mixins.py changed, reloading.
INFO:root:Liked Blog '575aefcf-26ac-4b06-b2c2-9cd2a810808c'
ERROR:django.request:Internal Server Error: /blogs/575aefcf-26ac-4b06-b2c2-9cd2a810808c/like_dislike/
Traceback (most recent call last):
  File "/home/utkarshrasal/.local/lib/python3.8/site-packages/django/core/handlers/exception.py", line 47, in inner
    response = get_response(request)
  File "/home/utkarshrasal/.local/lib/python3.8/site-packages/django/core/handlers/base.py", line 181, in _get_response
    response = wrapped_callback(request, *callback_args, **callback_kwargs)
  File "/home/utkarshrasal/.local/lib/python3.8/site-packages/django/views/decorators/csrf.py", line 54, in wrapped_view
    return view_func(*args, **kwargs)
  File "/home/utkarshrasal/.local/lib/python3.8/site-packages/rest_framework/viewsets.py", line 125, in view
    return self.dispatch(request, *args, **kwargs)
  File "/home/utkarshrasal/.local/lib/python3.8/site-packages/rest_framework/views.py", line 509, in dispatch
    response = self.handle_exception(exc)
  File "/home/utkarshrasal/.local/lib/python3.8/site-packages/rest_framework/views.py", line 469, in handle_exception
    self.raise_uncaught_exception(exc)
  File "/home/utkarshrasal/.local/lib/python3.8/site-packages/rest_framework/views.py", line 480, in raise_uncaught_exception
    raise exc
  File "/home/utkarshrasal/.local/lib/python3.8/site-packages/rest_framework/views.py", line 506, in dispatch
    response = handler(request, *args, **kwargs)
  File "/media/utkarshrasal/4846FE1A46FE0908/WORK/PYTHON/Django/bloggingwebsite/blogs/mixins.py", line 136, in like_dislike
    Activity.objects.create(user=request.user, blog=blogs, logs = f"Liked blog '{pk}'")
NameError: name 'pk' is not defined
INFO:django.utils.autoreload:/media/utkarshrasal/4846FE1A46FE0908/WORK/PYTHON/Django/bloggingwebsite/blogs/mixins.py changed, reloading.
INFO:root:Disliked Blog '575aefcf-26ac-4b06-b2c2-9cd2a810808c'
INFO:root:Liked Blog '575aefcf-26ac-4b06-b2c2-9cd2a810808c'
INFO:root:Disliked Blog '575aefcf-26ac-4b06-b2c2-9cd2a810808c'
INFO:django.utils.autoreload:/media/utkarshrasal/4846FE1A46FE0908/WORK/PYTHON/Django/bloggingwebsite/blogs/mixins.py changed, reloading.
INFO:django.utils.autoreload:/media/utkarshrasal/4846FE1A46FE0908/WORK/PYTHON/Django/bloggingwebsite/blogs/mixins.py changed, reloading.
INFO:django.utils.autoreload:/media/utkarshrasal/4846FE1A46FE0908/WORK/PYTHON/Django/bloggingwebsite/blogs/urls.py changed, reloading.
INFO:django.utils.autoreload:/media/utkarshrasal/4846FE1A46FE0908/WORK/PYTHON/Django/bloggingwebsite/blogs/mixins.py changed, reloading.
INFO:django.utils.autoreload:/media/utkarshrasal/4846FE1A46FE0908/WORK/PYTHON/Django/bloggingwebsite/blogs/mixins.py changed, reloading.
ERROR:django.request:Internal Server Error: /blogs/64a6230d-5437-457a-a455-b13a72cee174/
Traceback (most recent call last):
  File "/home/utkarshrasal/.local/lib/python3.8/site-packages/django/core/handlers/exception.py", line 47, in inner
    response = get_response(request)
  File "/home/utkarshrasal/.local/lib/python3.8/site-packages/django/core/handlers/base.py", line 181, in _get_response
    response = wrapped_callback(request, *callback_args, **callback_kwargs)
  File "/home/utkarshrasal/.local/lib/python3.8/site-packages/django/views/decorators/csrf.py", line 54, in wrapped_view
    return view_func(*args, **kwargs)
  File "/home/utkarshrasal/.local/lib/python3.8/site-packages/rest_framework/viewsets.py", line 125, in view
    return self.dispatch(request, *args, **kwargs)
  File "/home/utkarshrasal/.local/lib/python3.8/site-packages/rest_framework/views.py", line 509, in dispatch
    response = self.handle_exception(exc)
  File "/home/utkarshrasal/.local/lib/python3.8/site-packages/rest_framework/views.py", line 469, in handle_exception
    self.raise_uncaught_exception(exc)
  File "/home/utkarshrasal/.local/lib/python3.8/site-packages/rest_framework/views.py", line 480, in raise_uncaught_exception
    raise exc
  File "/home/utkarshrasal/.local/lib/python3.8/site-packages/rest_framework/views.py", line 506, in dispatch
    response = handler(request, *args, **kwargs)
  File "/media/utkarshrasal/4846FE1A46FE0908/WORK/PYTHON/Django/bloggingwebsite/blogs/viewsets.py", line 87, in retrieve
    instance = self.model_class.objects.get(id=pk)
  File "/home/utkarshrasal/.local/lib/python3.8/site-packages/django/db/models/manager.py", line 85, in manager_method
    return getattr(self.get_queryset(), name)(*args, **kwargs)
  File "/home/utkarshrasal/.local/lib/python3.8/site-packages/django/db/models/query.py", line 429, in get
    raise self.model.DoesNotExist(
blogs.models.Blogs.DoesNotExist: Blogs matching query does not exist.
WARNING:django.request:Method Not Allowed: /blogs/64a6230d-5437-457a-a455-b13a72cee174/comment/
INFO:django.utils.autoreload:/media/utkarshrasal/4846FE1A46FE0908/WORK/PYTHON/Django/bloggingwebsite/blogs/mixins.py changed, reloading.
WARNING:django.request:Method Not Allowed: /blogs/64a6230d-5437-457a-a455-b13a72cee174/comment/
WARNING:django.request:Not Found: /blogs/64a6230d-5437-457a-a455-b13a72cee174/destroy
WARNING:django.request:Not Found: /blogs/64a6230d-5437-457a-a455-b13a72cee174/destroy/
INFO:django.utils.autoreload:/media/utkarshrasal/4846FE1A46FE0908/WORK/PYTHON/Django/bloggingwebsite/blogs/mixins.py changed, reloading.
WARNING:django.request:Not Found: /blogs/64a6230d-5437-457a-a455-b13a72cee174/destroy/
WARNING:django.request:Not Found: /favicon.ico
WARNING:django.request:Not Found: /favicon.ico
INFO:django.utils.autoreload:/media/utkarshrasal/4846FE1A46FE0908/WORK/PYTHON/Django/bloggingwebsite/blogs/serializers.py changed, reloading.
WARNING:django.request:Not Found: /favicon.ico
INFO:django.utils.autoreload:/media/utkarshrasal/4846FE1A46FE0908/WORK/PYTHON/Django/bloggingwebsite/blogs/mixins.py changed, reloading.
ERROR:django.request:Internal Server Error: /blogs/575aefcf-26ac-4b06-b2c2-9cd2a810808c/activity/
Traceback (most recent call last):
  File "/home/utkarshrasal/.local/lib/python3.8/site-packages/django/core/handlers/exception.py", line 47, in inner
    response = get_response(request)
  File "/home/utkarshrasal/.local/lib/python3.8/site-packages/django/core/handlers/base.py", line 181, in _get_response
    response = wrapped_callback(request, *callback_args, **callback_kwargs)
  File "/home/utkarshrasal/.local/lib/python3.8/site-packages/django/views/decorators/csrf.py", line 54, in wrapped_view
    return view_func(*args, **kwargs)
  File "/home/utkarshrasal/.local/lib/python3.8/site-packages/rest_framework/viewsets.py", line 125, in view
    return self.dispatch(request, *args, **kwargs)
  File "/home/utkarshrasal/.local/lib/python3.8/site-packages/rest_framework/views.py", line 509, in dispatch
    response = self.handle_exception(exc)
  File "/home/utkarshrasal/.local/lib/python3.8/site-packages/rest_framework/views.py", line 469, in handle_exception
    self.raise_uncaught_exception(exc)
  File "/home/utkarshrasal/.local/lib/python3.8/site-packages/rest_framework/views.py", line 480, in raise_uncaught_exception
    raise exc
  File "/home/utkarshrasal/.local/lib/python3.8/site-packages/rest_framework/views.py", line 506, in dispatch
    response = handler(request, *args, **kwargs)
  File "/media/utkarshrasal/4846FE1A46FE0908/WORK/PYTHON/Django/bloggingwebsite/blogs/mixins.py", line 170, in activity
    instance = Activity.objects.filter(user=request.user)
NameError: name 'request' is not defined
INFO:django.utils.autoreload:/media/utkarshrasal/4846FE1A46FE0908/WORK/PYTHON/Django/bloggingwebsite/blogs/mixins.py changed, reloading.
WARNING:django.request:Not Found: /favicon.ico
WARNING:django.request:Not Found: /favicon.ico
WARNING:django.request:Not Found: /favicon.ico
INFO:django.utils.autoreload:/media/utkarshrasal/4846FE1A46FE0908/WORK/PYTHON/Django/bloggingwebsite/blogs/views.py changed, reloading.
INFO:django.utils.autoreload:/media/utkarshrasal/4846FE1A46FE0908/WORK/PYTHON/Django/bloggingwebsite/blogs/views.py changed, reloading.
INFO:django.utils.autoreload:/media/utkarshrasal/4846FE1A46FE0908/WORK/PYTHON/Django/bloggingwebsite/blogs/views.py changed, reloading.
ERROR:django.request:Internal Server Error: /blogs/575aefcf-26ac-4b06-b2c2-9cd2a810808c/
Traceback (most recent call last):
  File "/home/utkarshrasal/.local/lib/python3.8/site-packages/django/utils/datastructures.py", line 76, in __getitem__
    list_ = super().__getitem__(key)
KeyError: 'file'

During handling of the above exception, another exception occurred:

Traceback (most recent call last):
  File "/home/utkarshrasal/.local/lib/python3.8/site-packages/django/core/handlers/exception.py", line 47, in inner
    response = get_response(request)
  File "/home/utkarshrasal/.local/lib/python3.8/site-packages/django/core/handlers/base.py", line 181, in _get_response
    response = wrapped_callback(request, *callback_args, **callback_kwargs)
  File "/home/utkarshrasal/.local/lib/python3.8/site-packages/django/views/decorators/csrf.py", line 54, in wrapped_view
    return view_func(*args, **kwargs)
  File "/home/utkarshrasal/.local/lib/python3.8/site-packages/rest_framework/viewsets.py", line 125, in view
    return self.dispatch(request, *args, **kwargs)
  File "/home/utkarshrasal/.local/lib/python3.8/site-packages/rest_framework/views.py", line 509, in dispatch
    response = self.handle_exception(exc)
  File "/home/utkarshrasal/.local/lib/python3.8/site-packages/rest_framework/views.py", line 469, in handle_exception
    self.raise_uncaught_exception(exc)
  File "/home/utkarshrasal/.local/lib/python3.8/site-packages/rest_framework/views.py", line 480, in raise_uncaught_exception
    raise exc
  File "/home/utkarshrasal/.local/lib/python3.8/site-packages/rest_framework/views.py", line 506, in dispatch
    response = handler(request, *args, **kwargs)
  File "/media/utkarshrasal/4846FE1A46FE0908/WORK/PYTHON/Django/bloggingwebsite/blogs/views.py", line 29, in partial_update
    path = 'http://' + current_site + '/' + file_path(request)
  File "/media/utkarshrasal/4846FE1A46FE0908/WORK/PYTHON/Django/bloggingwebsite/blogs/path.py", line 5, in file_path
    file = request.FILES['file']
  File "/home/utkarshrasal/.local/lib/python3.8/site-packages/django/utils/datastructures.py", line 78, in __getitem__
    raise MultiValueDictKeyError(key)
django.utils.datastructures.MultiValueDictKeyError: 'file'
INFO:django.utils.autoreload:/media/utkarshrasal/4846FE1A46FE0908/WORK/PYTHON/Django/bloggingwebsite/blogs/views.py changed, reloading.
INFO:django.utils.autoreload:/media/utkarshrasal/4846FE1A46FE0908/WORK/PYTHON/Django/bloggingwebsite/blogs/viewsets.py changed, reloading.
INFO:django.utils.autoreload:/media/utkarshrasal/4846FE1A46FE0908/WORK/PYTHON/Django/bloggingwebsite/blogs/viewsets.py changed, reloading.
ERROR:django.request:Internal Server Error: /blogs/575aefcf-26ac-4b06-b2c2-9cd2a810808c/
Traceback (most recent call last):
  File "/home/utkarshrasal/.local/lib/python3.8/site-packages/django/utils/datastructures.py", line 76, in __getitem__
    list_ = super().__getitem__(key)
KeyError: 'file'

During handling of the above exception, another exception occurred:

Traceback (most recent call last):
  File "/home/utkarshrasal/.local/lib/python3.8/site-packages/django/core/handlers/exception.py", line 47, in inner
    response = get_response(request)
  File "/home/utkarshrasal/.local/lib/python3.8/site-packages/django/core/handlers/base.py", line 181, in _get_response
    response = wrapped_callback(request, *callback_args, **callback_kwargs)
  File "/home/utkarshrasal/.local/lib/python3.8/site-packages/django/views/decorators/csrf.py", line 54, in wrapped_view
    return view_func(*args, **kwargs)
  File "/home/utkarshrasal/.local/lib/python3.8/site-packages/rest_framework/viewsets.py", line 125, in view
    return self.dispatch(request, *args, **kwargs)
  File "/home/utkarshrasal/.local/lib/python3.8/site-packages/rest_framework/views.py", line 509, in dispatch
    response = self.handle_exception(exc)
  File "/home/utkarshrasal/.local/lib/python3.8/site-packages/rest_framework/views.py", line 469, in handle_exception
    self.raise_uncaught_exception(exc)
  File "/home/utkarshrasal/.local/lib/python3.8/site-packages/rest_framework/views.py", line 480, in raise_uncaught_exception
    raise exc
  File "/home/utkarshrasal/.local/lib/python3.8/site-packages/rest_framework/views.py", line 506, in dispatch
    response = handler(request, *args, **kwargs)
  File "/media/utkarshrasal/4846FE1A46FE0908/WORK/PYTHON/Django/bloggingwebsite/blogs/viewsets.py", line 139, in partial_update
    path = 'http://' + current_site + '/' + file_path(request)
  File "/media/utkarshrasal/4846FE1A46FE0908/WORK/PYTHON/Django/bloggingwebsite/blogs/path.py", line 5, in file_path
    file = request.FILES['file']
  File "/home/utkarshrasal/.local/lib/python3.8/site-packages/django/utils/datastructures.py", line 78, in __getitem__
    raise MultiValueDictKeyError(key)
django.utils.datastructures.MultiValueDictKeyError: 'file'
INFO:django.utils.autoreload:/media/utkarshrasal/4846FE1A46FE0908/WORK/PYTHON/Django/bloggingwebsite/blogs/viewsets.py changed, reloading.
INFO:root:Partially updated Blog '575aefcf-26ac-4b06-b2c2-9cd2a810808c'
ERROR:django.request:Internal Server Error: /blogs/575aefcf-26ac-4b06-b2c2-9cd2a810808c/
Traceback (most recent call last):
  File "/home/utkarshrasal/.local/lib/python3.8/site-packages/django/utils/datastructures.py", line 76, in __getitem__
    list_ = super().__getitem__(key)
KeyError: 'file'

During handling of the above exception, another exception occurred:

Traceback (most recent call last):
  File "/home/utkarshrasal/.local/lib/python3.8/site-packages/django/core/handlers/exception.py", line 47, in inner
    response = get_response(request)
  File "/home/utkarshrasal/.local/lib/python3.8/site-packages/django/core/handlers/base.py", line 181, in _get_response
    response = wrapped_callback(request, *callback_args, **callback_kwargs)
  File "/home/utkarshrasal/.local/lib/python3.8/site-packages/django/views/decorators/csrf.py", line 54, in wrapped_view
    return view_func(*args, **kwargs)
  File "/home/utkarshrasal/.local/lib/python3.8/site-packages/rest_framework/viewsets.py", line 125, in view
    return self.dispatch(request, *args, **kwargs)
  File "/home/utkarshrasal/.local/lib/python3.8/site-packages/rest_framework/views.py", line 509, in dispatch
    response = self.handle_exception(exc)
  File "/home/utkarshrasal/.local/lib/python3.8/site-packages/rest_framework/views.py", line 469, in handle_exception
    self.raise_uncaught_exception(exc)
  File "/home/utkarshrasal/.local/lib/python3.8/site-packages/rest_framework/views.py", line 480, in raise_uncaught_exception
    raise exc
  File "/home/utkarshrasal/.local/lib/python3.8/site-packages/rest_framework/views.py", line 506, in dispatch
    response = handler(request, *args, **kwargs)
  File "/media/utkarshrasal/4846FE1A46FE0908/WORK/PYTHON/Django/bloggingwebsite/blogs/viewsets.py", line 140, in partial_update
    if request.data['file']:
  File "/home/utkarshrasal/.local/lib/python3.8/site-packages/django/utils/datastructures.py", line 78, in __getitem__
    raise MultiValueDictKeyError(key)
django.utils.datastructures.MultiValueDictKeyError: 'file'
INFO:django.utils.autoreload:/media/utkarshrasal/4846FE1A46FE0908/WORK/PYTHON/Django/bloggingwebsite/blogs/viewsets.py changed, reloading.
INFO:root:Partially updated Blog '575aefcf-26ac-4b06-b2c2-9cd2a810808c'
INFO:root:Partially updated Blog '575aefcf-26ac-4b06-b2c2-9cd2a810808c'
INFO:django.utils.autoreload:/media/utkarshrasal/4846FE1A46FE0908/WORK/PYTHON/Django/bloggingwebsite/blogs/viewsets.py changed, reloading.
INFO:root:Partially updated Blog '575aefcf-26ac-4b06-b2c2-9cd2a810808c'
INFO:django.utils.autoreload:/media/utkarshrasal/4846FE1A46FE0908/WORK/PYTHON/Django/bloggingwebsite/blogs/viewsets.py changed, reloading.
INFO:root:Partially updated Blog '575aefcf-26ac-4b06-b2c2-9cd2a810808c'
ERROR:django.request:Internal Server Error: /blogs/575aefcf-26ac-4b06-b2c2-9cd2a810808c/
Traceback (most recent call last):
  File "/home/utkarshrasal/.local/lib/python3.8/site-packages/django/core/handlers/exception.py", line 47, in inner
    response = get_response(request)
  File "/home/utkarshrasal/.local/lib/python3.8/site-packages/django/core/handlers/base.py", line 181, in _get_response
    response = wrapped_callback(request, *callback_args, **callback_kwargs)
  File "/home/utkarshrasal/.local/lib/python3.8/site-packages/django/views/decorators/csrf.py", line 54, in wrapped_view
    return view_func(*args, **kwargs)
  File "/home/utkarshrasal/.local/lib/python3.8/site-packages/rest_framework/viewsets.py", line 125, in view
    return self.dispatch(request, *args, **kwargs)
  File "/home/utkarshrasal/.local/lib/python3.8/site-packages/rest_framework/views.py", line 509, in dispatch
    response = self.handle_exception(exc)
  File "/home/utkarshrasal/.local/lib/python3.8/site-packages/rest_framework/views.py", line 469, in handle_exception
    self.raise_uncaught_exception(exc)
  File "/home/utkarshrasal/.local/lib/python3.8/site-packages/rest_framework/views.py", line 480, in raise_uncaught_exception
    raise exc
  File "/home/utkarshrasal/.local/lib/python3.8/site-packages/rest_framework/views.py", line 506, in dispatch
    response = handler(request, *args, **kwargs)
  File "/media/utkarshrasal/4846FE1A46FE0908/WORK/PYTHON/Django/bloggingwebsite/blogs/viewsets.py", line 144, in partial_update
    serializers = self.get_serializer(instance=instance, data=data, partial=True)
UnboundLocalError: local variable 'data' referenced before assignment
INFO:django.utils.autoreload:/media/utkarshrasal/4846FE1A46FE0908/WORK/PYTHON/Django/bloggingwebsite/blogs/viewsets.py changed, reloading.
ERROR:django.request:Internal Server Error: /blogs/575aefcf-26ac-4b06-b2c2-9cd2a810808c/
Traceback (most recent call last):
  File "/home/utkarshrasal/.local/lib/python3.8/site-packages/django/core/handlers/exception.py", line 47, in inner
    response = get_response(request)
  File "/home/utkarshrasal/.local/lib/python3.8/site-packages/django/core/handlers/base.py", line 181, in _get_response
    response = wrapped_callback(request, *callback_args, **callback_kwargs)
  File "/home/utkarshrasal/.local/lib/python3.8/site-packages/django/views/decorators/csrf.py", line 54, in wrapped_view
    return view_func(*args, **kwargs)
  File "/home/utkarshrasal/.local/lib/python3.8/site-packages/rest_framework/viewsets.py", line 125, in view
    return self.dispatch(request, *args, **kwargs)
  File "/home/utkarshrasal/.local/lib/python3.8/site-packages/rest_framework/views.py", line 509, in dispatch
    response = self.handle_exception(exc)
  File "/home/utkarshrasal/.local/lib/python3.8/site-packages/rest_framework/views.py", line 469, in handle_exception
    self.raise_uncaught_exception(exc)
  File "/home/utkarshrasal/.local/lib/python3.8/site-packages/rest_framework/views.py", line 480, in raise_uncaught_exception
    raise exc
  File "/home/utkarshrasal/.local/lib/python3.8/site-packages/rest_framework/views.py", line 506, in dispatch
    response = handler(request, *args, **kwargs)
  File "/media/utkarshrasal/4846FE1A46FE0908/WORK/PYTHON/Django/bloggingwebsite/blogs/viewsets.py", line 147, in partial_update
    serializers = self.get_serializer(instance=instance, data=data, partial=True)
UnboundLocalError: local variable 'data' referenced before assignment
INFO:django.utils.autoreload:/media/utkarshrasal/4846FE1A46FE0908/WORK/PYTHON/Django/bloggingwebsite/blogs/viewsets.py changed, reloading.
ERROR:django.request:Internal Server Error: /blogs/575aefcf-26ac-4b06-b2c2-9cd2a810808c/
Traceback (most recent call last):
  File "/home/utkarshrasal/.local/lib/python3.8/site-packages/django/core/handlers/exception.py", line 47, in inner
    response = get_response(request)
  File "/home/utkarshrasal/.local/lib/python3.8/site-packages/django/core/handlers/base.py", line 181, in _get_response
    response = wrapped_callback(request, *callback_args, **callback_kwargs)
  File "/home/utkarshrasal/.local/lib/python3.8/site-packages/django/views/decorators/csrf.py", line 54, in wrapped_view
    return view_func(*args, **kwargs)
  File "/home/utkarshrasal/.local/lib/python3.8/site-packages/rest_framework/viewsets.py", line 125, in view
    return self.dispatch(request, *args, **kwargs)
  File "/home/utkarshrasal/.local/lib/python3.8/site-packages/rest_framework/views.py", line 509, in dispatch
    response = self.handle_exception(exc)
  File "/home/utkarshrasal/.local/lib/python3.8/site-packages/rest_framework/views.py", line 469, in handle_exception
    self.raise_uncaught_exception(exc)
  File "/home/utkarshrasal/.local/lib/python3.8/site-packages/rest_framework/views.py", line 480, in raise_uncaught_exception
    raise exc
  File "/home/utkarshrasal/.local/lib/python3.8/site-packages/rest_framework/views.py", line 506, in dispatch
    response = handler(request, *args, **kwargs)
  File "/media/utkarshrasal/4846FE1A46FE0908/WORK/PYTHON/Django/bloggingwebsite/blogs/viewsets.py", line 147, in partial_update
    serializers = self.get_serializer(instance=instance, data=data, partial=True)
UnboundLocalError: local variable 'data' referenced before assignment
INFO:django.utils.autoreload:/media/utkarshrasal/4846FE1A46FE0908/WORK/PYTHON/Django/bloggingwebsite/blogs/viewsets.py changed, reloading.
INFO:root:Partially updated Blog '575aefcf-26ac-4b06-b2c2-9cd2a810808c'
INFO:root:Partially updated Blog '575aefcf-26ac-4b06-b2c2-9cd2a810808c'
INFO:django.utils.autoreload:/media/utkarshrasal/4846FE1A46FE0908/WORK/PYTHON/Django/bloggingwebsite/blogs/viewsets.py changed, reloading.
INFO:root:Partially updated Blog '575aefcf-26ac-4b06-b2c2-9cd2a810808c'
INFO:root:Partially updated Blog '575aefcf-26ac-4b06-b2c2-9cd2a810808c'
ERROR:django.request:Internal Server Error: /blogs/575aefcf-26ac-4b06-b2c2-9cd2a810808c/
Traceback (most recent call last):
  File "/home/utkarshrasal/.local/lib/python3.8/site-packages/django/utils/datastructures.py", line 76, in __getitem__
    list_ = super().__getitem__(key)
KeyError: 'content'

During handling of the above exception, another exception occurred:

Traceback (most recent call last):
  File "/home/utkarshrasal/.local/lib/python3.8/site-packages/django/core/handlers/exception.py", line 47, in inner
    response = get_response(request)
  File "/home/utkarshrasal/.local/lib/python3.8/site-packages/django/core/handlers/base.py", line 181, in _get_response
    response = wrapped_callback(request, *callback_args, **callback_kwargs)
  File "/home/utkarshrasal/.local/lib/python3.8/site-packages/django/views/decorators/csrf.py", line 54, in wrapped_view
    return view_func(*args, **kwargs)
  File "/home/utkarshrasal/.local/lib/python3.8/site-packages/rest_framework/viewsets.py", line 125, in view
    return self.dispatch(request, *args, **kwargs)
  File "/home/utkarshrasal/.local/lib/python3.8/site-packages/rest_framework/views.py", line 509, in dispatch
    response = self.handle_exception(exc)
  File "/home/utkarshrasal/.local/lib/python3.8/site-packages/rest_framework/views.py", line 469, in handle_exception
    self.raise_uncaught_exception(exc)
  File "/home/utkarshrasal/.local/lib/python3.8/site-packages/rest_framework/views.py", line 480, in raise_uncaught_exception
    raise exc
  File "/home/utkarshrasal/.local/lib/python3.8/site-packages/rest_framework/views.py", line 506, in dispatch
    response = handler(request, *args, **kwargs)
  File "/media/utkarshrasal/4846FE1A46FE0908/WORK/PYTHON/Django/bloggingwebsite/blogs/viewsets.py", line 146, in partial_update
    if request.data['content']:
  File "/home/utkarshrasal/.local/lib/python3.8/site-packages/django/utils/datastructures.py", line 78, in __getitem__
    raise MultiValueDictKeyError(key)
django.utils.datastructures.MultiValueDictKeyError: 'content'
INFO:django.utils.autoreload:/media/utkarshrasal/4846FE1A46FE0908/WORK/PYTHON/Django/bloggingwebsite/blogs/viewsets.py changed, reloading.
INFO:root:Partially updated Blog '575aefcf-26ac-4b06-b2c2-9cd2a810808c'
INFO:root:Partially updated Blog '575aefcf-26ac-4b06-b2c2-9cd2a810808c'
INFO:django.utils.autoreload:/media/utkarshrasal/4846FE1A46FE0908/WORK/PYTHON/Django/bloggingwebsite/blogs/serializers.py changed, reloading.
ERROR:django.request:Internal Server Error: /blogs/575aefcf-26ac-4b06-b2c2-9cd2a810808c/
Traceback (most recent call last):
  File "/home/utkarshrasal/.local/lib/python3.8/site-packages/django/core/handlers/exception.py", line 47, in inner
    response = get_response(request)
  File "/home/utkarshrasal/.local/lib/python3.8/site-packages/django/core/handlers/base.py", line 181, in _get_response
    response = wrapped_callback(request, *callback_args, **callback_kwargs)
  File "/home/utkarshrasal/.local/lib/python3.8/site-packages/django/views/decorators/csrf.py", line 54, in wrapped_view
    return view_func(*args, **kwargs)
  File "/home/utkarshrasal/.local/lib/python3.8/site-packages/rest_framework/viewsets.py", line 125, in view
    return self.dispatch(request, *args, **kwargs)
  File "/home/utkarshrasal/.local/lib/python3.8/site-packages/rest_framework/views.py", line 509, in dispatch
    response = self.handle_exception(exc)
  File "/home/utkarshrasal/.local/lib/python3.8/site-packages/rest_framework/views.py", line 469, in handle_exception
    self.raise_uncaught_exception(exc)
  File "/home/utkarshrasal/.local/lib/python3.8/site-packages/rest_framework/views.py", line 480, in raise_uncaught_exception
    raise exc
  File "/home/utkarshrasal/.local/lib/python3.8/site-packages/rest_framework/views.py", line 506, in dispatch
    response = handler(request, *args, **kwargs)
  File "/media/utkarshrasal/4846FE1A46FE0908/WORK/PYTHON/Django/bloggingwebsite/blogs/viewsets.py", line 151, in partial_update
    serializers.save()
  File "/home/utkarshrasal/.local/lib/python3.8/site-packages/rest_framework/serializers.py", line 200, in save
    self.instance = self.update(self.instance, validated_data)
  File "/media/utkarshrasal/4846FE1A46FE0908/WORK/PYTHON/Django/bloggingwebsite/blogs/serializers.py", line 42, in update
    media_file = validated_data.pop('media_file')
KeyError: 'media_file'
INFO:django.utils.autoreload:/media/utkarshrasal/4846FE1A46FE0908/WORK/PYTHON/Django/bloggingwebsite/blogs/serializers.py changed, reloading.
INFO:root:Partially updated Blog '575aefcf-26ac-4b06-b2c2-9cd2a810808c'
WARNING:django.request:Not Found: /favicon.ico
INFO:root:Partially updated Blog '575aefcf-26ac-4b06-b2c2-9cd2a810808c'
INFO:django.utils.autoreload:/media/utkarshrasal/4846FE1A46FE0908/WORK/PYTHON/Django/bloggingwebsite/blogs/viewsets.py changed, reloading.
INFO:root:Partially updated Blog '575aefcf-26ac-4b06-b2c2-9cd2a810808c'
INFO:root:Partially updated Blog '575aefcf-26ac-4b06-b2c2-9cd2a810808c'
WARNING:django.request:Not Found: /favicon.ico
WARNING:django.request:Not Found: /favicon.ico
INFO:root:Partially updated Blog '575aefcf-26ac-4b06-b2c2-9cd2a810808c'
WARNING:django.request:Not Found: /favicon.ico
INFO:django.utils.autoreload:/media/utkarshrasal/4846FE1A46FE0908/WORK/PYTHON/Django/bloggingwebsite/blogs/viewsets.py changed, reloading.
INFO:django.utils.autoreload:/media/utkarshrasal/4846FE1A46FE0908/WORK/PYTHON/Django/bloggingwebsite/blogs/viewsets.py changed, reloading.
INFO:django.utils.autoreload:/media/utkarshrasal/4846FE1A46FE0908/WORK/PYTHON/Django/bloggingwebsite/blogs/viewsets.py changed, reloading.
INFO:django.utils.autoreload:/media/utkarshrasal/4846FE1A46FE0908/WORK/PYTHON/Django/bloggingwebsite/blogs/serializers.py changed, reloading.
INFO:django.utils.autoreload:/media/utkarshrasal/4846FE1A46FE0908/WORK/PYTHON/Django/bloggingwebsite/blogs/serializers.py changed, reloading.
INFO:django.utils.autoreload:/media/utkarshrasal/4846FE1A46FE0908/WORK/PYTHON/Django/bloggingwebsite/blogs/mixins.py changed, reloading.
INFO:django.utils.autoreload:/media/utkarshrasal/4846FE1A46FE0908/WORK/PYTHON/Django/bloggingwebsite/blogs/mixins.py changed, reloading.
INFO:django.utils.autoreload:/media/utkarshrasal/4846FE1A46FE0908/WORK/PYTHON/Django/bloggingwebsite/blogs/serializers.py changed, reloading.
WARNING:django.request:Not Found: /favicon.ico
ERROR:django.request:Internal Server Error: /blogs/activity/
Traceback (most recent call last):
  File "/home/utkarshrasal/.local/lib/python3.8/site-packages/django/db/models/fields/__init__.py", line 2336, in to_python
    return uuid.UUID(**{input_form: value})
  File "/usr/lib/python3.8/uuid.py", line 169, in __init__
    raise ValueError('badly formed hexadecimal UUID string')
ValueError: badly formed hexadecimal UUID string

During handling of the above exception, another exception occurred:

Traceback (most recent call last):
  File "/home/utkarshrasal/.local/lib/python3.8/site-packages/django/core/handlers/exception.py", line 47, in inner
    response = get_response(request)
  File "/home/utkarshrasal/.local/lib/python3.8/site-packages/django/core/handlers/base.py", line 181, in _get_response
    response = wrapped_callback(request, *callback_args, **callback_kwargs)
  File "/home/utkarshrasal/.local/lib/python3.8/site-packages/django/views/decorators/csrf.py", line 54, in wrapped_view
    return view_func(*args, **kwargs)
  File "/home/utkarshrasal/.local/lib/python3.8/site-packages/rest_framework/viewsets.py", line 125, in view
    return self.dispatch(request, *args, **kwargs)
  File "/home/utkarshrasal/.local/lib/python3.8/site-packages/rest_framework/views.py", line 509, in dispatch
    response = self.handle_exception(exc)
  File "/home/utkarshrasal/.local/lib/python3.8/site-packages/rest_framework/views.py", line 469, in handle_exception
    self.raise_uncaught_exception(exc)
  File "/home/utkarshrasal/.local/lib/python3.8/site-packages/rest_framework/views.py", line 480, in raise_uncaught_exception
    raise exc
  File "/home/utkarshrasal/.local/lib/python3.8/site-packages/rest_framework/views.py", line 506, in dispatch
    response = handler(request, *args, **kwargs)
  File "/media/utkarshrasal/4846FE1A46FE0908/WORK/PYTHON/Django/bloggingwebsite/blogs/viewsets.py", line 87, in retrieve
    instance = self.model_class.objects.get(id=pk)
  File "/home/utkarshrasal/.local/lib/python3.8/site-packages/django/db/models/manager.py", line 85, in manager_method
    return getattr(self.get_queryset(), name)(*args, **kwargs)
  File "/home/utkarshrasal/.local/lib/python3.8/site-packages/django/db/models/query.py", line 418, in get
    clone = self._chain() if self.query.combinator else self.filter(*args, **kwargs)
  File "/home/utkarshrasal/.local/lib/python3.8/site-packages/django/db/models/query.py", line 942, in filter
    return self._filter_or_exclude(False, *args, **kwargs)
  File "/home/utkarshrasal/.local/lib/python3.8/site-packages/django/db/models/query.py", line 962, in _filter_or_exclude
    clone._filter_or_exclude_inplace(negate, *args, **kwargs)
  File "/home/utkarshrasal/.local/lib/python3.8/site-packages/django/db/models/query.py", line 969, in _filter_or_exclude_inplace
    self._query.add_q(Q(*args, **kwargs))
  File "/home/utkarshrasal/.local/lib/python3.8/site-packages/django/db/models/sql/query.py", line 1358, in add_q
    clause, _ = self._add_q(q_object, self.used_aliases)
  File "/home/utkarshrasal/.local/lib/python3.8/site-packages/django/db/models/sql/query.py", line 1377, in _add_q
    child_clause, needed_inner = self.build_filter(
  File "/home/utkarshrasal/.local/lib/python3.8/site-packages/django/db/models/sql/query.py", line 1319, in build_filter
    condition = self.build_lookup(lookups, col, value)
  File "/home/utkarshrasal/.local/lib/python3.8/site-packages/django/db/models/sql/query.py", line 1165, in build_lookup
    lookup = lookup_class(lhs, rhs)
  File "/home/utkarshrasal/.local/lib/python3.8/site-packages/django/db/models/lookups.py", line 24, in __init__
    self.rhs = self.get_prep_lookup()
  File "/home/utkarshrasal/.local/lib/python3.8/site-packages/django/db/models/lookups.py", line 76, in get_prep_lookup
    return self.lhs.output_field.get_prep_value(self.rhs)
  File "/home/utkarshrasal/.local/lib/python3.8/site-packages/django/db/models/fields/__init__.py", line 2320, in get_prep_value
    return self.to_python(value)
  File "/home/utkarshrasal/.local/lib/python3.8/site-packages/django/db/models/fields/__init__.py", line 2338, in to_python
    raise exceptions.ValidationError(
django.core.exceptions.ValidationError: ['“activity” is not a valid UUID.']
WARNING:django.request:Not Found: /blogs/575aefcf-26ac-4b06-b2c2-9cd2a810808c/activty
INFO:django.utils.autoreload:/media/utkarshrasal/4846FE1A46FE0908/WORK/PYTHON/Django/bloggingwebsite/blogs/serializers.py changed, reloading.
ERROR:django.request:Internal Server Error: /blogs/575aefcf-26ac-4b06-b2c2-9cd2a810808c/activity/
Traceback (most recent call last):
  File "/home/utkarshrasal/.local/lib/python3.8/site-packages/django/core/handlers/exception.py", line 47, in inner
    response = get_response(request)
  File "/home/utkarshrasal/.local/lib/python3.8/site-packages/django/core/handlers/base.py", line 181, in _get_response
    response = wrapped_callback(request, *callback_args, **callback_kwargs)
  File "/home/utkarshrasal/.local/lib/python3.8/site-packages/django/views/decorators/csrf.py", line 54, in wrapped_view
    return view_func(*args, **kwargs)
  File "/home/utkarshrasal/.local/lib/python3.8/site-packages/rest_framework/viewsets.py", line 125, in view
    return self.dispatch(request, *args, **kwargs)
  File "/home/utkarshrasal/.local/lib/python3.8/site-packages/rest_framework/views.py", line 509, in dispatch
    response = self.handle_exception(exc)
  File "/home/utkarshrasal/.local/lib/python3.8/site-packages/rest_framework/views.py", line 469, in handle_exception
    self.raise_uncaught_exception(exc)
  File "/home/utkarshrasal/.local/lib/python3.8/site-packages/rest_framework/views.py", line 480, in raise_uncaught_exception
    raise exc
  File "/home/utkarshrasal/.local/lib/python3.8/site-packages/rest_framework/views.py", line 506, in dispatch
    response = handler(request, *args, **kwargs)
  File "/media/utkarshrasal/4846FE1A46FE0908/WORK/PYTHON/Django/bloggingwebsite/blogs/mixins.py", line 176, in activity
    'data':serializers.data
  File "/home/utkarshrasal/.local/lib/python3.8/site-packages/rest_framework/serializers.py", line 745, in data
    ret = super().data
  File "/home/utkarshrasal/.local/lib/python3.8/site-packages/rest_framework/serializers.py", line 246, in data
    self._data = self.to_representation(self.instance)
  File "/home/utkarshrasal/.local/lib/python3.8/site-packages/rest_framework/serializers.py", line 663, in to_representation
    return [
  File "/home/utkarshrasal/.local/lib/python3.8/site-packages/rest_framework/serializers.py", line 664, in <listcomp>
    self.child.to_representation(item) for item in iterable
  File "/home/utkarshrasal/.local/lib/python3.8/site-packages/rest_framework/serializers.py", line 515, in to_representation
    ret[field.field_name] = field.to_representation(attribute)
  File "/home/utkarshrasal/.local/lib/python3.8/site-packages/rest_framework/serializers.py", line 663, in to_representation
    return [
TypeError: 'User' object is not iterable
INFO:django.utils.autoreload:/media/utkarshrasal/4846FE1A46FE0908/WORK/PYTHON/Django/bloggingwebsite/blogs/mixins.py changed, reloading.
ERROR:django.request:Internal Server Error: /blogs/575aefcf-26ac-4b06-b2c2-9cd2a810808c/activity/
Traceback (most recent call last):
  File "/home/utkarshrasal/.local/lib/python3.8/site-packages/rest_framework/fields.py", line 457, in get_attribute
    return get_attribute(instance, self.source_attrs)
  File "/home/utkarshrasal/.local/lib/python3.8/site-packages/rest_framework/fields.py", line 97, in get_attribute
    instance = getattr(instance, attr)
AttributeError: 'QuerySet' object has no attribute 'user'

During handling of the above exception, another exception occurred:

Traceback (most recent call last):
  File "/home/utkarshrasal/.local/lib/python3.8/site-packages/django/core/handlers/exception.py", line 47, in inner
    response = get_response(request)
  File "/home/utkarshrasal/.local/lib/python3.8/site-packages/django/core/handlers/base.py", line 181, in _get_response
    response = wrapped_callback(request, *callback_args, **callback_kwargs)
  File "/home/utkarshrasal/.local/lib/python3.8/site-packages/django/views/decorators/csrf.py", line 54, in wrapped_view
    return view_func(*args, **kwargs)
  File "/home/utkarshrasal/.local/lib/python3.8/site-packages/rest_framework/viewsets.py", line 125, in view
    return self.dispatch(request, *args, **kwargs)
  File "/home/utkarshrasal/.local/lib/python3.8/site-packages/rest_framework/views.py", line 509, in dispatch
    response = self.handle_exception(exc)
  File "/home/utkarshrasal/.local/lib/python3.8/site-packages/rest_framework/views.py", line 469, in handle_exception
    self.raise_uncaught_exception(exc)
  File "/home/utkarshrasal/.local/lib/python3.8/site-packages/rest_framework/views.py", line 480, in raise_uncaught_exception
    raise exc
  File "/home/utkarshrasal/.local/lib/python3.8/site-packages/rest_framework/views.py", line 506, in dispatch
    response = handler(request, *args, **kwargs)
  File "/media/utkarshrasal/4846FE1A46FE0908/WORK/PYTHON/Django/bloggingwebsite/blogs/mixins.py", line 176, in activity
    'data':serializers.data
  File "/home/utkarshrasal/.local/lib/python3.8/site-packages/rest_framework/serializers.py", line 548, in data
    ret = super().data
  File "/home/utkarshrasal/.local/lib/python3.8/site-packages/rest_framework/serializers.py", line 246, in data
    self._data = self.to_representation(self.instance)
  File "/home/utkarshrasal/.local/lib/python3.8/site-packages/rest_framework/serializers.py", line 502, in to_representation
    attribute = field.get_attribute(instance)
  File "/home/utkarshrasal/.local/lib/python3.8/site-packages/rest_framework/fields.py", line 490, in get_attribute
    raise type(exc)(msg)
AttributeError: Got AttributeError when attempting to get a value for field `user` on serializer `ActivitySerializer`.
The serializer field might be named incorrectly and not match any attribute or key on the `QuerySet` instance.
Original exception text was: 'QuerySet' object has no attribute 'user'.
INFO:django.utils.autoreload:/media/utkarshrasal/4846FE1A46FE0908/WORK/PYTHON/Django/bloggingwebsite/blogs/mixins.py changed, reloading.
INFO:django.utils.autoreload:/media/utkarshrasal/4846FE1A46FE0908/WORK/PYTHON/Django/bloggingwebsite/blogs/serializers.py changed, reloading.
ERROR:django.request:Internal Server Error: /blogs/575aefcf-26ac-4b06-b2c2-9cd2a810808c/activity/
Traceback (most recent call last):
  File "/home/utkarshrasal/.local/lib/python3.8/site-packages/django/core/handlers/exception.py", line 47, in inner
    response = get_response(request)
  File "/home/utkarshrasal/.local/lib/python3.8/site-packages/django/core/handlers/base.py", line 181, in _get_response
    response = wrapped_callback(request, *callback_args, **callback_kwargs)
  File "/home/utkarshrasal/.local/lib/python3.8/site-packages/django/views/decorators/csrf.py", line 54, in wrapped_view
    return view_func(*args, **kwargs)
  File "/home/utkarshrasal/.local/lib/python3.8/site-packages/rest_framework/viewsets.py", line 125, in view
    return self.dispatch(request, *args, **kwargs)
  File "/home/utkarshrasal/.local/lib/python3.8/site-packages/rest_framework/views.py", line 509, in dispatch
    response = self.handle_exception(exc)
  File "/home/utkarshrasal/.local/lib/python3.8/site-packages/rest_framework/views.py", line 469, in handle_exception
    self.raise_uncaught_exception(exc)
  File "/home/utkarshrasal/.local/lib/python3.8/site-packages/rest_framework/views.py", line 480, in raise_uncaught_exception
    raise exc
  File "/home/utkarshrasal/.local/lib/python3.8/site-packages/rest_framework/views.py", line 506, in dispatch
    response = handler(request, *args, **kwargs)
  File "/media/utkarshrasal/4846FE1A46FE0908/WORK/PYTHON/Django/bloggingwebsite/blogs/mixins.py", line 176, in activity
    'data':serializers.data
  File "/home/utkarshrasal/.local/lib/python3.8/site-packages/rest_framework/serializers.py", line 745, in data
    ret = super().data
  File "/home/utkarshrasal/.local/lib/python3.8/site-packages/rest_framework/serializers.py", line 246, in data
    self._data = self.to_representation(self.instance)
  File "/home/utkarshrasal/.local/lib/python3.8/site-packages/rest_framework/serializers.py", line 663, in to_representation
    return [
  File "/home/utkarshrasal/.local/lib/python3.8/site-packages/rest_framework/serializers.py", line 664, in <listcomp>
    self.child.to_representation(item) for item in iterable
  File "/home/utkarshrasal/.local/lib/python3.8/site-packages/rest_framework/serializers.py", line 515, in to_representation
    ret[field.field_name] = field.to_representation(attribute)
  File "/home/utkarshrasal/.local/lib/python3.8/site-packages/rest_framework/serializers.py", line 663, in to_representation
    return [
TypeError: 'User' object is not iterable
INFO:django.utils.autoreload:/media/utkarshrasal/4846FE1A46FE0908/WORK/PYTHON/Django/bloggingwebsite/blogs/serializers.py changed, reloading.
INFO:django.utils.autoreload:/media/utkarshrasal/4846FE1A46FE0908/WORK/PYTHON/Django/bloggingwebsite/blogs/serializers.py changed, reloading.
ERROR:django.request:Internal Server Error: /blogs/575aefcf-26ac-4b06-b2c2-9cd2a810808c/activity/
Traceback (most recent call last):
  File "/home/utkarshrasal/.local/lib/python3.8/site-packages/django/core/handlers/exception.py", line 47, in inner
    response = get_response(request)
  File "/home/utkarshrasal/.local/lib/python3.8/site-packages/django/core/handlers/base.py", line 181, in _get_response
    response = wrapped_callback(request, *callback_args, **callback_kwargs)
  File "/home/utkarshrasal/.local/lib/python3.8/site-packages/django/views/decorators/csrf.py", line 54, in wrapped_view
    return view_func(*args, **kwargs)
  File "/home/utkarshrasal/.local/lib/python3.8/site-packages/rest_framework/viewsets.py", line 125, in view
    return self.dispatch(request, *args, **kwargs)
  File "/home/utkarshrasal/.local/lib/python3.8/site-packages/rest_framework/views.py", line 509, in dispatch
    response = self.handle_exception(exc)
  File "/home/utkarshrasal/.local/lib/python3.8/site-packages/rest_framework/views.py", line 469, in handle_exception
    self.raise_uncaught_exception(exc)
  File "/home/utkarshrasal/.local/lib/python3.8/site-packages/rest_framework/views.py", line 480, in raise_uncaught_exception
    raise exc
  File "/home/utkarshrasal/.local/lib/python3.8/site-packages/rest_framework/views.py", line 506, in dispatch
    response = handler(request, *args, **kwargs)
  File "/media/utkarshrasal/4846FE1A46FE0908/WORK/PYTHON/Django/bloggingwebsite/blogs/mixins.py", line 176, in activity
    'data':serializers.data
  File "/home/utkarshrasal/.local/lib/python3.8/site-packages/rest_framework/serializers.py", line 745, in data
    ret = super().data
  File "/home/utkarshrasal/.local/lib/python3.8/site-packages/rest_framework/serializers.py", line 246, in data
    self._data = self.to_representation(self.instance)
  File "/home/utkarshrasal/.local/lib/python3.8/site-packages/rest_framework/serializers.py", line 663, in to_representation
    return [
  File "/home/utkarshrasal/.local/lib/python3.8/site-packages/rest_framework/serializers.py", line 664, in <listcomp>
    self.child.to_representation(item) for item in iterable
  File "/home/utkarshrasal/.local/lib/python3.8/site-packages/rest_framework/serializers.py", line 515, in to_representation
    ret[field.field_name] = field.to_representation(attribute)
  File "/home/utkarshrasal/.local/lib/python3.8/site-packages/rest_framework/serializers.py", line 663, in to_representation
    return [
TypeError: 'Blogs' object is not iterable
INFO:django.utils.autoreload:/media/utkarshrasal/4846FE1A46FE0908/WORK/PYTHON/Django/bloggingwebsite/blogs/serializers.py changed, reloading.
INFO:django.utils.autoreload:/media/utkarshrasal/4846FE1A46FE0908/WORK/PYTHON/Django/bloggingwebsite/blogs/serializers.py changed, reloading.
INFO:django.utils.autoreload:/media/utkarshrasal/4846FE1A46FE0908/WORK/PYTHON/Django/bloggingwebsite/blogs/serializers.py changed, reloading.
INFO:django.utils.autoreload:/media/utkarshrasal/4846FE1A46FE0908/WORK/PYTHON/Django/bloggingwebsite/blogs/serializers.py changed, reloading.
INFO:django.utils.autoreload:/media/utkarshrasal/4846FE1A46FE0908/WORK/PYTHON/Django/bloggingwebsite/blogs/serializers.py changed, reloading.
